Workbook

Sheet README
A1: Work Package E - Referral & Engagement Analytics
A3: Purpose | B3: Measure the referral funnel and user engagement without treating registration as a successful referral.
A4: Funnel | B4: Referral Created -> User Registered -> User Activated -> Referral Converted (only the last stage is a successful referral).
A6: SHEETS
A7: KPI_Dashboard | B7: All headline KPIs, targets, status flags, group and source breakdowns, charts.
A8: Referral_Data | B8: E1 - one row per referral: IDs, source, 4 stage timestamps, status, derived stage, data checks, cycle times.
A9: Engagement_Events | B9: E2 - event log (login / feature use / task completed) with helper columns for distinct counts.
A10: Daily_Activity | B10: Daily referral funnel + DAU, new, returning users, logins, feature uses, task completions.
A11: Feature_Adoption | B11: Adoption, repeat usage and frequency per feature.
A12: Settings | B12: As-of date, windows, targets, and the business definitions of Activation and Conversion.
A13: E1_Data_Dictionary / E2_Metric_Definitions | B13: Field definitions, stage rules and metric formulas.
A15: HOW TO USE
A16: 1 | B16: Replace the sample rows in Referral_Data (blue) and Engagement_Events (blue) with your real data. Sample data is illustrative only.
A17: 2 | B17: For new rows, copy the grey formula cells down. Summary formulas already read to row 1000 (referrals) / 3000 (events).
A18: 3 | B18: Set the As-of Date, windows and targets in Settings (yellow cells), and write down your Activation and Conversion definitions.
A19: 4 | B19: If the reporting period exceeds 45 days, copy the last row of Daily_Activity down.
A20: 5 | B20: Keep Referral_Data[Data Check] at OK - CHECK flags mean status, gaps or timestamp order are inconsistent.
A22: COLOR LEGEND
A23: Blue text | B23: Input data / assumptions you can edit.
A24: Black text | B24: Formulas - do not overwrite.
A25: Green text | B25: Link pulled from another sheet (Settings).
A26: Yellow fill | B26: Key assumption to confirm (targets, windows, definitions).

Sheet KPI_Dashboard
A1: Referral & Engagement KPI Dashboard
A2: As-of date: | B2: =Settings!B5 -> 46310
A4: 1. REFERRAL FUNNEL | B4: Count | C4: % of Created | D4: Step Conversion | E4: Definition / Notes
A5: Referral Created | B5: =COUNTA(Referral_Data!$A$5:$A$1000) -> 60 | C5: =IFERROR(B5/$B$5,0) -> 1 | D5: - | E5: Referral record exists (invite/link generated).
A6: User Registered | B6: =COUNT(Referral_Data!$F$5:$F$1000) -> 40 | C6: =IFERROR(B6/$B$5,0) -> 0.66666667 | D6: =IFERROR(B6/B5,0) -> 0.66666667 | E6: Referred user completed sign-up (registration timestamp present).
A7: User Activated | B7: =COUNT(Referral_Data!$G$5:$G$1000) -> 20 | C7: =IFERROR(B7/$B$5,0) -> 0.33333333 | D7: =IFERROR(B7/B6,0) -> 0.5 | E7: Referred user completed the activation event defined in Settings.
A8: Referral Converted | B8: =COUNT(Referral_Data!$H$5:$H$1000) -> 10 | C8: =IFERROR(B8/$B$5,0) -> 0.16666667 | D8: =IFERROR(B8/B7,0) -> 0.5 | E8: Referred user reached the conversion event defined in Settings.
A9: Expired (never registered) | B9: =COUNTIF(Referral_Data!$I$5:$I$1000,"Expired") -> 7 | E9: Referral older than expiry window with no registration.
A10: Registered but NOT converted | B10: =B6-B8 -> 30 | E10: Registration is not conversion - this is the gap to close.
A11: Registered but NOT activated | B11: =B6-B7 -> 20 | E11: Signed up but never reached first value.
A12: Activated within window | B12: =COUNTIF(Referral_Data!$P$5:$P$1000,"Yes") -> 20 | C12: =IFERROR(B12/B7,0) -> 1 | E12: Activated within the activation-window days from Settings.
A13: Data-quality flags (Referral_Data) | B13: =COUNTIF(Referral_Data!$K$5:$K$1000,"CHECK*") -> 0 | E13: Rows where status, gaps or timestamp order look wrong. Should be 0.
A15: 2. REFERRAL KPIs vs TARGET | B15: Value | C15: Target | D15: Status | E15: Definition
A16: Registration Rate | B16: =IFERROR(B6/B5,0) -> 0.66666667 | C16: =Settings!B12 -> 0.6 | D16: =IF(B16>=C16,"On track","Below target") -> On track | E16: Registered / Created
A17: Activation Rate (of registered) | B17: =IFERROR(B7/B6,0) -> 0.5 | C17: =Settings!B13 -> 0.5 | D17: =IF(B17>=C17,"On track","Below target") -> On track | E17: Activated / Registered
A18: Conversion Rate (of activated) | B18: =IFERROR(B8/B7,0) -> 0.5 | C18: =Settings!B14 -> 0.5 | D18: =IF(B18>=C18,"On track","Below target") -> On track | E18: Converted / Activated
A19: Overall Referral Conversion Rate | B19: =IFERROR(B8/B5,0) -> 0.16666667 | C19: =Settings!B15 -> 0.15 | D19: =IF(B19>=C19,"On track","Below target") -> On track | E19: Converted / Created - the true referral success rate.
A20: Registered-to-Converted Rate | B20: =IFERROR(B8/B6,0) -> 0.25 | E20: Converted / Registered - shows how misleading 'registration = success' would be.
A21: Referring users (distinct) | B21: =SUM(Referral_Data!$Q$5:$Q$1000) -> 12 | E21: Distinct referring users with at least one referral.
A22: Referring users with 1+ conversion | B22: =SUM(Referral_Data!$R$5:$R$1000) -> 7 | E22: Distinct referrers whose referral reached Converted.
A23: Referrer Success Rate | B23: =IFERROR(B22/B21,0) -> 0.58333333 | E23: Referrers with 1+ conversion / all referrers.
A25: 3. REFERRAL CYCLE TIME (days) | B25: Average | C25: Median | E25: Definition
A26: Created to Registered | B26: =IFERROR(AVERAGE(Referral_Data!$L$5:$L$1000),0) -> 2.0327951 | C26: =IFERROR(MEDIAN(Referral_Data!$L$5:$L$1000),0) -> 1.2194444 | E26: Only referrals that reached both stages are included.
A27: Registered to Activated | B27: =IFERROR(AVERAGE(Referral_Data!$M$5:$M$1000),0) -> 2.9104167 | C27: =IFERROR(MEDIAN(Referral_Data!$M$5:$M$1000),0) -> 2.6458333 | E27: Only referrals that reached both stages are included.
A28: Activated to Converted | B28: =IFERROR(AVERAGE(Referral_Data!$N$5:$N$1000),0) -> 6.1916667 | C28: =IFERROR(MEDIAN(Referral_Data!$N$5:$N$1000),0) -> 6 | E28: Only referrals that reached both stages are included.
A29: Created to Converted | B29: =IFERROR(AVERAGE(Referral_Data!$O$5:$O$1000),0) -> 10.491389 | C29: =IFERROR(MEDIAN(Referral_Data!$O$5:$O$1000),0) -> 10.789931 | E29: Only referrals that reached both stages are included.
A31: 4. ENGAGEMENT KPIs | B31: Value | C31: Target | D31: Status | E31: Definition
A32: Distinct active users (all-time in log) | B32: =SUM(Engagement_Events!$K$5:$K$3000) -> 58 | E32: Users with at least one event.
A33: DAU (as-of date) | B33: =SUMIFS(Engagement_Events!$G$5:$G$3000,Engagement_Events!$C$5:$C$3000,Settings!B5) -> 19 | E33: Distinct users with any event on the as-of date.
A34: WAU (rolling window) | B34: =SUM(Engagement_Events!$L$5:$L$3000) -> 53 | E34: Distinct users active in the last N days (Settings: WAU window).
A35: MAU (rolling window) | B35: =SUM(Engagement_Events!$M$5:$M$3000) -> 58 | E35: Distinct users active in the last N days (Settings: MAU window).
A36: Stickiness (DAU / MAU) | B36: =IFERROR(B33/B35,0) -> 0.32758621 | C36: =Settings!B16 -> 0.2 | D36: =IF(B36>=C36,"On track","Below target") -> On track | E36: How often monthly users show up daily.
A37: Returning users (as-of date) | B37: =SUMIFS(Engagement_Events!$H$5:$H$3000,Engagement_Events!$C$5:$C$3000,Settings!B5) -> 18 | E37: Active on as-of date AND active on an earlier date.
A38: Returning user rate | B38: =IFERROR(B37/B33,0) -> 0.94736842 | C38: =Settings!B17 -> 0.4 | D38: =IF(B38>=C38,"On track","Below target") -> On track | E38: Returning users / DAU.
A39: Average DAU over reporting period | B39: =IFERROR(AVERAGE(Daily_Activity!F5:F49),0) -> 12 | E39: Mean of daily active users on Daily_Activity.
A40: Total task completions | B40: =COUNTIF(Engagement_Events!$D$5:$D$3000,"Task Completed") -> 287 | E40: Count of 'Task Completed' events.
A41: Task completions per active user | B41: =IFERROR(B40/B32,0) -> 4.9482759 | E41: Task activity depth.
A42: Total feature uses | B42: =COUNTIF(Engagement_Events!$D$5:$D$3000,"Feature Use") -> 804 | E42: Count of 'Feature Use' events.
A43: Feature uses per active user | B43: =IFERROR(B42/B32,0) -> 13.862069 | E43: Feature frequency per user.
A44: Feature adoption rate (any feature) | B44: =IFERROR(SUM(Engagement_Events!$N$5:$N$3000)/B32,0) -> 1 | E44: Users with 1+ feature use / active users.
...

Sheet Referral_Data
A1: Referral Data (E1) - one row per referral
A2: Blue = input data (replace sample rows with your own). Grey = formulas (copy down for new rows). A referral is only 'Converted' when a conversion timestamp exists - registration alone is not conversion.
A4: Referral ID | B4: Referring User ID | C4: Referred User ID | D4: Source | E4: Created Timestamp | F4: Registered Timestamp | G4: Activated Timestamp | H4: Converted Timestamp | I4: Status | J4: Derived Stage (from timestamps) | K4: Data Check | L4: Days: Created to Registered | M4: Days: Registered to Activated | N4: Days: Activated to Converted | O4: Days: Created to Converted | P4: Activated Within Window? | Q4: First Referral of Referrer (1/0) | R4: First Converted Referral of Referrer (1/0)
A5: REF-0001 | B5: U001 | C5: R001 | D5: Email | E5: 46273.324 | F5: 46274.399 | G5: 46279.565 | H5: 46286.565 | I5: Converted | J5: =IF(H5<>"","Converted",IF(G5<>"","Activated",IF(F5<>"","Registered","Created"))) -> Converted | K5: =IF(AND(I5="Expired",J5="Created"),"OK",IF(I5<>J5,"CHECK status",IF(OR(AND(G5<>"",F5=""),AND(H5<>"",G5="")),"CHECK gap",IF(OR(AND(F5<>"",F5<E5),AND(G5<>"",G5<F5),AND(H5<>"",H5<G5)),"CHECK order","OK")))) -> OK | L5: =IF(F5="","",F5-E5) -> 1.0743056 | M5: =IF(G5="","",G5-F5) -> 5.1666667 | N5: =IF(H5="","",H5-G5) -> 7 | O5: =IF(H5="","",H5-E5) -> 13.240972 | P5: =IF(G5="","",IF(G5-F5<=Settings!$B$6,"Yes","No")) -> Yes | Q5: =IF(COUNTIF($B$5:B5,B5)=1,1,0) -> 1 | R5: =IF(H5="",0,IF(COUNTIFS($B$5:B5,B5,$H$5:H5,"<>")=1,1,0)) -> 1
A6: REF-0002 | B6: U007 | C6: R002 | D6: WhatsApp | E6: 46280.651 | F6: 46281.888 | I6: Registered | J6: =IF(H6<>"","Converted",IF(G6<>"","Activated",IF(F6<>"","Registered","Created"))) -> Registered | K6: =IF(AND(I6="Expired",J6="Created"),"OK",IF(I6<>J6,"CHECK status",IF(OR(AND(G6<>"",F6=""),AND(H6<>"",G6="")),"CHECK gap",IF(OR(AND(F6<>"",F6<E6),AND(G6<>"",G6<F6),AND(H6<>"",H6<G6)),"CHECK order","OK")))) -> OK | L6: =IF(F6="","",F6-E6) -> 1.2368056 | M6: =IF(G6="","",G6-F6) | N6: =IF(H6="","",H6-G6) | O6: =IF(H6="","",H6-E6) | P6: =IF(G6="","",IF(G6-F6<=Settings!$B$6,"Yes","No")) | Q6: =IF(COUNTIF($B$5:B6,B6)=1,1,0) -> 1 | R6: =IF(H6="",0,IF(COUNTIFS($B$5:B6,B6,$H$5:H6,"<>")=1,1,0)) -> 0
A7: REF-0003 | B7: U003 | D7: In-App Invite | E7: 46303.494 | I7: Created | J7: =IF(H7<>"","Converted",IF(G7<>"","Activated",IF(F7<>"","Registered","Created"))) -> Created | K7: =IF(AND(I7="Expired",J7="Created"),"OK",IF(I7<>J7,"CHECK status",IF(OR(AND(G7<>"",F7=""),AND(H7<>"",G7="")),"CHECK gap",IF(OR(AND(F7<>"",F7<E7),AND(G7<>"",G7<F7),AND(H7<>"",H7<G7)),"CHECK order","OK")))) -> OK | L7: =IF(F7="","",F7-E7) | M7: =IF(G7="","",G7-F7) | N7: =IF(H7="","",H7-G7) | O7: =IF(H7="","",H7-E7) | P7: =IF(G7="","",IF(G7-F7<=Settings!$B$6,"Yes","No")) | Q7: =IF(COUNTIF($B$5:B7,B7)=1,1,0) -> 1 | R7: =IF(H7="",0,IF(COUNTIFS($B$5:B7,B7,$H$5:H7,"<>")=1,1,0)) -> 0
A8: REF-0004 | B8: U012 | C8: R003 | D8: Social Media | E8: 46287.465 | F8: 46290.468 | G8: 46292.718 | H8: 46297.718 | I8: Converted | J8: =IF(H8<>"","Converted",IF(G8<>"","Activated",IF(F8<>"","Registered","Created"))) -> Converted | K8: =IF(AND(I8="Expired",J8="Created"),"OK",IF(I8<>J8,"CHECK status",IF(OR(AND(G8<>"",F8=""),AND(H8<>"",G8="")),"CHECK gap",IF(OR(AND(F8<>"",F8<E8),AND(G8<>"",G8<F8),AND(H8<>"",H8<G8)),"CHECK order","OK")))) -> OK | L8: =IF(F8="","",F8-E8) -> 3.0034722 | M8: =IF(G8="","",G8-F8) -> 2.25 | N8: =IF(H8="","",H8-G8) -> 5 | O8: =IF(H8="","",H8-E8) -> 10.253472 | P8: =IF(G8="","",IF(G8-F8<=Settings!$B$6,"Yes","No")) -> Yes | Q8: =IF(COUNTIF($B$5:B8,B8)=1,1,0) -> 1 | R8: =IF(H8="",0,IF(COUNTIFS($B$5:B8,B8,$H$5:H8,"<>")=1,1,0)) -> 1
A9: REF-0005 | B9: U006 | C9: R004 | D9: Social Media | E9: 46273.892 | F9: 46276.127 | I9: Registered | J9: =IF(H9<>"","Converted",IF(G9<>"","Activated",IF(F9<>"","Registered","Created"))) -> Registered | K9: =IF(AND(I9="Expired",J9="Created"),"OK",IF(I9<>J9,"CHECK status",IF(OR(AND(G9<>"",F9=""),AND(H9<>"",G9="")),"CHECK gap",IF(OR(AND(F9<>"",F9<E9),AND(G9<>"",G9<F9),AND(H9<>"",H9<G9)),"CHECK order","OK")))) -> OK | L9: =IF(F9="","",F9-E9) -> 2.2354167 | M9: =IF(G9="","",G9-F9) | N9: =IF(H9="","",H9-G9) | O9: =IF(H9="","",H9-E9) | P9: =IF(G9="","",IF(G9-F9<=Settings!$B$6,"Yes","No")) | Q9: =IF(COUNTIF($B$5:B9,B9)=1,1,0) -> 1 | R9: =IF(H9="",0,IF(COUNTIFS($B$5:B9,B9,$H$5:H9,"<>")=1,1,0)) -> 0
A10: REF-0006 | B10: U003 | C10: R005 | D10: WhatsApp | E10: 46270.321 | F10: 46272.358 | G10: 46272.483 | H10: 46283.567 | I10: Converted | J10: =IF(H10<>"","Converted",IF(G10<>"","Activated",IF(F10<>"","Registered","Created"))) -> Converted | K10: =IF(AND(I10="Expired",J10="Created"),"OK",IF(I10<>J10,"CHECK status",IF(OR(AND(G10<>"",F10=""),AND(H10<>"",G10="")),"CHECK gap",IF(OR(AND(F10<>"",F10<E10),AND(G10<>"",G10<F10),AND(H10<>"",H10<G10)),"CHECK order","OK")))) -> OK | L10: =IF(F10="","",F10-E10) -> 2.0375 | M10: =IF(G10="","",G10-F10) -> 0.125 | N10: =IF(H10="","",H10-G10) -> 11.083333 | O10: =IF(H10="","",H10-E10) -> 13.245833 | P10: =IF(G10="","",IF(G10-F10<=Settings!$B$6,"Yes","No")) -> Yes | Q10: =IF(COUNTIF($B$5:B10,B10)=1,1,0) -> 0 | R10: =IF(H10="",0,IF(COUNTIFS($B$5:B10,B10,$H$5:H10,"<>")=1,1,0)) -> 1
A11: REF-0007 | B11: U011 | C11: R006 | D11: In-App Invite | E11: 46279.72 | F11: 46279.915 | G11: 46284.956 | H11: 46292.04 | I11: Converted | J11: =IF(H11<>"","Converted",IF(G11<>"","Activated",IF(F11<>"","Registered","Created"))) -> Converted | K11: =IF(AND(I11="Expired",J11="Created"),"OK",IF(I11<>J11,"CHECK status",IF(OR(AND(G11<>"",F11=""),AND(H11<>"",G11="")),"CHECK gap",IF(OR(AND(F11<>"",F11<E11),AND(G11<>"",G11<F11),AND(H11<>"",H11<G11)),"CHECK order","OK")))) -> OK | L11: =IF(F11="","",F11-E11) -> 0.19444444 | M11: =IF(G11="","",G11-F11) -> 5.0416667 | N11: =IF(H11="","",H11-G11) -> 7.0833333 | O11: =IF(H11="","",H11-E11) -> 12.319444 | P11: =IF(G11="","",IF(G11-F11<=Settings!$B$6,"Yes","No")) -> Yes | Q11: =IF(COUNTIF($B$5:B11,B11)=1,1,0) -> 1 | R11: =IF(H11="",0,IF(COUNTIFS($B$5:B11,B11,$H$5:H11,"<>")=1,1,0)) -> 1
A12: REF-0008 | B12: U001 | D12: WhatsApp | E12: 46280.722 | I12: Expired | J12: =IF(H12<>"","Converted",IF(G12<>"","Activated",IF(F12<>"","Registered","Created"))) -> Created | K12: =IF(AND(I12="Expired",J12="Created"),"OK",IF(I12<>J12,"CHECK status",IF(OR(AND(G12<>"",F12=""),AND(H12<>"",G12="")),"CHECK gap",IF(OR(AND(F12<>"",F12<E12),AND(G12<>"",G12<F12),AND(H12<>"",H12<G12)),"CHECK order","OK")))) -> OK | L12: =IF(F12="","",F12-E12) | M12: =IF(G12="","",G12-F12) | N12: =IF(H12="","",H12-G12) | O12: =IF(H12="","",H12-E12) | P12: =IF(G12="","",IF(G12-F12<=Settings!$B$6,"Yes","No")) | Q12: =IF(COUNTIF($B$5:B12,B12)=1,1,0) -> 0 | R12: =IF(H12="",0,IF(COUNTIFS($B$5:B12,B12,$H$5:H12,"<>")=1,1,0)) -> 0
A13: REF-0009 | B13: U012 | C13: R007 | D13: WhatsApp | E13: 46268.806 | F13: 46268.887 | I13: Registered | J13: =IF(H13<>"","Converted",IF(G13<>"","Activated",IF(F13<>"","Registered","Created"))) -> Registered | K13: =IF(AND(I13="Expired",J13="Created"),"OK",IF(I13<>J13,"CHECK status",IF(OR(AND(G13<>"",F13=""),AND(H13<>"",G13="")),"CHECK gap",IF(OR(AND(F13<>"",F13<E13),AND(G13<>"",G13<F13),AND(H13<>"",H13<G13)),"CHECK order","OK")))) -> OK | L13: =IF(F13="","",F13-E13) -> 0.081944444 | M13: =IF(G13="","",G13-F13) | N13: =IF(H13="","",H13-G13) | O13: =IF(H13="","",H13-E13) | P13: =IF(G13="","",IF(G13-F13<=Settings!$B$6,"Yes","No")) | Q13: =IF(COUNTIF($B$5:B13,B13)=1,1,0) -> 0 | R13: =IF(H13="",0,IF(COUNTIFS($B$5:B13,B13,$H$5:H13,"<>")=1,1,0)) -> 0
A14: REF-0010 | B14: U008 | D14: Email | E14: 46297.581 | I14: Created | J14: =IF(H14<>"","Converted",IF(G14<>"","Activated",IF(F14<>"","Registered","Created"))) -> Created | K14: =IF(AND(I14="Expired",J14="Created"),"OK",IF(I14<>J14,"CHECK status",IF(OR(AND(G14<>"",F14=""),AND(H14<>"",G14="")),"CHECK gap",IF(OR(AND(F14<>"",F14<E14),AND(G14<>"",G14<F14),AND(H14<>"",H14<G14)),"CHECK order","OK")))) -> OK | L14: =IF(F14="","",F14-E14) | M14: =IF(G14="","",G14-F14) | N14: =IF(H14="","",H14-G14) | O14: =IF(H14="","",H14-E14) | P14: =IF(G14="","",IF(G14-F14<=Settings!$B$6,"Yes","No")) | Q14: =IF(COUNTIF($B$5:B14,B14)=1,1,0) -> 1 | R14: =IF(H14="",0,IF(COUNTIFS($B$5:B14,B14,$H$5:H14,"<>")=1,1,0)) -> 0
A15: REF-0011 | B15: U008 | C15: R008 | D15: Email | E15: 46274.449 | F15: 46276.683 | G15: 46280.808 | H15: 46283.975 | I15: Converted | J15: =IF(H15<>"","Converted",IF(G15<>"","Activated",IF(F15<>"","Registered","Created"))) -> Converted | K15: =IF(AND(I15="Expired",J15="Created"),"OK",IF(I15<>J15,"CHECK status",IF(OR(AND(G15<>"",F15=""),AND(H15<>"",G15="")),"CHECK gap",IF(OR(AND(F15<>"",F15<E15),AND(G15<>"",G15<F15),AND(H15<>"",H15<G15)),"CHECK order","OK")))) -> OK | L15: =IF(F15="","",F15-E15) -> 2.2340278 | M15: =IF(G15="","",G15-F15) -> 4.125 | N15: =IF(H15="","",H15-G15) -> 3.1666667 | O15: =IF(H15="","",H15-E15) -> 9.5256944 | P15: =IF(G15="","",IF(G15-F15<=Settings!$B$6,"Yes","No")) -> Yes | Q15: =IF(COUNTIF($B$5:B15,B15)=1,1,0) -> 0 | R15: =IF(H15="",0,IF(COUNTIFS($B$5:B15,B15,$H$5:H15,"<>")=1,1,0)) -> 1
A16: REF-0012 | B16: U008 | C16: R009 | D16: Social Media | E16: 46269.838 | F16: 46271.065 | G16: 46274.19 | I16: Activated | J16: =IF(H16<>"","Converted",IF(G16<>"","Activated",IF(F16<>"","Registered","Created"))) -> Activated | K16: =IF(AND(I16="Expired",J16="Created"),"OK",IF(I16<>J16,"CHECK status",IF(OR(AND(G16<>"",F16=""),AND(H16<>"",G16="")),"CHECK gap",IF(OR(AND(F16<>"",F16<E16),AND(G16<>"",G16<F16),AND(H16<>"",H16<G16)),"CHECK order","OK")))) -> OK | L16: =IF(F16="","",F16-E16) -> 1.2270833 | M16: =IF(G16="","",G16-F16) -> 3.125 | N16: =IF(H16="","",H16-G16) | O16: =IF(H16="","",H16-E16) | P16: =IF(G16="","",IF(G16-F16<=Settings!$B$6,"Yes","No")) -> Yes | Q16: =IF(COUNTIF($B$5:B16,B16)=1,1,0) -> 0 | R16: =IF(H16="",0,IF(COUNTIFS($B$5:B16,B16,$H$5:H16,"<>")=1,1,0)) -> 0
A17: REF-0013 | B17: U002 | C17: R010 | D17: WhatsApp | E17: 46301.833 | F17: 46302.081 | G17: 46304.331 | I17: Activated | J17: =IF(H17<>"","Converted",IF(G17<>"","Activated",IF(F17<>"","Registered","Created"))) -> Activated | K17: =IF(AND(I17="Expired",J17="Created"),"OK",IF(I17<>J17,"CHECK status",IF(OR(AND(G17<>"",F17=""),AND(H17<>"",G17="")),"CHECK gap",IF(OR(AND(F17<>"",F17<E17),AND(G17<>"",G17<F17),AND(H17<>"",H17<G17)),"CHECK order","OK")))) -> OK | L17: =IF(F17="","",F17-E17) -> 0.24722222 | M17: =IF(G17="","",G17-F17) -> 2.25 | N17: =IF(H17="","",H17-G17) | O17: =IF(H17="","",H17-E17) | P17: =IF(G17="","",IF(G17-F17<=Settings!$B$6,"Yes","No")) -> Yes | Q17: =IF(COUNTIF($B$5:B17,B17)=1,1,0) -> 1 | R17: =IF(H17="",0,IF(COUNTIFS($B$5:B17,B17,$H$5:H17,"<>")=1,1,0)) -> 0
A18: REF-0014 | B18: U012 | D18: WhatsApp | E18: 46276.583 | I18: Expired | J18: =IF(H18<>"","Converted",IF(G18<>"","Activated",IF(F18<>"","Registered","Created"))) -> Created | K18: =IF(AND(I18="Expired",J18="Created"),"OK",IF(I18<>J18,"CHECK status",IF(OR(AND(G18<>"",F18=""),AND(H18<>"",G18="")),"CHECK gap",IF(OR(AND(F18<>"",F18<E18),AND(G18<>"",G18<F18),AND(H18<>"",H18<G18)),"CHECK order","OK")))) -> OK | L18: =IF(F18="","",F18-E18) | M18: =IF(G18="","",G18-F18) | N18: =IF(H18="","",H18-G18) | O18: =IF(H18="","",H18-E18) | P18: =IF(G18="","",IF(G18-F18<=Settings!$B$6,"Yes","No")) | Q18: =IF(COUNTIF($B$5:B18,B18)=1,1,0) -> 0 | R18: =IF(H18="",0,IF(COUNTIFS($B$5:B18,B18,$H$5:H18,"<>")=1,1,0)) -> 0
A19: REF-0015 | B19: U009 | C19: R011 | D19: Social Media | E19: 46298.799 | F19: 46299.021 | I19: Registered | J19: =IF(H19<>"","Converted",IF(G19<>"","Activated",IF(F19<>"","Registered","Created"))) -> Registered | K19: =IF(AND(I19="Expired",J19="Created"),"OK",IF(I19<>J19,"CHECK status",IF(OR(AND(G19<>"",F19=""),AND(H19<>"",G19="")),"CHECK gap",IF(OR(AND(F19<>"",F19<E19),AND(G19<>"",G19<F19),AND(H19<>"",H19<G19)),"CHECK order","OK")))) -> OK | L19: =IF(F19="","",F19-E19) -> 0.22152778 | M19: =IF(G19="","",G19-F19) | N19: =IF(H19="","",H19-G19) | O19: =IF(H19="","",H19-E19) | P19: =IF(G19="","",IF(G19-F19<=Settings!$B$6,"Yes","No")) | Q19: =IF(COUNTIF($B$5:B19,B19)=1,1,0) -> 1 | R19: =IF(H19="",0,IF(COUNTIFS($B$5:B19,B19,$H$5:H19,"<>")=1,1,0)) -> 0
A20: REF-0016 | B20: U005 | C20: R012 | D20: WhatsApp | E20: 46275.533 | F20: 46275.714 | G20: 46275.797 | I20: Activated | J20: =IF(H20<>"","Converted",IF(G20<>"","Activated",IF(F20<>"","Registered","Created"))) -> Activated | K20: =IF(AND(I20="Expired",J20="Created"),"OK",IF(I20<>J20,"CHECK status",IF(OR(AND(G20<>"",F20=""),AND(H20<>"",G20="")),"CHECK gap",IF(OR(AND(F20<>"",F20<E20),AND(G20<>"",G20<F20),AND(H20<>"",H20<G20)),"CHECK order","OK")))) -> OK | L20: =IF(F20="","",F20-E20) -> 0.18055556 | M20: =IF(G20="","",G20-F20) -> 0.083333333 | N20: =IF(H20="","",H20-G20) | O20: =IF(H20="","",H20-E20) | P20: =IF(G20="","",IF(G20-F20<=Settings!$B$6,"Yes","No")) -> Yes | Q20: =IF(COUNTIF($B$5:B20,B20)=1,1,0) -> 1 | R20: =IF(H20="",0,IF(COUNTIFS($B$5:B20,B20,$H$5:H20,"<>")=1,1,0)) -> 0
A21: REF-0017 | B21: U002 | D21: In-App Invite | E21: 46281.9 | I21: Created | J21: =IF(H21<>"","Converted",IF(G21<>"","Activated",IF(F21<>"","Registered","Created"))) -> Created | K21: =IF(AND(I21="Expired",J21="Created"),"OK",IF(I21<>J21,"CHECK status",IF(OR(AND(G21<>"",F21=""),AND(H21<>"",G21="")),"CHECK gap",IF(OR(AND(F21<>"",F21<E21),AND(G21<>"",G21<F21),AND(H21<>"",H21<G21)),"CHECK order","OK")))) -> OK | L21: =IF(F21="","",F21-E21) | M21: =IF(G21="","",G21-F21) | N21: =IF(H21="","",H21-G21) | O21: =IF(H21="","",H21-E21) | P21: =IF(G21="","",IF(G21-F21<=Settings!$B$6,"Yes","No")) | Q21: =IF(COUNTIF($B$5:B21,B21)=1,1,0) -> 0 | R21: =IF(H21="",0,IF(COUNTIFS($B$5:B21,B21,$H$5:H21,"<>")=1,1,0)) -> 0
A22: REF-0018 | B22: U003 | D22: In-App Invite | E22: 46270.815 | I22: Expired | J22: =IF(H22<>"","Converted",IF(G22<>"","Activated",IF(F22<>"","Registered","Created"))) -> Created | K22: =IF(AND(I22="Expired",J22="Created"),"OK",IF(I22<>J22,"CHECK status",IF(OR(AND(G22<>"",F22=""),AND(H22<>"",G22="")),"CHECK gap",IF(OR(AND(F22<>"",F22<E22),AND(G22<>"",G22<F22),AND(H22<>"",H22<G22)),"CHECK order","OK")))) -> OK | L22: =IF(F22="","",F22-E22) | M22: =IF(G22="","",G22-F22) | N22: =IF(H22="","",H22-G22) | O22: =IF(H22="","",H22-E22) | P22: =IF(G22="","",IF(G22-F22<=Settings!$B$6,"Yes","No")) | Q22: =IF(COUNTIF($B$5:B22,B22)=1,1,0) -> 0 | R22: =IF(H22="",0,IF(COUNTIFS($B$5:B22,B22,$H$5:H22,"<>")=1,1,0)) -> 0
A23: REF-0019 | B23: U004 | C23: R013 | D23: In-App Invite | E23: 46301.386 | F23: 46306.469 | I23: Registered | J23: =IF(H23<>"","Converted",IF(G23<>"","Activated",IF(F23<>"","Registered","Created"))) -> Registered | K23: =IF(AND(I23="Expired",J23="Created"),"OK",IF(I23<>J23,"CHECK status",IF(OR(AND(G23<>"",F23=""),AND(H23<>"",G23="")),"CHECK gap",IF(OR(AND(F23<>"",F23<E23),AND(G23<>"",G23<F23),AND(H23<>"",H23<G23)),"CHECK order","OK")))) -> OK | L23: =IF(F23="","",F23-E23) -> 5.0826389 | M23: =IF(G23="","",G23-F23) | N23: =IF(H23="","",H23-G23) | O23: =IF(H23="","",H23-E23) | P23: =IF(G23="","",IF(G23-F23<=Settings!$B$6,"Yes","No")) | Q23: =IF(COUNTIF($B$5:B23,B23)=1,1,0) -> 1 | R23: =IF(H23="",0,IF(COUNTIFS($B$5:B23,B23,$H$5:H23,"<>")=1,1,0)) -> 0
A24: REF-0020 | B24: U004 | C24: R014 | D24: Social Media | E24: 46291.737 | F24: 46298.747 | G24: 46300.747 | I24: Activated | J24: =IF(H24<>"","Converted",IF(G24<>"","Activated",IF(F24<>"","Registered","Created"))) -> Activated | K24: =IF(AND(I24="Expired",J24="Created"),"OK",IF(I24<>J24,"CHECK status",IF(OR(AND(G24<>"",F24=""),AND(H24<>"",G24="")),"CHECK gap",IF(OR(AND(F24<>"",F24<E24),AND(G24<>"",G24<F24),AND(H24<>"",H24<G24)),"CHECK order","OK")))) -> OK | L24: =IF(F24="","",F24-E24) -> 7.0104167 | M24: =IF(G24="","",G24-F24) -> 2 | N24: =IF(H24="","",H24-G24) | O24: =IF(H24="","",H24-E24) | P24: =IF(G24="","",IF(G24-F24<=Settings!$B$6,"Yes","No")) -> Yes | Q24: =IF(COUNTIF($B$5:B24,B24)=1,1,0) -> 0 | R24: =IF(H24="",0,IF(COUNTIFS($B$5:B24,B24,$H$5:H24,"<>")=1,1,0)) -> 0
A25: REF-0021 | B25: U005 | C25: R015 | D25: In-App Invite | E25: 46266.365 | F25: 46267.404 | G25: 46269.404 | I25: Activated | J25: =IF(H25<>"","Converted",IF(G25<>"","Activated",IF(F25<>"","Registered","Created"))) -> Activated | K25: =IF(AND(I25="Expired",J25="Created"),"OK",IF(I25<>J25,"CHECK status",IF(OR(AND(G25<>"",F25=""),AND(H25<>"",G25="")),"CHECK gap",IF(OR(AND(F25<>"",F25<E25),AND(G25<>"",G25<F25),AND(H25<>"",H25<G25)),"CHECK order","OK")))) -> OK | L25: =IF(F25="","",F25-E25) -> 1.0395833 | M25: =IF(G25="","",G25-F25) -> 2 | N25: =IF(H25="","",H25-G25) | O25: =IF(H25="","",H25-E25) | P25: =IF(G25="","",IF(G25-F25<=Settings!$B$6,"Yes","No")) -> Yes | Q25: =IF(COUNTIF($B$5:B25,B25)=1,1,0) -> 0 | R25: =IF(H25="",0,IF(COUNTIFS($B$5:B25,B25,$H$5:H25,"<>")=1,1,0)) -> 0
A26: REF-0022 | B26: U010 | D26: Social Media | E26: 46279.631 | I26: Expired | J26: =IF(H26<>"","Converted",IF(G26<>"","Activated",IF(F26<>"","Registered","Created"))) -> Created | K26: =IF(AND(I26="Expired",J26="Created"),"OK",IF(I26<>J26,"CHECK status",IF(OR(AND(G26<>"",F26=""),AND(H26<>"",G26="")),"CHECK gap",IF(OR(AND(F26<>"",F26<E26),AND(G26<>"",G26<F26),AND(H26<>"",H26<G26)),"CHECK order","OK")))) -> OK | L26: =IF(F26="","",F26-E26) | M26: =IF(G26="","",G26-F26) | N26: =IF(H26="","",H26-G26) | O26: =IF(H26="","",H26-E26) | P26: =IF(G26="","",IF(G26-F26<=Settings!$B$6,"Yes","No")) | Q26: =IF(COUNTIF($B$5:B26,B26)=1,1,0) -> 1 | R26: =IF(H26="",0,IF(COUNTIFS($B$5:B26,B26,$H$5:H26,"<>")=1,1,0)) -> 0
A27: REF-0023 | B27: U004 | D27: Email | E27: 46281.812 | I27: Created | J27: =IF(H27<>"","Converted",IF(G27<>"","Activated",IF(F27<>"","Registered","Created"))) -> Created | K27: =IF(AND(I27="Expired",J27="Created"),"OK",IF(I27<>J27,"CHECK status",IF(OR(AND(G27<>"",F27=""),AND(H27<>"",G27="")),"CHECK gap",IF(OR(AND(F27<>"",F27<E27),AND(G27<>"",G27<F27),AND(H27<>"",H27<G27)),"CHECK order","OK")))) -> OK | L27: =IF(F27="","",F27-E27) | M27: =IF(G27="","",G27-F27) | N27: =IF(H27="","",H27-G27) | O27: =IF(H27="","",H27-E27) | P27: =IF(G27="","",IF(G27-F27<=Settings!$B$6,"Yes","No")) | Q27: =IF(COUNTIF($B$5:B27,B27)=1,1,0) -> 0 | R27: =IF(H27="",0,IF(COUNTIFS($B$5:B27,B27,$H$5:H27,"<>")=1,1,0)) -> 0
A28: REF-0024 | B28: U002 | C28: R016 | D28: Email | E28: 46293.519 | F28: 46293.756 | I28: Registered | J28: =IF(H28<>"","Converted",IF(G28<>"","Activated",IF(F28<>"","Registered","Created"))) -> Registered | K28: =IF(AND(I28="Expired",J28="Created"),"OK",IF(I28<>J28,"CHECK status",IF(OR(AND(G28<>"",F28=""),AND(H28<>"",G28="")),"CHECK gap",IF(OR(AND(F28<>"",F28<E28),AND(G28<>"",G28<F28),AND(H28<>"",H28<G28)),"CHECK order","OK")))) -> OK | L28: =IF(F28="","",F28-E28) -> 0.23680556 | M28: =IF(G28="","",G28-F28) | N28: =IF(H28="","",H28-G28) | O28: =IF(H28="","",H28-E28) | P28: =IF(G28="","",IF(G28-F28<=Settings!$B$6,"Yes","No")) | Q28: =IF(COUNTIF($B$5:B28,B28)=1,1,0) -> 0 | R28: =IF(H28="",0,IF(COUNTIFS($B$5:B28,B28,$H$5:H28,"<>")=1,1,0)) -> 0
A29: REF-0025 | B29: U008 | C29: R017 | D29: In-App Invite | E29: 46287.83 | F29: 46288.895 | G29: 46291.937 | H29: 46295.937 | I29: Converted | J29: =IF(H29<>"","Converted",IF(G29<>"","Activated",IF(F29<>"","Registered","Created"))) -> Converted | K29: =IF(AND(I29="Expired",J29="Created"),"OK",IF(I29<>J29,"CHECK status",IF(OR(AND(G29<>"",F29=""),AND(H29<>"",G29="")),"CHECK gap",IF(OR(AND(F29<>"",F29<E29),AND(G29<>"",G29<F29),AND(H29<>"",H29<G29)),"CHECK order","OK")))) -> OK | L29: =IF(F29="","",F29-E29) -> 1.0652778 | M29: =IF(G29="","",G29-F29) -> 3.0416667 | N29: =IF(H29="","",H29-G29) -> 4 | O29: =IF(H29="","",H29-E29) -> 8.1069444 | P29: =IF(G29="","",IF(G29-F29<=Settings!$B$6,"Yes","No")) -> Yes | Q29: =IF(COUNTIF($B$5:B29,B29)=1,1,0) -> 0 | R29: =IF(H29="",0,IF(COUNTIFS($B$5:B29,B29,$H$5:H29,"<>")=1,1,0)) -> 0
A30: REF-0026 | B30: U004 | C30: R018 | D30: Email | E30: 46301.335 | F30: 46301.376 | I30: Registered | J30: =IF(H30<>"","Converted",IF(G30<>"","Activated",IF(F30<>"","Registered","Created"))) -> Registered | K30: =IF(AND(I30="Expired",J30="Created"),"OK",IF(I30<>J30,"CHECK status",IF(OR(AND(G30<>"",F30=""),AND(H30<>"",G30="")),"CHECK gap",IF(OR(AND(F30<>"",F30<E30),AND(G30<>"",G30<F30),AND(H30<>"",H30<G30)),"CHECK order","OK")))) -> OK | L30: =IF(F30="","",F30-E30) -> 0.040972222 | M30: =IF(G30="","",G30-F30) | N30: =IF(H30="","",H30-G30) | O30: =IF(H30="","",H30-E30) | P30: =IF(G30="","",IF(G30-F30<=Settings!$B$6,"Yes","No")) | Q30: =IF(COUNTIF($B$5:B30,B30)=1,1,0) -> 0 | R30: =IF(H30="",0,IF(COUNTIFS($B$5:B30,B30,$H$5:H30,"<>")=1,1,0)) -> 0
A31: REF-0027 | B31: U001 | D31: Email | E31: 46297.592 | I31: Created | J31: =IF(H31<>"","Converted",IF(G31<>"","Activated",IF(F31<>"","Registered","Created"))) -> Created | K31: =IF(AND(I31="Expired",J31="Created"),"OK",IF(I31<>J31,"CHECK status",IF(OR(AND(G31<>"",F31=""),AND(H31<>"",G31="")),"CHECK gap",IF(OR(AND(F31<>"",F31<E31),AND(G31<>"",G31<F31),AND(H31<>"",H31<G31)),"CHECK order","OK")))) -> OK | L31: =IF(F31="","",F31-E31) | M31: =IF(G31="","",G31-F31) | N31: =IF(H31="","",H31-G31) | O31: =IF(H31="","",H31-E31) | P31: =IF(G31="","",IF(G31-F31<=Settings!$B$6,"Yes","No")) | Q31: =IF(COUNTIF($B$5:B31,B31)=1,1,0) -> 0 | R31: =IF(H31="",0,IF(COUNTIFS($B$5:B31,B31,$H$5:H31,"<>")=1,1,0)) -> 0
A32: REF-0028 | B32: U008 | D32: WhatsApp | E32: 46266.553 | I32: Expired | J32: =IF(H32<>"","Converted",IF(G32<>"","Activated",IF(F32<>"","Registered","Created"))) -> Created | K32: =IF(AND(I32="Expired",J32="Created"),"OK",IF(I32<>J32,"CHECK status",IF(OR(AND(G32<>"",F32=""),AND(H32<>"",G32="")),"CHECK gap",IF(OR(AND(F32<>"",F32<E32),AND(G32<>"",G32<F32),AND(H32<>"",H32<G32)),"CHECK order","OK")))) -> OK | L32: =IF(F32="","",F32-E32) | M32: =IF(G32="","",G32-F32) | N32: =IF(H32="","",H32-G32) | O32: =IF(H32="","",H32-E32) | P32: =IF(G32="","",IF(G32-F32<=Settings!$B$6,"Yes","No")) | Q32: =IF(COUNTIF($B$5:B32,B32)=1,1,0) -> 0 | R32: =IF(H32="",0,IF(COUNTIFS($B$5:B32,B32,$H$5:H32,"<>")=1,1,0)) -> 0
A33: REF-0029 | B33: U010 | C33: R019 | D33: In-App Invite | E33: 46301.74 | F33: 46302.832 | I33: Registered | J33: =IF(H33<>"","Converted",IF(G33<>"","Activated",IF(F33<>"","Registered","Created"))) -> Registered | K33: =IF(AND(I33="Expired",J33="Created"),"OK",IF(I33<>J33,"CHECK status",IF(OR(AND(G33<>"",F33=""),AND(H33<>"",G33="")),"CHECK gap",IF(OR(AND(F33<>"",F33<E33),AND(G33<>"",G33<F33),AND(H33<>"",H33<G33)),"CHECK order","OK")))) -> OK | L33: =IF(F33="","",F33-E33) -> 1.0923611 | M33: =IF(G33="","",G33-F33) | N33: =IF(H33="","",H33-G33) | O33: =IF(H33="","",H33-E33) | P33: =IF(G33="","",IF(G33-F33<=Settings!$B$6,"Yes","No")) | Q33: =IF(COUNTIF($B$5:B33,B33)=1,1,0) -> 0 | R33: =IF(H33="",0,IF(COUNTIFS($B$5:B33,B33,$H$5:H33,"<>")=1,1,0)) -> 0
A34: REF-0030 | B34: U003 | C34: R020 | D34: Email | E34: 46269.764 | F34: 46276.971 | I34: Registered | J34: =IF(H34<>"","Converted",IF(G34<>"","Activated",IF(F34<>"","Registered","Created"))) -> Registered | K34: =IF(AND(I34="Expired",J34="Created"),"OK",IF(I34<>J34,"CHECK status",IF(OR(AND(G34<>"",F34=""),AND(H34<>"",G34="")),"CHECK gap",IF(OR(AND(F34<>"",F34<E34),AND(G34<>"",G34<F34),AND(H34<>"",H34<G34)),"CHECK order","OK")))) -> OK | L34: =IF(F34="","",F34-E34) -> 7.2069444 | M34: =IF(G34="","",G34-F34) | N34: =IF(H34="","",H34-G34) | O34: =IF(H34="","",H34-E34) | P34: =IF(G34="","",IF(G34-F34<=Settings!$B$6,"Yes","No")) | Q34: =IF(COUNTIF($B$5:B34,B34)=1,1,0) -> 0 | R34: =IF(H34="",0,IF(COUNTIFS($B$5:B34,B34,$H$5:H34,"<>")=1,1,0)) -> 0
A35: REF-0031 | B35: U010 | C35: R021 | D35: Email | E35: 46298.371 | F35: 46298.617 | G35: 46298.784 | H35: 46308.784 | I35: Converted | J35: =IF(H35<>"","Converted",IF(G35<>"","Activated",IF(F35<>"","Registered","Created"))) -> Converted | K35: =IF(AND(I35="Expired",J35="Created"),"OK",IF(I35<>J35,"CHECK status",IF(OR(AND(G35<>"",F35=""),AND(H35<>"",G35="")),"CHECK gap",IF(OR(AND(F35<>"",F35<E35),AND(G35<>"",G35<F35),AND(H35<>"",H35<G35)),"CHECK order","OK")))) -> OK | L35: =IF(F35="","",F35-E35) -> 0.24652778 | M35: =IF(G35="","",G35-F35) -> 0.16666667 | N35: =IF(H35="","",H35-G35) -> 10 | O35: =IF(H35="","",H35-E35) -> 10.413194 | P35: =IF(G35="","",IF(G35-F35<=Settings!$B$6,"Yes","No")) -> Yes | Q35: =IF(COUNTIF($B$5:B35,B35)=1,1,0) -> 0 | R35: =IF(H35="",0,IF(COUNTIFS($B$5:B35,B35,$H$5:H35,"<>")=1,1,0)) -> 1
A36: REF-0032 | B36: U004 | C36: R022 | D36: WhatsApp | E36: 46303.69 | F36: 46305.76 | I36: Registered | J36: =IF(H36<>"","Converted",IF(G36<>"","Activated",IF(F36<>"","Registered","Created"))) -> Registered | K36: =IF(AND(I36="Expired",J36="Created"),"OK",IF(I36<>J36,"CHECK status",IF(OR(AND(G36<>"",F36=""),AND(H36<>"",G36="")),"CHECK gap",IF(OR(AND(F36<>"",F36<E36),AND(G36<>"",G36<F36),AND(H36<>"",H36<G36)),"CHECK order","OK")))) -> OK | L36: =IF(F36="","",F36-E36) -> 2.0708333 | M36: =IF(G36="","",G36-F36) | N36: =IF(H36="","",H36-G36) | O36: =IF(H36="","",H36-E36) | P36: =IF(G36="","",IF(G36-F36<=Settings!$B$6,"Yes","No")) | Q36: =IF(COUNTIF($B$5:B36,B36)=1,1,0) -> 0 | R36: =IF(H36="",0,IF(COUNTIFS($B$5:B36,B36,$H$5:H36,"<>")=1,1,0)) -> 0
A37: REF-0033 | B37: U005 | C37: R023 | D37: Email | E37: 46274.737 | F37: 46277.737 | G37: 46281.737 | H37: 46285.903 | I37: Converted | J37: =IF(H37<>"","Converted",IF(G37<>"","Activated",IF(F37<>"","Registered","Created"))) -> Converted | K37: =IF(AND(I37="Expired",J37="Created"),"OK",IF(I37<>J37,"CHECK status",IF(OR(AND(G37<>"",F37=""),AND(H37<>"",G37="")),"CHECK gap",IF(OR(AND(F37<>"",F37<E37),AND(G37<>"",G37<F37),AND(H37<>"",H37<G37)),"CHECK order","OK")))) -> OK | L37: =IF(F37="","",F37-E37) -> 3 | M37: =IF(G37="","",G37-F37) -> 4 | N37: =IF(H37="","",H37-G37) -> 4.1666667 | O37: =IF(H37="","",H37-E37) -> 11.166667 | P37: =IF(G37="","",IF(G37-F37<=Settings!$B$6,"Yes","No")) -> Yes | Q37: =IF(COUNTIF($B$5:B37,B37)=1,1,0) -> 0 | R37: =IF(H37="",0,IF(COUNTIFS($B$5:B37,B37,$H$5:H37,"<>")=1,1,0)) -> 1
A38: REF-0034 | B38: U006 | D38: WhatsApp | E38: 46288.878 | I38: Created | J38: =IF(H38<>"","Converted",IF(G38<>"","Activated",IF(F38<>"","Registered","Created"))) -> Created | K38: =IF(AND(I38="Expired",J38="Created"),"OK",IF(I38<>J38,"CHECK status",IF(OR(AND(G38<>"",F38=""),AND(H38<>"",G38="")),"CHECK gap",IF(OR(AND(F38<>"",F38<E38),AND(G38<>"",G38<F38),AND(H38<>"",H38<G38)),"CHECK order","OK")))) -> OK | L38: =IF(F38="","",F38-E38) | M38: =IF(G38="","",G38-F38) | N38: =IF(H38="","",H38-G38) | O38: =IF(H38="","",H38-E38) | P38: =IF(G38="","",IF(G38-F38<=Settings!$B$6,"Yes","No")) | Q38: =IF(COUNTIF($B$5:B38,B38)=1,1,0) -> 0 | R38: =IF(H38="",0,IF(COUNTIFS($B$5:B38,B38,$H$5:H38,"<>")=1,1,0)) -> 0
A39: REF-0035 | B39: U003 | C39: R024 | D39: WhatsApp | E39: 46294.857 | F39: 46295.101 | G39: 46300.101 | I39: Activated | J39: =IF(H39<>"","Converted",IF(G39<>"","Activated",IF(F39<>"","Registered","Created"))) -> Activated | K39: =IF(AND(I39="Expired",J39="Created"),"OK",IF(I39<>J39,"CHECK status",IF(OR(AND(G39<>"",F39=""),AND(H39<>"",G39="")),"CHECK gap",IF(OR(AND(F39<>"",F39<E39),AND(G39<>"",G39<F39),AND(H39<>"",H39<G39)),"CHECK order","OK")))) -> OK | L39: =IF(F39="","",F39-E39) -> 0.24444444 | M39: =IF(G39="","",G39-F39) -> 5 | N39: =IF(H39="","",H39-G39) | O39: =IF(H39="","",H39-E39) | P39: =IF(G39="","",IF(G39-F39<=Settings!$B$6,"Yes","No")) -> Yes | Q39: =IF(COUNTIF($B$5:B39,B39)=1,1,0) -> 0 | R39: =IF(H39="",0,IF(COUNTIFS($B$5:B39,B39,$H$5:H39,"<>")=1,1,0)) -> 0
A40: REF-0036 | B40: U004 | C40: R025 | D40: In-App Invite | E40: 46272.774 | F40: 46274.95 | I40: Registered | J40: =IF(H40<>"","Converted",IF(G40<>"","Activated",IF(F40<>"","Registered","Created"))) -> Registered | K40: =IF(AND(I40="Expired",J40="Created"),"OK",IF(I40<>J40,"CHECK status",IF(OR(AND(G40<>"",F40=""),AND(H40<>"",G40="")),"CHECK gap",IF(OR(AND(F40<>"",F40<E40),AND(G40<>"",G40<F40),AND(H40<>"",H40<G40)),"CHECK order","OK")))) -> OK | L40: =IF(F40="","",F40-E40) -> 2.1756944 | M40: =IF(G40="","",G40-F40) | N40: =IF(H40="","",H40-G40) | O40: =IF(H40="","",H40-E40) | P40: =IF(G40="","",IF(G40-F40<=Settings!$B$6,"Yes","No")) | Q40: =IF(COUNTIF($B$5:B40,B40)=1,1,0) -> 0 | R40: =IF(H40="",0,IF(COUNTIFS($B$5:B40,B40,$H$5:H40,"<>")=1,1,0)) -> 0
A41: REF-0037 | B41: U005 | C41: R026 | D41: Email | E41: 46282.647 | F41: 46282.674 | G41: 46284.674 | H41: 46287.883 | I41: Converted | J41: =IF(H41<>"","Converted",IF(G41<>"","Activated",IF(F41<>"","Registered","Created"))) -> Converted | K41: =IF(AND(I41="Expired",J41="Created"),"OK",IF(I41<>J41,"CHECK status",IF(OR(AND(G41<>"",F41=""),AND(H41<>"",G41="")),"CHECK gap",IF(OR(AND(F41<>"",F41<E41),AND(G41<>"",G41<F41),AND(H41<>"",H41<G41)),"CHECK order","OK")))) -> OK | L41: =IF(F41="","",F41-E41) -> 0.027777778 | M41: =IF(G41="","",G41-F41) -> 2 | N41: =IF(H41="","",H41-G41) -> 3.2083333 | O41: =IF(H41="","",H41-E41) -> 5.2361111 | P41: =IF(G41="","",IF(G41-F41<=Settings!$B$6,"Yes","No")) -> Yes | Q41: =IF(COUNTIF($B$5:B41,B41)=1,1,0) -> 0 | R41: =IF(H41="",0,IF(COUNTIFS($B$5:B41,B41,$H$5:H41,"<>")=1,1,0)) -> 0
...

Sheet Engagement_Events
A1: Engagement Events (E2) - one row per user event
A2: Blue = input event log. Grey = helper formulas that make distinct counts possible (copy down for new rows). Event Type: Login / Feature Use / Task Completed.
A4: Event ID | B4: User ID | C4: Event Date | D4: Event Type | E4: Feature | F4: User Group (auto) | G4: First Event of User-Day | H4: Returning User-Day | I4: First Use of Feature by User | J4: Repeat (2nd) Use of Feature by User | K4: First Event of User (ever) | L4: First Event of User in WAU Window | M4: First Event of User in MAU Window | N4: First Feature Use of User (any feature)
A5: EVT-00001 | B5: O002 | C5: 46266 | D5: Login | E5: n/a | F5: =IF(COUNTIF(Referral_Data!$C$5:$C$1000,B5)>0,"Referred",IF(COUNTIF(Referral_Data!$B$5:$B$1000,B5)>0,"Referrer","Organic")) -> Organic | G5: =IF(COUNTIFS($B$5:B5,B5,$C$5:C5,C5)=1,1,0) -> 1 | H5: =IF(AND(G5=1,COUNTIFS($B$5:$B$1635,B5,$C$5:$C$1635,"<"&C5)>0),1,0) -> 0 | I5: =IF(AND(D5="Feature Use",COUNTIFS($B$5:B5,B5,$D$5:D5,"Feature Use",$E$5:E5,E5)=1),1,0) -> 0 | J5: =IF(AND(D5="Feature Use",COUNTIFS($B$5:B5,B5,$D$5:D5,"Feature Use",$E$5:E5,E5)=2),1,0) -> 0 | K5: =IF(COUNTIF($B$5:B5,B5)=1,1,0) -> 1 | L5: =IF(AND(C5>=Settings!$B$5-Settings!$B$8+1,C5<=Settings!$B$5,COUNTIFS($B$5:B5,B5,$C$5:C5,">="&(Settings!$B$5-Settings!$B$8+1),$C$5:C5,"<="&Settings!$B$5)=1),1,0) -> 0 | M5: =IF(AND(C5>=Settings!$B$5-Settings!$B$9+1,C5<=Settings!$B$5,COUNTIFS($B$5:B5,B5,$C$5:C5,">="&(Settings!$B$5-Settings!$B$9+1),$C$5:C5,"<="&Settings!$B$5)=1),1,0) -> 0 | N5: =IF(AND(D5="Feature Use",COUNTIFS($B$5:B5,B5,$D$5:D5,"Feature Use")=1),1,0) -> 0
A6: EVT-00002 | B6: O002 | C6: 46266 | D6: Feature Use | E6: Chat | F6: =IF(COUNTIF(Referral_Data!$C$5:$C$1000,B6)>0,"Referred",IF(COUNTIF(Referral_Data!$B$5:$B$1000,B6)>0,"Referrer","Organic")) -> Organic | G6: =IF(COUNTIFS($B$5:B6,B6,$C$5:C6,C6)=1,1,0) -> 0 | H6: =IF(AND(G6=1,COUNTIFS($B$5:$B$1635,B6,$C$5:$C$1635,"<"&C6)>0),1,0) -> 0 | I6: =IF(AND(D6="Feature Use",COUNTIFS($B$5:B6,B6,$D$5:D6,"Feature Use",$E$5:E6,E6)=1),1,0) -> 1 | J6: =IF(AND(D6="Feature Use",COUNTIFS($B$5:B6,B6,$D$5:D6,"Feature Use",$E$5:E6,E6)=2),1,0) -> 0 | K6: =IF(COUNTIF($B$5:B6,B6)=1,1,0) -> 0 | L6: =IF(AND(C6>=Settings!$B$5-Settings!$B$8+1,C6<=Settings!$B$5,COUNTIFS($B$5:B6,B6,$C$5:C6,">="&(Settings!$B$5-Settings!$B$8+1),$C$5:C6,"<="&Settings!$B$5)=1),1,0) -> 0 | M6: =IF(AND(C6>=Settings!$B$5-Settings!$B$9+1,C6<=Settings!$B$5,COUNTIFS($B$5:B6,B6,$C$5:C6,">="&(Settings!$B$5-Settings!$B$9+1),$C$5:C6,"<="&Settings!$B$5)=1),1,0) -> 0 | N6: =IF(AND(D6="Feature Use",COUNTIFS($B$5:B6,B6,$D$5:D6,"Feature Use")=1),1,0) -> 1
A7: EVT-00003 | B7: O004 | C7: 46266 | D7: Login | E7: n/a | F7: =IF(COUNTIF(Referral_Data!$C$5:$C$1000,B7)>0,"Referred",IF(COUNTIF(Referral_Data!$B$5:$B$1000,B7)>0,"Referrer","Organic")) -> Organic | G7: =IF(COUNTIFS($B$5:B7,B7,$C$5:C7,C7)=1,1,0) -> 1 | H7: =IF(AND(G7=1,COUNTIFS($B$5:$B$1635,B7,$C$5:$C$1635,"<"&C7)>0),1,0) -> 0 | I7: =IF(AND(D7="Feature Use",COUNTIFS($B$5:B7,B7,$D$5:D7,"Feature Use",$E$5:E7,E7)=1),1,0) -> 0 | J7: =IF(AND(D7="Feature Use",COUNTIFS($B$5:B7,B7,$D$5:D7,"Feature Use",$E$5:E7,E7)=2),1,0) -> 0 | K7: =IF(COUNTIF($B$5:B7,B7)=1,1,0) -> 1 | L7: =IF(AND(C7>=Settings!$B$5-Settings!$B$8+1,C7<=Settings!$B$5,COUNTIFS($B$5:B7,B7,$C$5:C7,">="&(Settings!$B$5-Settings!$B$8+1),$C$5:C7,"<="&Settings!$B$5)=1),1,0) -> 0 | M7: =IF(AND(C7>=Settings!$B$5-Settings!$B$9+1,C7<=Settings!$B$5,COUNTIFS($B$5:B7,B7,$C$5:C7,">="&(Settings!$B$5-Settings!$B$9+1),$C$5:C7,"<="&Settings!$B$5)=1),1,0) -> 0 | N7: =IF(AND(D7="Feature Use",COUNTIFS($B$5:B7,B7,$D$5:D7,"Feature Use")=1),1,0) -> 0
A8: EVT-00004 | B8: O004 | C8: 46266 | D8: Feature Use | E8: Dashboard | F8: =IF(COUNTIF(Referral_Data!$C$5:$C$1000,B8)>0,"Referred",IF(COUNTIF(Referral_Data!$B$5:$B$1000,B8)>0,"Referrer","Organic")) -> Organic | G8: =IF(COUNTIFS($B$5:B8,B8,$C$5:C8,C8)=1,1,0) -> 0 | H8: =IF(AND(G8=1,COUNTIFS($B$5:$B$1635,B8,$C$5:$C$1635,"<"&C8)>0),1,0) -> 0 | I8: =IF(AND(D8="Feature Use",COUNTIFS($B$5:B8,B8,$D$5:D8,"Feature Use",$E$5:E8,E8)=1),1,0) -> 1 | J8: =IF(AND(D8="Feature Use",COUNTIFS($B$5:B8,B8,$D$5:D8,"Feature Use",$E$5:E8,E8)=2),1,0) -> 0 | K8: =IF(COUNTIF($B$5:B8,B8)=1,1,0) -> 0 | L8: =IF(AND(C8>=Settings!$B$5-Settings!$B$8+1,C8<=Settings!$B$5,COUNTIFS($B$5:B8,B8,$C$5:C8,">="&(Settings!$B$5-Settings!$B$8+1),$C$5:C8,"<="&Settings!$B$5)=1),1,0) -> 0 | M8: =IF(AND(C8>=Settings!$B$5-Settings!$B$9+1,C8<=Settings!$B$5,COUNTIFS($B$5:B8,B8,$C$5:C8,">="&(Settings!$B$5-Settings!$B$9+1),$C$5:C8,"<="&Settings!$B$5)=1),1,0) -> 0 | N8: =IF(AND(D8="Feature Use",COUNTIFS($B$5:B8,B8,$D$5:D8,"Feature Use")=1),1,0) -> 1
A9: EVT-00005 | B9: O004 | C9: 46266 | D9: Feature Use | E9: Dashboard | F9: =IF(COUNTIF(Referral_Data!$C$5:$C$1000,B9)>0,"Referred",IF(COUNTIF(Referral_Data!$B$5:$B$1000,B9)>0,"Referrer","Organic")) -> Organic | G9: =IF(COUNTIFS($B$5:B9,B9,$C$5:C9,C9)=1,1,0) -> 0 | H9: =IF(AND(G9=1,COUNTIFS($B$5:$B$1635,B9,$C$5:$C$1635,"<"&C9)>0),1,0) -> 0 | I9: =IF(AND(D9="Feature Use",COUNTIFS($B$5:B9,B9,$D$5:D9,"Feature Use",$E$5:E9,E9)=1),1,0) -> 0 | J9: =IF(AND(D9="Feature Use",COUNTIFS($B$5:B9,B9,$D$5:D9,"Feature Use",$E$5:E9,E9)=2),1,0) -> 1 | K9: =IF(COUNTIF($B$5:B9,B9)=1,1,0) -> 0 | L9: =IF(AND(C9>=Settings!$B$5-Settings!$B$8+1,C9<=Settings!$B$5,COUNTIFS($B$5:B9,B9,$C$5:C9,">="&(Settings!$B$5-Settings!$B$8+1),$C$5:C9,"<="&Settings!$B$5)=1),1,0) -> 0 | M9: =IF(AND(C9>=Settings!$B$5-Settings!$B$9+1,C9<=Settings!$B$5,COUNTIFS($B$5:B9,B9,$C$5:C9,">="&(Settings!$B$5-Settings!$B$9+1),$C$5:C9,"<="&Settings!$B$5)=1),1,0) -> 0 | N9: =IF(AND(D9="Feature Use",COUNTIFS($B$5:B9,B9,$D$5:D9,"Feature Use")=1),1,0) -> 0
A10: EVT-00006 | B10: O004 | C10: 46266 | D10: Task Completed | E10: Export | F10: =IF(COUNTIF(Referral_Data!$C$5:$C$1000,B10)>0,"Referred",IF(COUNTIF(Referral_Data!$B$5:$B$1000,B10)>0,"Referrer","Organic")) -> Organic | G10: =IF(COUNTIFS($B$5:B10,B10,$C$5:C10,C10)=1,1,0) -> 0 | H10: =IF(AND(G10=1,COUNTIFS($B$5:$B$1635,B10,$C$5:$C$1635,"<"&C10)>0),1,0) -> 0 | I10: =IF(AND(D10="Feature Use",COUNTIFS($B$5:B10,B10,$D$5:D10,"Feature Use",$E$5:E10,E10)=1),1,0) -> 0 | J10: =IF(AND(D10="Feature Use",COUNTIFS($B$5:B10,B10,$D$5:D10,"Feature Use",$E$5:E10,E10)=2),1,0) -> 0 | K10: =IF(COUNTIF($B$5:B10,B10)=1,1,0) -> 0 | L10: =IF(AND(C10>=Settings!$B$5-Settings!$B$8+1,C10<=Settings!$B$5,COUNTIFS($B$5:B10,B10,$C$5:C10,">="&(Settings!$B$5-Settings!$B$8+1),$C$5:C10,"<="&Settings!$B$5)=1),1,0) -> 0 | M10: =IF(AND(C10>=Settings!$B$5-Settings!$B$9+1,C10<=Settings!$B$5,COUNTIFS($B$5:B10,B10,$C$5:C10,">="&(Settings!$B$5-Settings!$B$9+1),$C$5:C10,"<="&Settings!$B$5)=1),1,0) -> 0 | N10: =IF(AND(D10="Feature Use",COUNTIFS($B$5:B10,B10,$D$5:D10,"Feature Use")=1),1,0) -> 0
A11: EVT-00007 | B11: O004 | C11: 46266 | D11: Task Completed | E11: Reports | F11: =IF(COUNTIF(Referral_Data!$C$5:$C$1000,B11)>0,"Referred",IF(COUNTIF(Referral_Data!$B$5:$B$1000,B11)>0,"Referrer","Organic")) -> Organic | G11: =IF(COUNTIFS($B$5:B11,B11,$C$5:C11,C11)=1,1,0) -> 0 | H11: =IF(AND(G11=1,COUNTIFS($B$5:$B$1635,B11,$C$5:$C$1635,"<"&C11)>0),1,0) -> 0 | I11: =IF(AND(D11="Feature Use",COUNTIFS($B$5:B11,B11,$D$5:D11,"Feature Use",$E$5:E11,E11)=1),1,0) -> 0 | J11: =IF(AND(D11="Feature Use",COUNTIFS($B$5:B11,B11,$D$5:D11,"Feature Use",$E$5:E11,E11)=2),1,0) -> 0 | K11: =IF(COUNTIF($B$5:B11,B11)=1,1,0) -> 0 | L11: =IF(AND(C11>=Settings!$B$5-Settings!$B$8+1,C11<=Settings!$B$5,COUNTIFS($B$5:B11,B11,$C$5:C11,">="&(Settings!$B$5-Settings!$B$8+1),$C$5:C11,"<="&Settings!$B$5)=1),1,0) -> 0 | M11: =IF(AND(C11>=Settings!$B$5-Settings!$B$9+1,C11<=Settings!$B$5,COUNTIFS($B$5:B11,B11,$C$5:C11,">="&(Settings!$B$5-Settings!$B$9+1),$C$5:C11,"<="&Settings!$B$5)=1),1,0) -> 0 | N11: =IF(AND(D11="Feature Use",COUNTIFS($B$5:B11,B11,$D$5:D11,"Feature Use")=1),1,0) -> 0
A12: EVT-00008 | B12: O008 | C12: 46266 | D12: Login | E12: n/a | F12: =IF(COUNTIF(Referral_Data!$C$5:$C$1000,B12)>0,"Referred",IF(COUNTIF(Referral_Data!$B$5:$B$1000,B12)>0,"Referrer","Organic")) -> Organic | G12: =IF(COUNTIFS($B$5:B12,B12,$C$5:C12,C12)=1,1,0) -> 1 | H12: =IF(AND(G12=1,COUNTIFS($B$5:$B$1635,B12,$C$5:$C$1635,"<"&C12)>0),1,0) -> 0 | I12: =IF(AND(D12="Feature Use",COUNTIFS($B$5:B12,B12,$D$5:D12,"Feature Use",$E$5:E12,E12)=1),1,0) -> 0 | J12: =IF(AND(D12="Feature Use",COUNTIFS($B$5:B12,B12,$D$5:D12,"Feature Use",$E$5:E12,E12)=2),1,0) -> 0 | K12: =IF(COUNTIF($B$5:B12,B12)=1,1,0) -> 1 | L12: =IF(AND(C12>=Settings!$B$5-Settings!$B$8+1,C12<=Settings!$B$5,COUNTIFS($B$5:B12,B12,$C$5:C12,">="&(Settings!$B$5-Settings!$B$8+1),$C$5:C12,"<="&Settings!$B$5)=1),1,0) -> 0 | M12: =IF(AND(C12>=Settings!$B$5-Settings!$B$9+1,C12<=Settings!$B$5,COUNTIFS($B$5:B12,B12,$C$5:C12,">="&(Settings!$B$5-Settings!$B$9+1),$C$5:C12,"<="&Settings!$B$5)=1),1,0) -> 0 | N12: =IF(AND(D12="Feature Use",COUNTIFS($B$5:B12,B12,$D$5:D12,"Feature Use")=1),1,0) -> 0
A13: EVT-00009 | B13: O008 | C13: 46266 | D13: Feature Use | E13: Chat | F13: =IF(COUNTIF(Referral_Data!$C$5:$C$1000,B13)>0,"Referred",IF(COUNTIF(Referral_Data!$B$5:$B$1000,B13)>0,"Referrer","Organic")) -> Organic | G13: =IF(COUNTIFS($B$5:B13,B13,$C$5:C13,C13)=1,1,0) -> 0 | H13: =IF(AND(G13=1,COUNTIFS($B$5:$B$1635,B13,$C$5:$C$1635,"<"&C13)>0),1,0) -> 0 | I13: =IF(AND(D13="Feature Use",COUNTIFS($B$5:B13,B13,$D$5:D13,"Feature Use",$E$5:E13,E13)=1),1,0) -> 1 | J13: =IF(AND(D13="Feature Use",COUNTIFS($B$5:B13,B13,$D$5:D13,"Feature Use",$E$5:E13,E13)=2),1,0) -> 0 | K13: =IF(COUNTIF($B$5:B13,B13)=1,1,0) -> 0 | L13: =IF(AND(C13>=Settings!$B$5-Settings!$B$8+1,C13<=Settings!$B$5,COUNTIFS($B$5:B13,B13,$C$5:C13,">="&(Settings!$B$5-Settings!$B$8+1),$C$5:C13,"<="&Settings!$B$5)=1),1,0) -> 0 | M13: =IF(AND(C13>=Settings!$B$5-Settings!$B$9+1,C13<=Settings!$B$5,COUNTIFS($B$5:B13,B13,$C$5:C13,">="&(Settings!$B$5-Settings!$B$9+1),$C$5:C13,"<="&Settings!$B$5)=1),1,0) -> 0 | N13: =IF(AND(D13="Feature Use",COUNTIFS($B$5:B13,B13,$D$5:D13,"Feature Use")=1),1,0) -> 1
A14: EVT-00010 | B14: O008 | C14: 46266 | D14: Task Completed | E14: Dashboard | F14: =IF(COUNTIF(Referral_Data!$C$5:$C$1000,B14)>0,"Referred",IF(COUNTIF(Referral_Data!$B$5:$B$1000,B14)>0,"Referrer","Organic")) -> Organic | G14: =IF(COUNTIFS($B$5:B14,B14,$C$5:C14,C14)=1,1,0) -> 0 | H14: =IF(AND(G14=1,COUNTIFS($B$5:$B$1635,B14,$C$5:$C$1635,"<"&C14)>0),1,0) -> 0 | I14: =IF(AND(D14="Feature Use",COUNTIFS($B$5:B14,B14,$D$5:D14,"Feature Use",$E$5:E14,E14)=1),1,0) -> 0 | J14: =IF(AND(D14="Feature Use",COUNTIFS($B$5:B14,B14,$D$5:D14,"Feature Use",$E$5:E14,E14)=2),1,0) -> 0 | K14: =IF(COUNTIF($B$5:B14,B14)=1,1,0) -> 0 | L14: =IF(AND(C14>=Settings!$B$5-Settings!$B$8+1,C14<=Settings!$B$5,COUNTIFS($B$5:B14,B14,$C$5:C14,">="&(Settings!$B$5-Settings!$B$8+1),$C$5:C14,"<="&Settings!$B$5)=1),1,0) -> 0 | M14: =IF(AND(C14>=Settings!$B$5-Settings!$B$9+1,C14<=Settings!$B$5,COUNTIFS($B$5:B14,B14,$C$5:C14,">="&(Settings!$B$5-Settings!$B$9+1),$C$5:C14,"<="&Settings!$B$5)=1),1,0) -> 0 | N14: =IF(AND(D14="Feature Use",COUNTIFS($B$5:B14,B14,$D$5:D14,"Feature Use")=1),1,0) -> 0
A15: EVT-00011 | B15: U006 | C15: 46266 | D15: Login | E15: n/a | F15: =IF(COUNTIF(Referral_Data!$C$5:$C$1000,B15)>0,"Referred",IF(COUNTIF(Referral_Data!$B$5:$B$1000,B15)>0,"Referrer","Organic")) -> Referrer | G15: =IF(COUNTIFS($B$5:B15,B15,$C$5:C15,C15)=1,1,0) -> 1 | H15: =IF(AND(G15=1,COUNTIFS($B$5:$B$1635,B15,$C$5:$C$1635,"<"&C15)>0),1,0) -> 0 | I15: =IF(AND(D15="Feature Use",COUNTIFS($B$5:B15,B15,$D$5:D15,"Feature Use",$E$5:E15,E15)=1),1,0) -> 0 | J15: =IF(AND(D15="Feature Use",COUNTIFS($B$5:B15,B15,$D$5:D15,"Feature Use",$E$5:E15,E15)=2),1,0) -> 0 | K15: =IF(COUNTIF($B$5:B15,B15)=1,1,0) -> 1 | L15: =IF(AND(C15>=Settings!$B$5-Settings!$B$8+1,C15<=Settings!$B$5,COUNTIFS($B$5:B15,B15,$C$5:C15,">="&(Settings!$B$5-Settings!$B$8+1),$C$5:C15,"<="&Settings!$B$5)=1),1,0) -> 0 | M15: =IF(AND(C15>=Settings!$B$5-Settings!$B$9+1,C15<=Settings!$B$5,COUNTIFS($B$5:B15,B15,$C$5:C15,">="&(Settings!$B$5-Settings!$B$9+1),$C$5:C15,"<="&Settings!$B$5)=1),1,0) -> 0 | N15: =IF(AND(D15="Feature Use",COUNTIFS($B$5:B15,B15,$D$5:D15,"Feature Use")=1),1,0) -> 0
A16: EVT-00012 | B16: U006 | C16: 46266 | D16: Feature Use | E16: Dashboard | F16: =IF(COUNTIF(Referral_Data!$C$5:$C$1000,B16)>0,"Referred",IF(COUNTIF(Referral_Data!$B$5:$B$1000,B16)>0,"Referrer","Organic")) -> Referrer | G16: =IF(COUNTIFS($B$5:B16,B16,$C$5:C16,C16)=1,1,0) -> 0 | H16: =IF(AND(G16=1,COUNTIFS($B$5:$B$1635,B16,$C$5:$C$1635,"<"&C16)>0),1,0) -> 0 | I16: =IF(AND(D16="Feature Use",COUNTIFS($B$5:B16,B16,$D$5:D16,"Feature Use",$E$5:E16,E16)=1),1,0) -> 1 | J16: =IF(AND(D16="Feature Use",COUNTIFS($B$5:B16,B16,$D$5:D16,"Feature Use",$E$5:E16,E16)=2),1,0) -> 0 | K16: =IF(COUNTIF($B$5:B16,B16)=1,1,0) -> 0 | L16: =IF(AND(C16>=Settings!$B$5-Settings!$B$8+1,C16<=Settings!$B$5,COUNTIFS($B$5:B16,B16,$C$5:C16,">="&(Settings!$B$5-Settings!$B$8+1),$C$5:C16,"<="&Settings!$B$5)=1),1,0) -> 0 | M16: =IF(AND(C16>=Settings!$B$5-Settings!$B$9+1,C16<=Settings!$B$5,COUNTIFS($B$5:B16,B16,$C$5:C16,">="&(Settings!$B$5-Settings!$B$9+1),$C$5:C16,"<="&Settings!$B$5)=1),1,0) -> 0 | N16: =IF(AND(D16="Feature Use",COUNTIFS($B$5:B16,B16,$D$5:D16,"Feature Use")=1),1,0) -> 1
... A1635: EVT-01631 | B1635: U012 | C1635: 46310 | D1635: Task Completed | E1635: Dashboard | F1635: =IF(COUNTIF(Referral_Data!$C$5:$C$1000,B1635)>0,"Referred",IF(COUNTIF(Referral_Data!$B$5:$B$1000,B1635)>0,"Referrer","Organic")) -> Referrer | G1635: =IF(COUNTIFS($B$5:B1635,B1635,$C$5:C1635,C1635)=1,1,0) -> 0 | H1635: =IF(AND(G1635=1,COUNTIFS($B$5:$B$1635,B1635,$C$5:$C$1635,"<"&C1635)>0),1,0) -> 0 | I1635: =IF(AND(D1635="Feature Use",COUNTIFS($B$5:B1635,B1635,$D$5:D1635,"Feature Use",$E$5:E1635,E1635)=1),1,0) -> 0 | J1635: =IF(AND(D1635="Feature Use",COUNTIFS($B$5:B1635,B1635,$D$5:D1635,"Feature Use",$E$5:E1635,E1635)=2),1,0) -> 0 | K1635: =IF(COUNTIF($B$5:B1635,B1635)=1,1,0) -> 0 | L1635: =IF(AND(C1635>=Settings!$B$5-Settings!$B$8+1,C1635<=Settings!$B$5,COUNTIFS($B$5:B1635,B1635,$C$5:C1635,">="&(Settings!$B$5-Settings!$B$8+1),$C$5:C1635,"<="&Settings!$B$5)=1),1,0) -> 0 | M1635: =IF(AND(C1635>=Settings!$B$5-Settings!$B$9+1,C1635<=Settings!$B$5,COUNTIFS($B$5:B1635,B1635,$C$5:C1635,">="&(Settings!$B$5-Settings!$B$9+1),$C$5:C1635,"<="&Settings!$B$5)=1),1,0) -> 0 | N1635: =IF(AND(D1635="Feature Use",COUNTIFS($B$5:B1635,B1635,$D$5:D1635,"Feature Use")=1),1,0) -> 0

Sheet Daily_Activity
A1: Daily Activity & Daily Referral Funnel
A2: All cells are formulas driven by Referral_Data, Engagement_Events and Settings. Add rows (copy last row down) if the reporting period grows.
A4: Date | B4: Referrals Created | C4: Users Registered | D4: Users Activated | E4: Referrals Converted | F4: DAU (Active Users) | G4: New Users (first-ever activity) | H4: Returning Users | I4: Logins | J4: Feature Uses | K4: Task Completions | L4: Cumulative Created | M4: Cumulative Converted | N4: Cumulative Conversion Rate
A5: =Settings!$B$4 -> 46266 | B5: =COUNTIFS(Referral_Data!$E$5:$E$1000,">="&$A5,Referral_Data!$E$5:$E$1000,"<"&($A5+1)) -> 2 | C5: =COUNTIFS(Referral_Data!$F$5:$F$1000,">="&$A5,Referral_Data!$F$5:$F$1000,"<"&($A5+1)) -> 0 | D5: =COUNTIFS(Referral_Data!$G$5:$G$1000,">="&$A5,Referral_Data!$G$5:$G$1000,"<"&($A5+1)) -> 0 | E5: =COUNTIFS(Referral_Data!$H$5:$H$1000,">="&$A5,Referral_Data!$H$5:$H$1000,"<"&($A5+1)) -> 0 | F5: =SUMIFS(Engagement_Events!$G$5:$G$3000,Engagement_Events!$C$5:$C$3000,$A5) -> 6 | G5: =SUMIFS(Engagement_Events!$K$5:$K$3000,Engagement_Events!$C$5:$C$3000,$A5) -> 6 | H5: =SUMIFS(Engagement_Events!$H$5:$H$3000,Engagement_Events!$C$5:$C$3000,$A5) -> 0 | I5: =COUNTIFS(Engagement_Events!$C$5:$C$3000,$A5,Engagement_Events!$D$5:$D$3000,"Login") -> 6 | J5: =COUNTIFS(Engagement_Events!$C$5:$C$3000,$A5,Engagement_Events!$D$5:$D$3000,"Feature Use") -> 8 | K5: =COUNTIFS(Engagement_Events!$C$5:$C$3000,$A5,Engagement_Events!$D$5:$D$3000,"Task Completed") -> 5 | L5: =SUM($B$5:B5) -> 2 | M5: =SUM($E$5:E5) -> 0 | N5: =IF(L5=0,0,M5/L5) -> 0
A6: =A5+1 -> 46267 | B6: =COUNTIFS(Referral_Data!$E$5:$E$1000,">="&$A6,Referral_Data!$E$5:$E$1000,"<"&($A6+1)) -> 1 | C6: =COUNTIFS(Referral_Data!$F$5:$F$1000,">="&$A6,Referral_Data!$F$5:$F$1000,"<"&($A6+1)) -> 1 | D6: =COUNTIFS(Referral_Data!$G$5:$G$1000,">="&$A6,Referral_Data!$G$5:$G$1000,"<"&($A6+1)) -> 0 | E6: =COUNTIFS(Referral_Data!$H$5:$H$1000,">="&$A6,Referral_Data!$H$5:$H$1000,"<"&($A6+1)) -> 0 | F6: =SUMIFS(Engagement_Events!$G$5:$G$3000,Engagement_Events!$C$5:$C$3000,$A6) -> 7 | G6: =SUMIFS(Engagement_Events!$K$5:$K$3000,Engagement_Events!$C$5:$C$3000,$A6) -> 5 | H6: =SUMIFS(Engagement_Events!$H$5:$H$3000,Engagement_Events!$C$5:$C$3000,$A6) -> 2 | I6: =COUNTIFS(Engagement_Events!$C$5:$C$3000,$A6,Engagement_Events!$D$5:$D$3000,"Login") -> 7 | J6: =COUNTIFS(Engagement_Events!$C$5:$C$3000,$A6,Engagement_Events!$D$5:$D$3000,"Feature Use") -> 10 | K6: =COUNTIFS(Engagement_Events!$C$5:$C$3000,$A6,Engagement_Events!$D$5:$D$3000,"Task Completed") -> 4 | L6: =SUM($B$5:B6) -> 3 | M6: =SUM($E$5:E6) -> 0 | N6: =IF(L6=0,0,M6/L6) -> 0
A7: =A6+1 -> 46268 | B7: =COUNTIFS(Referral_Data!$E$5:$E$1000,">="&$A7,Referral_Data!$E$5:$E$1000,"<"&($A7+1)) -> 2 | C7: =COUNTIFS(Referral_Data!$F$5:$F$1000,">="&$A7,Referral_Data!$F$5:$F$1000,"<"&($A7+1)) -> 1 | D7: =COUNTIFS(Referral_Data!$G$5:$G$1000,">="&$A7,Referral_Data!$G$5:$G$1000,"<"&($A7+1)) -> 0 | E7: =COUNTIFS(Referral_Data!$H$5:$H$1000,">="&$A7,Referral_Data!$H$5:$H$1000,"<"&($A7+1)) -> 0 | F7: =SUMIFS(Engagement_Events!$G$5:$G$3000,Engagement_Events!$C$5:$C$3000,$A7) -> 10 | G7: =SUMIFS(Engagement_Events!$K$5:$K$3000,Engagement_Events!$C$5:$C$3000,$A7) -> 4 | H7: =SUMIFS(Engagement_Events!$H$5:$H$3000,Engagement_Events!$C$5:$C$3000,$A7) -> 6 | I7: =COUNTIFS(Engagement_Events!$C$5:$C$3000,$A7,Engagement_Events!$D$5:$D$3000,"Login") -> 10 | J7: =COUNTIFS(Engagement_Events!$C$5:$C$3000,$A7,Engagement_Events!$D$5:$D$3000,"Feature Use") -> 15 | K7: =COUNTIFS(Engagement_Events!$C$5:$C$3000,$A7,Engagement_Events!$D$5:$D$3000,"Task Completed") -> 7 | L7: =SUM($B$5:B7) -> 5 | M7: =SUM($E$5:E7) -> 0 | N7: =IF(L7=0,0,M7/L7) -> 0
A8: =A7+1 -> 46269 | B8: =COUNTIFS(Referral_Data!$E$5:$E$1000,">="&$A8,Referral_Data!$E$5:$E$1000,"<"&($A8+1)) -> 2 | C8: =COUNTIFS(Referral_Data!$F$5:$F$1000,">="&$A8,Referral_Data!$F$5:$F$1000,"<"&($A8+1)) -> 0 | D8: =COUNTIFS(Referral_Data!$G$5:$G$1000,">="&$A8,Referral_Data!$G$5:$G$1000,"<"&($A8+1)) -> 1 | E8: =COUNTIFS(Referral_Data!$H$5:$H$1000,">="&$A8,Referral_Data!$H$5:$H$1000,"<"&($A8+1)) -> 0 | F8: =SUMIFS(Engagement_Events!$G$5:$G$3000,Engagement_Events!$C$5:$C$3000,$A8) -> 9 | G8: =SUMIFS(Engagement_Events!$K$5:$K$3000,Engagement_Events!$C$5:$C$3000,$A8) -> 4 | H8: =SUMIFS(Engagement_Events!$H$5:$H$3000,Engagement_Events!$C$5:$C$3000,$A8) -> 5 | I8: =COUNTIFS(Engagement_Events!$C$5:$C$3000,$A8,Engagement_Events!$D$5:$D$3000,"Login") -> 9 | J8: =COUNTIFS(Engagement_Events!$C$5:$C$3000,$A8,Engagement_Events!$D$5:$D$3000,"Feature Use") -> 13 | K8: =COUNTIFS(Engagement_Events!$C$5:$C$3000,$A8,Engagement_Events!$D$5:$D$3000,"Task Completed") -> 2 | L8: =SUM($B$5:B8) -> 7 | M8: =SUM($E$5:E8) -> 0 | N8: =IF(L8=0,0,M8/L8) -> 0
A9: =A8+1 -> 46270 | B9: =COUNTIFS(Referral_Data!$E$5:$E$1000,">="&$A9,Referral_Data!$E$5:$E$1000,"<"&($A9+1)) -> 2 | C9: =COUNTIFS(Referral_Data!$F$5:$F$1000,">="&$A9,Referral_Data!$F$5:$F$1000,"<"&($A9+1)) -> 0 | D9: =COUNTIFS(Referral_Data!$G$5:$G$1000,">="&$A9,Referral_Data!$G$5:$G$1000,"<"&($A9+1)) -> 0 | E9: =COUNTIFS(Referral_Data!$H$5:$H$1000,">="&$A9,Referral_Data!$H$5:$H$1000,"<"&($A9+1)) -> 0 | F9: =SUMIFS(Engagement_Events!$G$5:$G$3000,Engagement_Events!$C$5:$C$3000,$A9) -> 6 | G9: =SUMIFS(Engagement_Events!$K$5:$K$3000,Engagement_Events!$C$5:$C$3000,$A9) -> 0 | H9: =SUMIFS(Engagement_Events!$H$5:$H$3000,Engagement_Events!$C$5:$C$3000,$A9) -> 6 | I9: =COUNTIFS(Engagement_Events!$C$5:$C$3000,$A9,Engagement_Events!$D$5:$D$3000,"Login") -> 6 | J9: =COUNTIFS(Engagement_Events!$C$5:$C$3000,$A9,Engagement_Events!$D$5:$D$3000,"Feature Use") -> 10 | K9: =COUNTIFS(Engagement_Events!$C$5:$C$3000,$A9,Engagement_Events!$D$5:$D$3000,"Task Completed") -> 4 | L9: =SUM($B$5:B9) -> 9 | M9: =SUM($E$5:E9) -> 0 | N9: =IF(L9=0,0,M9/L9) -> 0
A10: =A9+1 -> 46271 | B10: =COUNTIFS(Referral_Data!$E$5:$E$1000,">="&$A10,Referral_Data!$E$5:$E$1000,"<"&($A10+1)) -> 0 | C10: =COUNTIFS(Referral_Data!$F$5:$F$1000,">="&$A10,Referral_Data!$F$5:$F$1000,"<"&($A10+1)) -> 1 | D10: =COUNTIFS(Referral_Data!$G$5:$G$1000,">="&$A10,Referral_Data!$G$5:$G$1000,"<"&($A10+1)) -> 0 | E10: =COUNTIFS(Referral_Data!$H$5:$H$1000,">="&$A10,Referral_Data!$H$5:$H$1000,"<"&($A10+1)) -> 0 | F10: =SUMIFS(Engagement_Events!$G$5:$G$3000,Engagement_Events!$C$5:$C$3000,$A10) -> 5 | G10: =SUMIFS(Engagement_Events!$K$5:$K$3000,Engagement_Events!$C$5:$C$3000,$A10) -> 1 | H10: =SUMIFS(Engagement_Events!$H$5:$H$3000,Engagement_Events!$C$5:$C$3000,$A10) -> 4 | I10: =COUNTIFS(Engagement_Events!$C$5:$C$3000,$A10,Engagement_Events!$D$5:$D$3000,"Login") -> 5 | J10: =COUNTIFS(Engagement_Events!$C$5:$C$3000,$A10,Engagement_Events!$D$5:$D$3000,"Feature Use") -> 6 | K10: =COUNTIFS(Engagement_Events!$C$5:$C$3000,$A10,Engagement_Events!$D$5:$D$3000,"Task Completed") -> 2 | L10: =SUM($B$5:B10) -> 9 | M10: =SUM($E$5:E10) -> 0 | N10: =IF(L10=0,0,M10/L10) -> 0
A11: =A10+1 -> 46272 | B11: =COUNTIFS(Referral_Data!$E$5:$E$1000,">="&$A11,Referral_Data!$E$5:$E$1000,"<"&($A11+1)) -> 1 | C11: =COUNTIFS(Referral_Data!$F$5:$F$1000,">="&$A11,Referral_Data!$F$5:$F$1000,"<"&($A11+1)) -> 1 | D11: =COUNTIFS(Referral_Data!$G$5:$G$1000,">="&$A11,Referral_Data!$G$5:$G$1000,"<"&($A11+1)) -> 1 | E11: =COUNTIFS(Referral_Data!$H$5:$H$1000,">="&$A11,Referral_Data!$H$5:$H$1000,"<"&($A11+1)) -> 0 | F11: =SUMIFS(Engagement_Events!$G$5:$G$3000,Engagement_Events!$C$5:$C$3000,$A11) -> 10 | G11: =SUMIFS(Engagement_Events!$K$5:$K$3000,Engagement_Events!$C$5:$C$3000,$A11) -> 3 | H11: =SUMIFS(Engagement_Events!$H$5:$H$3000,Engagement_Events!$C$5:$C$3000,$A11) -> 7 | I11: =COUNTIFS(Engagement_Events!$C$5:$C$3000,$A11,Engagement_Events!$D$5:$D$3000,"Login") -> 10 | J11: =COUNTIFS(Engagement_Events!$C$5:$C$3000,$A11,Engagement_Events!$D$5:$D$3000,"Feature Use") -> 14 | K11: =COUNTIFS(Engagement_Events!$C$5:$C$3000,$A11,Engagement_Events!$D$5:$D$3000,"Task Completed") -> 4 | L11: =SUM($B$5:B11) -> 10 | M11: =SUM($E$5:E11) -> 0 | N11: =IF(L11=0,0,M11/L11) -> 0
