Workbook

Sheet README
A1: Veloop Data Dictionary — Work Package G
A3: ASSUMPTION: No Veloop source material was supplied, so Veloop is modelled as a shared bike / e-bike / e-scooter mobility platform (app, vehicles, stations, trips, payments, support). Entities, fields and sources are PROPOSED. Replace or delete any that do not match the real business.
A5: How to use
A6: 1. 'Data Dictionary' sheet: one row per field, with all 11 required attributes plus Field ID and Status.
A7: 2. 'Entity Summary': grain and field counts per entity (formula-driven, updates when you edit the dictionary).
A8: 3. 'Checks': automatic quality checks (75+ field target, duplicates, missing attributes, sensitivity mix).
A9: 4. 'Rationale & Gaps': why the field set is sufficient, and what to add next.
A11: Status rule: every field is 'Proposed'. Change to 'Confirmed' only after the data owner has verified the field exists in the named source with the stated type and rules.
A12: Sensitivity: Public = safe to publish; Internal = staff only; Restricted = personal, precise location, or identity-linked data (access-controlled, aggregate when reporting).
A13: Edit cells in 'Data Dictionary' directly; dropdowns exist for Required, Sensitivity and Status.

Sheet Data Dictionary
A1: Field ID | B1: Entity | C1: Field Name | D1: Data Type | E1: Definition | F1: Example | G1: Required | H1: Allowed Values | I1: Validation | J1: Source | K1: Sensitivity | L1: Analytical Use | M1: Status
A2: F001 | B2: dim_user | C2: user_id | D2: STRING | E2: Unique surrogate identifier of a registered rider account. | F2: U-00048213 | G2: Yes | I2: Unique, not null, format U-####### | J2: Mobile app backend | K2: Internal | L2: Primary join key for all rider-level analysis (retention, LTV, cohorts). | M2: Proposed
A3: F002 | B3: dim_user | C3: signup_date | D3: DATE | E3: Calendar date the account was created. | F3: 2026-03-14 | G3: Yes | I3: Valid date, <= today, >= launch date | J3: Mobile app backend | K3: Internal | L3: Cohort assignment and acquisition trend analysis. | M3: Proposed
A4: F003 | B4: dim_user | C4: signup_channel | D4: STRING | E4: Marketing/acquisition channel credited for the signup. | F4: referral | G4: Yes | H4: organic, paid_social, paid_search, referral, partner, unknown | I4: Must be in allowed list | J4: App backend + attribution SDK | K4: Internal | L4: Compares CAC and retention by channel. | M4: Proposed
A5: F004 | B5: dim_user | C5: country_code | D5: STRING | E5: ISO 3166-1 alpha-2 country of the account's home market. | F5: DE | G5: Yes | H5: ISO 3166-1 alpha-2 | I5: 2 uppercase letters, in ISO list | J5: Mobile app backend | K5: Internal | L5: Market-level segmentation and reporting. | M5: Proposed
A6: F005 | B6: dim_user | C6: home_city | D6: STRING | E6: City where the user takes most trips or registered. | F6: Berlin | G6: No | I6: Not blank if provided; matches city reference list | J6: Derived (ETL) from trips | K6: Internal | L6: City-level demand and penetration analysis. | M6: Proposed
A7: F006 | B7: dim_user | C7: birth_year | D7: INTEGER | E7: Year of birth supplied at signup (year only, to limit PII). | F7: 1994 | G7: No | I7: 1920 <= value <= current year - minimum age | J7: Mobile app backend | K7: Restricted | L7: Age-band segmentation and age-eligibility compliance. | M7: Proposed
A8: F007 | B8: dim_user | C8: user_status | D8: STRING | E8: Current lifecycle state of the account. | F8: active | G8: Yes | H8: active, dormant, suspended, deleted | I8: Must be in allowed list | J8: Derived (ETL) | K8: Internal | L8: Active-user counts, churn and reactivation tracking. | M8: Proposed
A9: F008 | B9: dim_user | C9: account_tier | D9: STRING | E9: Subscription tier the user is currently on. | F9: monthly_pass | G9: Yes | H9: pay_as_you_go, monthly_pass, annual_pass, corporate | I9: Must be in allowed list | J9: Billing system | K9: Internal | L9: Revenue mix and tier-upgrade analysis. | M9: Proposed
A10: F009 | B10: dim_user | C10: marketing_consent_flag | D10: BOOLEAN | E10: Whether the user consented to marketing communications. | F10: TRUE | G10: Yes | H10: TRUE, FALSE | I10: Not null | J10: Mobile app backend | K10: Restricted | L10: Ensures campaign analysis respects consent (GDPR). | M10: Proposed
A11: F010 | B11: dim_user | C11: email_hash | D11: STRING | E11: SHA-256 hash of normalised email, used for matching without exposing the address. | F11: 9f86d0...a08 | G11: No | I11: 64 hex chars, lowercase | J11: Derived (ETL) | K11: Restricted | L11: Deduplicating accounts and joining to CRM without raw PII. | M11: Proposed
A12: F011 | B12: dim_user | C12: first_trip_date | D12: DATE | E12: Date of the user's first completed trip. | F12: 2026-03-15 | G12: No | I12: Null until first trip; >= signup_date | J12: Derived (ETL) | K12: Internal | L12: Activation rate and time-to-first-trip. | M12: Proposed
A13: F012 | B13: dim_vehicle | C13: vehicle_id | D13: STRING | E13: Unique identifier of a physical bike/e-bike/scooter. | F13: V-100245 | G13: Yes | I13: Unique, not null | J13: Fleet ops system | K13: Internal | L13: Join key for utilisation, maintenance and telemetry. | M13: Proposed
A14: F013 | B14: dim_vehicle | C14: vehicle_type | D14: STRING | E14: Category of vehicle. | F14: ebike | G14: Yes | H14: bike, ebike, escooter, cargo_bike | I14: Must be in allowed list | J14: Fleet ops system | K14: Internal | L14: Utilisation and revenue comparison by vehicle type. | M14: Proposed
A15: F014 | B15: dim_vehicle | C15: model_name | D15: STRING | E15: Manufacturer model designation. | F15: VL-E2 Gen3 | G15: Yes | I15: Must match vehicle model reference list | J15: Fleet ops system | K15: Internal | L15: Reliability and cost analysis by model. | M15: Proposed
A16: F015 | B16: dim_vehicle | C16: battery_capacity_wh | D16: INTEGER | E16: Rated battery capacity in watt-hours (null for non-electric). | F16: 504 | G16: No | I16: > 0 when vehicle_type is electric, else null | J16: Fleet ops system | K16: Internal | L16: Range modelling and battery-swap planning. | M16: Proposed
A17: F016 | B17: dim_vehicle | C17: commission_date | D17: DATE | E17: Date the vehicle entered service. | F17: 2025-09-01 | G17: Yes | I17: Valid date, <= today | J17: Fleet ops system | K17: Internal | L17: Vehicle age and lifecycle analysis. | M17: Proposed
A18: F017 | B18: dim_vehicle | C18: vehicle_status | D18: STRING | E18: Current operational state. | F18: available | G18: Yes | H18: available, in_use, maintenance, missing, retired | I18: Must be in allowed list | J18: Fleet ops system | K18: Internal | L18: Fleet availability and downtime reporting. | M18: Proposed
A19: F018 | B19: dim_vehicle | C19: firmware_version | D19: STRING | E19: Version of firmware on the vehicle's lock/IoT unit. | F19: 3.4.1 | G19: No | I19: Semantic version pattern X.Y.Z | J19: IoT telematics | K19: Internal | L19: Links faults and trip anomalies to firmware releases. | M19: Proposed
A20: F019 | B20: dim_vehicle | C20: fleet_owner_type | D20: STRING | E20: Whether the vehicle is owned, leased or partner-supplied. | F20: owned | G20: Yes | H20: owned, leased, partner | I20: Must be in allowed list | J20: Finance / fleet ops | K20: Internal | L20: Unit economics by ownership model. | M20: Proposed
A21: F020 | B21: dim_vehicle | C21: retirement_date | D21: DATE | E21: Date the vehicle left the fleet permanently. | F21: 2027-01-20 | G21: No | I21: Null unless vehicle_status = retired; >= commission_date | J21: Fleet ops system | K21: Internal | L21: Asset life and replacement planning. | M21: Proposed
A22: F021 | B22: dim_station | C22: station_id | D22: STRING | E22: Unique identifier of a docking station or designated parking zone. | F22: S-0231 | G22: Yes | I22: Unique, not null | J22: Station registry | K22: Internal | L22: Join key for supply/demand and flow analysis. | M22: Proposed
A23: F022 | B23: dim_station | C23: station_name | D23: STRING | E23: Public name of the station. | F23: Alexanderplatz North | G23: Yes | I23: Not blank, <= 100 chars | J23: Station registry | K23: Public | L23: Readable labels for dashboards and maps. | M23: Proposed
A24: F023 | B24: dim_station | C24: city | D24: STRING | E24: City in which the station is located. | F24: Berlin | G24: Yes | I24: Matches city reference list | J24: Station registry | K24: Public | L24: Geographic roll-ups. | M24: Proposed
A25: F024 | B25: dim_station | C25: latitude | D25: DECIMAL(9,6) | E25: WGS84 latitude of the station. | F25: 52.521918 | G25: Yes | I25: -90 to 90 | J25: Station registry | K25: Public | L25: Spatial analysis and heatmaps. | M25: Proposed
A26: F025 | B26: dim_station | C26: longitude | D26: DECIMAL(9,6) | E26: WGS84 longitude of the station. | F26: 13.413215 | G26: Yes | I26: -180 to 180 | J26: Station registry | K26: Public | L26: Spatial analysis and heatmaps. | M26: Proposed
A27: F026 | B27: dim_station | C27: dock_capacity | D27: INTEGER | E27: Number of vehicles the station can hold. | F27: 24 | G27: Yes | I27: Integer >= 0 (0 allowed for virtual zones) | J27: Station registry | K27: Internal | L27: Occupancy and rebalancing calculations. | M27: Proposed
A28: F027 | B28: dim_station | C28: station_type | D28: STRING | E28: Physical or virtual type of the location. | F28: docked | G28: Yes | H28: docked, virtual_zone, hub | I28: Must be in allowed list | J28: Station registry | K28: Internal | L28: Compares performance by station design. | M28: Proposed
A29: F028 | B29: dim_station | C29: pricing_zone_id | D29: STRING | E29: Pricing zone the station belongs to. | F29: Z-CENTRAL | G29: No | I29: Must exist in zone reference list | J29: Reference data (manual) | K29: Internal | L29: Analyses price sensitivity by zone. | M29: Proposed
A30: F029 | B30: dim_station | C30: station_opened_date | D30: DATE | E30: Date the station became operational. | F30: 2025-06-12 | G30: Yes | I30: Valid date, <= today | J30: Station registry | K30: Internal | L30: Maturity curves for new stations. | M30: Proposed
A31: F030 | B31: dim_station | C31: station_status | D31: STRING | E31: Current operating state of the station. | F31: active | G31: Yes | H31: active, temporarily_closed, decommissioned | I31: Must be in allowed list | J31: Station registry | K31: Internal | L31: Excludes closed stations from availability metrics. | M31: Proposed
A32: F031 | B32: dim_date | C32: date_key | D32: INTEGER | E32: Surrogate key in YYYYMMDD form. | F32: 20261017 | G32: Yes | I32: 8 digits, valid date | J32: Calendar table (generated) | K32: Public | L32: Standard time join for all facts. | M32: Proposed
A33: F032 | B33: dim_date | C33: calendar_date | D33: DATE | E33: The calendar date. | F33: 2026-10-17 | G33: Yes | I33: Unique, continuous series | J33: Calendar table (generated) | K33: Public | L33: Daily trend analysis. | M33: Proposed
A34: F033 | B34: dim_date | C34: day_of_week | D34: STRING | E34: Day name. | F34: Saturday | G34: Yes | H34: Monday ... Sunday | I34: Must be in allowed list | J34: Calendar table (generated) | K34: Public | L34: Weekday vs weekend demand patterns. | M34: Proposed
A35: F034 | B35: dim_date | C35: is_weekend | D35: BOOLEAN | E35: TRUE for Saturday or Sunday. | F35: TRUE | G35: Yes | H35: TRUE, FALSE | I35: Consistent with day_of_week | J35: Calendar table (generated) | K35: Public | L35: Leisure vs commuter segmentation. | M35: Proposed
A36: F035 | B36: dim_date | C36: is_public_holiday | D36: BOOLEAN | E36: TRUE if the date is a public holiday in the market. | F36: FALSE | G36: Yes | H36: TRUE, FALSE | I36: Matches holiday reference per country | J36: Reference data (manual) | K36: Public | L36: Explains demand spikes and dips. | M36: Proposed
A37: F036 | B37: dim_date | C37: iso_week | D37: INTEGER | E37: ISO 8601 week number of the year. | F37: 42 | G37: Yes | I37: 1 to 53 | J37: Calendar table (generated) | K37: Public | L37: Weekly reporting cadence. | M37: Proposed
A38: F037 | B38: fact_trip | C38: trip_id | D38: STRING | E38: Unique identifier of one rental/trip. | F38: T-9004412 | G38: Yes | I38: Unique, not null | J38: Mobile app backend | K38: Internal | L38: Grain of the trip fact; counts and rates. | M38: Proposed
A39: F038 | B39: fact_trip | C39: user_id | D39: STRING | E39: Rider who took the trip (FK to dim_user). | F39: U-00048213 | G39: Yes | I39: Must exist in dim_user | J39: Mobile app backend | K39: Internal | L39: Rider behaviour, frequency and retention. | M39: Proposed
A40: F039 | B40: fact_trip | C40: vehicle_id | D40: STRING | E40: Vehicle used (FK to dim_vehicle). | F40: V-100245 | G40: Yes | I40: Must exist in dim_vehicle | J40: Mobile app backend | K40: Internal | L40: Vehicle utilisation and revenue per vehicle. | M40: Proposed
...

Sheet Entity Summary
A1: Entity | B1: Type | C1: Grain | D1: Total Fields | E1: Required Fields | F1: Restricted Fields | G1: Proposed Fields
A2: dim_user | B2: Dimension | C2: One row per rider account | D2: =COUNTIF('Data Dictionary'!$B$2:$B$210,A2) -> 11 | E2: =COUNTIFS('Data Dictionary'!$B$2:$B$210,A2,'Data Dictionary'!$G$2:$G$210,"Yes") -> 7 | F2: =COUNTIFS('Data Dictionary'!$B$2:$B$210,A2,'Data Dictionary'!$K$2:$K$210,"Restricted") -> 3 | G2: =COUNTIFS('Data Dictionary'!$B$2:$B$210,A2,'Data Dictionary'!$M$2:$M$210,"Proposed") -> 11
A3: dim_vehicle | B3: Dimension | C3: One row per physical vehicle | D3: =COUNTIF('Data Dictionary'!$B$2:$B$210,A3) -> 9 | E3: =COUNTIFS('Data Dictionary'!$B$2:$B$210,A3,'Data Dictionary'!$G$2:$G$210,"Yes") -> 6 | F3: =COUNTIFS('Data Dictionary'!$B$2:$B$210,A3,'Data Dictionary'!$K$2:$K$210,"Restricted") -> 0 | G3: =COUNTIFS('Data Dictionary'!$B$2:$B$210,A3,'Data Dictionary'!$M$2:$M$210,"Proposed") -> 9
A4: dim_station | B4: Dimension | C4: One row per station / parking zone | D4: =COUNTIF('Data Dictionary'!$B$2:$B$210,A4) -> 10 | E4: =COUNTIFS('Data Dictionary'!$B$2:$B$210,A4,'Data Dictionary'!$G$2:$G$210,"Yes") -> 9 | F4: =COUNTIFS('Data Dictionary'!$B$2:$B$210,A4,'Data Dictionary'!$K$2:$K$210,"Restricted") -> 0 | G4: =COUNTIFS('Data Dictionary'!$B$2:$B$210,A4,'Data Dictionary'!$M$2:$M$210,"Proposed") -> 10
A5: dim_date | B5: Dimension | C5: One row per calendar date | D5: =COUNTIF('Data Dictionary'!$B$2:$B$210,A5) -> 6 | E5: =COUNTIFS('Data Dictionary'!$B$2:$B$210,A5,'Data Dictionary'!$G$2:$G$210,"Yes") -> 6 | F5: =COUNTIFS('Data Dictionary'!$B$2:$B$210,A5,'Data Dictionary'!$K$2:$K$210,"Restricted") -> 0 | G5: =COUNTIFS('Data Dictionary'!$B$2:$B$210,A5,'Data Dictionary'!$M$2:$M$210,"Proposed") -> 6
A6: dim_pricing_plan | B6: Dimension | C6: One row per pricing plan version | D6: =COUNTIF('Data Dictionary'!$B$2:$B$210,A6) -> 6 | E6: =COUNTIFS('Data Dictionary'!$B$2:$B$210,A6,'Data Dictionary'!$G$2:$G$210,"Yes") -> 6 | F6: =COUNTIFS('Data Dictionary'!$B$2:$B$210,A6,'Data Dictionary'!$K$2:$K$210,"Restricted") -> 0 | G6: =COUNTIFS('Data Dictionary'!$B$2:$B$210,A6,'Data Dictionary'!$M$2:$M$210,"Proposed") -> 6
A7: dim_promo | B7: Dimension | C7: One row per promo code | D7: =COUNTIF('Data Dictionary'!$B$2:$B$210,A7) -> 5 | E7: =COUNTIFS('Data Dictionary'!$B$2:$B$210,A7,'Data Dictionary'!$G$2:$G$210,"Yes") -> 5 | F7: =COUNTIFS('Data Dictionary'!$B$2:$B$210,A7,'Data Dictionary'!$K$2:$K$210,"Restricted") -> 0 | G7: =COUNTIFS('Data Dictionary'!$B$2:$B$210,A7,'Data Dictionary'!$M$2:$M$210,"Proposed") -> 5
A8: fact_trip | B8: Fact | C8: One row per trip | D8: =COUNTIF('Data Dictionary'!$B$2:$B$210,A8) -> 20 | E8: =COUNTIFS('Data Dictionary'!$B$2:$B$210,A8,'Data Dictionary'!$G$2:$G$210,"Yes") -> 8 | F8: =COUNTIFS('Data Dictionary'!$B$2:$B$210,A8,'Data Dictionary'!$K$2:$K$210,"Restricted") -> 4 | G8: =COUNTIFS('Data Dictionary'!$B$2:$B$210,A8,'Data Dictionary'!$M$2:$M$210,"Proposed") -> 20
A9: fact_payment | B9: Fact | C9: One row per payment transaction | D9: =COUNTIF('Data Dictionary'!$B$2:$B$210,A9) -> 11 | E9: =COUNTIFS('Data Dictionary'!$B$2:$B$210,A9,'Data Dictionary'!$G$2:$G$210,"Yes") -> 9 | F9: =COUNTIFS('Data Dictionary'!$B$2:$B$210,A9,'Data Dictionary'!$K$2:$K$210,"Restricted") -> 0 | G9: =COUNTIFS('Data Dictionary'!$B$2:$B$210,A9,'Data Dictionary'!$M$2:$M$210,"Proposed") -> 11
A10: fact_maintenance | B10: Fact | C10: One row per maintenance work order | D10: =COUNTIF('Data Dictionary'!$B$2:$B$210,A10) -> 9 | E10: =COUNTIFS('Data Dictionary'!$B$2:$B$210,A10,'Data Dictionary'!$G$2:$G$210,"Yes") -> 6 | F10: =COUNTIFS('Data Dictionary'!$B$2:$B$210,A10,'Data Dictionary'!$K$2:$K$210,"Restricted") -> 1 | G10: =COUNTIFS('Data Dictionary'!$B$2:$B$210,A10,'Data Dictionary'!$M$2:$M$210,"Proposed") -> 9
A11: fact_support_ticket | B11: Fact | C11: One row per support ticket | D11: =COUNTIF('Data Dictionary'!$B$2:$B$210,A11) -> 8 | E11: =COUNTIFS('Data Dictionary'!$B$2:$B$210,A11,'Data Dictionary'!$G$2:$G$210,"Yes") -> 5 | F11: =COUNTIFS('Data Dictionary'!$B$2:$B$210,A11,'Data Dictionary'!$K$2:$K$210,"Restricted") -> 0 | G11: =COUNTIFS('Data Dictionary'!$B$2:$B$210,A11,'Data Dictionary'!$M$2:$M$210,"Proposed") -> 8
A12: fact_app_event | B12: Fact | C12: One row per app event | D12: =COUNTIF('Data Dictionary'!$B$2:$B$210,A12) -> 8 | E12: =COUNTIFS('Data Dictionary'!$B$2:$B$210,A12,'Data Dictionary'!$G$2:$G$210,"Yes") -> 6 | F12: =COUNTIFS('Data Dictionary'!$B$2:$B$210,A12,'Data Dictionary'!$K$2:$K$210,"Restricted") -> 1 | G12: =COUNTIFS('Data Dictionary'!$B$2:$B$210,A12,'Data Dictionary'!$M$2:$M$210,"Proposed") -> 8
A13: fact_vehicle_snapshot | B13: Fact | C13: One row per vehicle per snapshot interval | D13: =COUNTIF('Data Dictionary'!$B$2:$B$210,A13) -> 6 | E13: =COUNTIFS('Data Dictionary'!$B$2:$B$210,A13,'Data Dictionary'!$G$2:$G$210,"Yes") -> 4 | F13: =COUNTIFS('Data Dictionary'!$B$2:$B$210,A13,'Data Dictionary'!$K$2:$K$210,"Restricted") -> 0 | G13: =COUNTIFS('Data Dictionary'!$B$2:$B$210,A13,'Data Dictionary'!$M$2:$M$210,"Proposed") -> 6
A14: TOTAL | D14: =SUM(D2:D13) -> 109 | E14: =SUM(E2:E13) -> 77 | F14: =SUM(F2:F13) -> 9 | G14: =SUM(G2:G13) -> 109

Sheet Checks
A1: Check | B1: Result | C1: Expected | D1: Pass?
A2: Total fields documented | B2: =COUNTA('Data Dictionary'!$C$2:$C$210) -> 109 | C2: 75 or more | D2: =IF(B2>=75,"PASS","FAIL") -> PASS
A3: Entities covered | B3: =COUNTA('Entity Summary'!A2:A13) -> 12 | C3: 1 or more | D3: =IF(B3>=1,"PASS","FAIL") -> PASS
A4: Duplicate Entity+Field rows | B4: =SUMPRODUCT(('Data Dictionary'!$B$2:$B$210<>"")*(COUNTIFS('Data Dictionary'!$B$2:$B$210,'Data Dictionary'!$B$2:$B$210,'Data Dictionary'!$C$2:$C$210,'Data Dictionary'!$C$2:$C$210)>1)) -> 0 | C4: 0 | D4: =IF(B4=0,"PASS","FAIL") -> PASS
A5: Rows with a blank required attribute | B5: =SUMPRODUCT(('Data Dictionary'!$C$2:$C$210<>"")*(('Data Dictionary'!$D$2:$D$210="")+('Data Dictionary'!$E$2:$E$210="")+('Data Dictionary'!$F$2:$F$210="")+('Data Dictionary'!$G$2:$G$210="")+('Data Dictionary'!$I$2:$I$210="")+('Data Dictionary'!$J$2:$J$210="")+('Data Dictionary'!$K$2:$K$210="")+('Data Dictionary'!$L$2:$L$210="")+('Data Dictionary'!$M$2:$M$210="")>0)) -> 0 | C5: 0 | D5: =IF(B5=0,"PASS","FAIL") -> PASS
A6: Fields still Proposed (count) | B6: =COUNTIF('Data Dictionary'!$M$2:$M$210,"Proposed") -> 109 | C6: Falls to 0 as owners sign off | D6: =IF(B6=0,"DONE","OPEN") -> OPEN
A7: Confirmed fields (%) | B7: =COUNTIF('Data Dictionary'!$M$2:$M$210,"Confirmed")/B2 -> 0 | C7: Rises toward 100% | D7: =IF(B7=1,"DONE","OPEN") -> OPEN
A8: Restricted fields (%) | B8: =COUNTIF('Data Dictionary'!$K$2:$K$210,"Restricted")/B2 -> 0.082568807 | C8: Keep small; review each | D8: =IF(B8<=0.2,"OK","REVIEW") -> OK
A9: Entity Summary total = dictionary total | B9: ='Entity Summary'!D14-B2 -> 0 | C9: 0 | D9: =IF(B9=0,"PASS","FAIL") -> PASS

Sheet Rationale & Gaps
A1: Why this field set
A2: Each field supports at least one named question: demand and utilisation (trips, snapshots), revenue and pricing (payments, plans, promos), retention and acquisition (users, channel, app events), fleet reliability and cost (vehicles, maintenance), and service quality (support tickets).
A3: Fields deliberately excluded: free-text notes, raw GPS breadcrumbs per second, full names, addresses, phone numbers and card data. They add privacy risk without a defined analytical question.
A4: The 75-field target is met only through fields tied to an analytical use; no filler columns were added.
A6: What to add next (not yet in the model)
A7: fact_incident: accidents, theft, vandalism, injuries (safety KPIs, insurance).
A8: fact_rebalancing_task: vehicle moves and battery swaps by operations crew (cost per rebalance, stock-out reduction).
A9: dim_city / dim_zone: population, regulation, fleet caps (market penetration).
A10: fact_marketing_spend: spend by channel and day (CAC, ROAS).
A11: fact_subscription: pass start, renewal, cancel dates and reasons (churn and LTV).
A12: fact_trip_route_point: sampled GPS path (route and safety analysis; Restricted).
A14: Open questions for the data owner
A15: Which source systems actually exist (names, owners)? Which fields are already captured? What is the legal retention period for precise location? Are there markets with different currency or tax rules?
