Workbook

Sheet Overview
A1: VELOOP – Work Package A: Product Data Readiness Audit
A2: Complete map of the data VELOOP will need: areas, features, user actions, system actions, transactions, states and outcomes
A4: Objective | B4: Map every measurable part of the product so that tracking, reporting and reconciliation can be designed before production.
A5: Sheets | B5: A1 Product Area Map | A2 User Action Flows | A3 Event Classification | A4 Coverage Matrix | Analytics Gaps | Summary
A6: Important assumption | B6: The product was mapped from the feature list in the brief plus common patterns in reward-based apps. Feature rules (limits, reward values, validation logic) have not been confirmed with Product or Engineering. Anything not confirmed is marked 'To Be Verified' or 'Proposed'.
A7: Status values | B7: Confirmed = feature named in the brief or agreed. Proposed = identified by the analyst, needs sign-off. To Be Verified = depends on a product or technical answer.
A8: Priority values | B8: Critical = needed for financial reconciliation or first production reports. High = core product KPI. Medium = useful for optimization. Low = nice to have.
A9: Event types | B9: User Event = a deliberate action by the user. System Event = an automated step or decision made by the platform. Business Outcome = the final result that changes a KPI, a balance or a status of record.
A10: Naming convention | B10: Events are snake_case and named object_action in the past tense (e.g., mission_completed, withdrawal_processed).
A11: Source values | B11: Frontend = app or web client. Backend = VELOOP server. Ad network / Payment provider = third-party callbacks. Admin tool = internal operations.
A12: Privacy | B12: No unnecessary personal data is requested. Analytics uses user_id and transaction_id. Payout and verification details stay in their source systems and are never copied into analytics.
A13: Tip | B13: Status, Priority and similar columns have dropdowns and filters. The Summary sheet counts update automatically.

Sheet A1 Product Area Map
A1: A1. Product Area Mapping
A3: Product Area | B3: Feature | C3: User Action | D3: System Outcome | E3: Data Required | F3: Business Question | G3: Status
A4: Registration | B4: Sign-up | C4: Submits sign-up details | D4: Account created, user_id assigned | E4: user_id, registration_timestamp, source, platform, UTM/referral code | F4: Which channels bring users, and how many visitors become users? | G4: Confirmed
A5: Login | B5: Login / session start | C5: Logs in or reopens the app | D5: Session created, last_login updated | E5: login_timestamp, session_id, method, platform, failure_reason | F5: How often do users return, and how often does login fail? | G5: Confirmed
A6: Onboarding | B6: Intro and first-use steps | C6: Views and completes onboarding steps | D6: Milestones recorded, user marked activated | E6: step, step timestamps, status, milestone | F6: Where do new users drop off before their first reward? | G6: Proposed
A7: Profile & Verification | B7: Profile and identity verification (if required) | C7: Completes profile or submits verification | D7: Verification approved or rejected | E7: verification_status, timestamps, reason code (no document content) | F7: Does verification block users from withdrawing? | G7: To Be Verified
A8: Watch Ads | B8: Rewarded video ad | C8: Taps to watch an ad and watches it | D8: Ad shown, completion confirmed by ad network, reward credited | E8: ad_unit_id, network, placement, impression, completion, revenue, reward amount | F8: What is the completion rate, and is revenue higher than reward cost per ad? | G8: Confirmed
A9: Daily Rewards | B9: Daily check-in and streak | C9: Opens the daily reward and claims it | D9: Eligibility checked, reward credited, streak updated | E9: claim date, streak day, amount, day boundary rule | F9: Does the daily reward improve retention? | G9: Confirmed
A10: Tap & Earn | B10: Tap game | C10: Taps the screen | D10: Taps aggregated, energy and limits applied, points credited | E10: tap count (batched), energy, points, limit reached | F10: How much does the feature engage users, and how many points does it issue? | G10: Confirmed
A11: Mining | B11: Timed mining session | C11: Starts mining and later claims the result | D11: Accrual calculated, reward credited at claim | E11: start time, rate, boost, claim time, amount | F11: How many users complete a mining cycle, and how many sessions go unclaimed? | G11: Confirmed
A12: Mining | B12: Boosts and upgrades | C12: Activates a boost or upgrade | D12: Rate or multiplier updated | E12: boost type, cost, multiplier, expiry | F12: Do boosts increase engagement or reward cost? | G12: To Be Verified
A13: Spin | B13: Spin wheel | C13: Taps spin | D13: Prize selected from the prize table, reward credited | E13: spin_id, prize table version, prize, ticket used | F13: What is the average reward per spin, and does it match the design? | G13: Confirmed
A14: Missions | B14: Missions and tasks | C14: Views, opens, starts and completes a mission | D14: Completion validated, reward credited | E14: mission_id, version, type, validation result, reward | F14: Which missions convert, and how many fail validation? | G14: Confirmed
... A33: Ad Revenue | B33: Ad network earnings | C33: None (third party) | D33: Revenue reported per ad unit and day | E33: network, ad_unit_id, date, impressions, revenue | F33: What is the revenue against reward cost (unit economics)? | G33: Proposed

Sheet A2 User Action Flows
A1: A2. User Action Flows
A2: Which steps should become measurable events, and which should not
A4: Feature | B4: Step | C4: Step Description | D4: Actor | E4: Classification | F4: Track as event? | G4: Proposed Event | H4: Rationale
A5: Missions | B5: 1 | C5: Mission viewed | D5: User | E5: User Event | F5: Yes | G5: mission_viewed | H5: Impression is the denominator for mission conversion. Send in batches to limit volume.
A6: Missions | B6: 2 | C6: Mission opened | D6: User | E6: User Event | F6: Yes | G6: mission_opened | H6: Shows interest beyond the list view.
A7: Missions | B7: 3 | C7: Mission started | D7: User | E7: User Event | F7: Yes | G7: mission_started | H7: Start of the attempt and of the completion-time clock.
A8: Missions | B8: 4 | C8: Mission completed (user side) | D8: User | E8: User Event | F8: Yes | G8: mission_submitted | H8: The user's claim of completion, before the platform checks it.
A9: Missions | B9: 5 | C9: Completion validated | D9: System | E9: System Event | F9: Yes | G9: mission_completion_validated | H9: Needed to measure pass and fail rates and detect abuse. Include result and reason.
A10: Missions | B10: 6 | C10: Mission completed (confirmed) | D10: System | E10: Business Outcome | F10: Yes | G10: mission_completed | H10: The official completion that counts in KPIs.
A11: Missions | B11: 7 | C11: Reward credited | D11: System | E11: Business Outcome | F11: Yes | G11: mission_reward_credited | H11: Links to the ledger by transaction_id.
A12: Watch Ads | B12: 1 | C12: Ad offer shown | D12: System | E12: System Event | F12: Yes | G12: ad_offer_shown | H12: Measures ad availability against ad starts.
A13: Watch Ads | B13: 2 | C13: Ad requested | D13: System | E13: System Event | F13: Yes | G13: ad_requested | H13: Needed for fill rate.
A14: Watch Ads | B14: 3 | C14: Ad started | D14: User | E14: User Event | F14: Yes | G14: ad_started | H14: Confirms the impression and ties it to the user.
A15: Watch Ads | B15: 4 | C15: Ad closed early or failed | D15: User | E15: User Event | F15: Yes | G15: ad_skipped / ad_failed | H15: Explains lost rewards and complaints.
A16: Watch Ads | B16: 5 | C16: Ad completion confirmed by network | D16: System | E16: System Event | F16: Yes | G16: ad_completed | H16: Server-side confirmation is the source of truth, not the client.
... A20: Daily Rewards | B20: 2 | C20: Reward claimed | D20: User | E20: User Event | F20: Yes | G20: daily_reward_claimed | H20: Core engagement event.
A21: Daily Rewards | B21: 3 | C21: Eligibility checked | D21: System | E21: System Event | F21: Derived | H21: Outcome is visible through claim success or failure. Log failures only.
A22: Daily Rewards | B22: 4 | C22: Streak updated or broken | D22: System | E22: System Event | F22: Yes | G22: streak_updated / streak_broken | H22: Needed for retention analysis.
A23: Daily Rewards | B23: 5 | C23: Reward credited | D23: System | E23: Business Outcome | F23: Yes | G23: daily_reward_credited | H23: Links to the ledger.
A24: Tap & Earn | B24: 1 | C24: Individual tap | D24: User | E24: User Event | F24: No | H24: Too much volume. Aggregate instead.
A25: Tap & Earn | B25: 2 | C25: Tap session started | D25: User | E25: User Event | F25: Yes | G25: tap_session_started | H25: Marks the start of a play session.
A26: Tap & Earn | B26: 3 | C26: Tap batch submitted | D26: User | E26: User Event | F26: Yes | G26: tap_batch_submitted | H26: Counts taps per batch with timestamps for anomaly checks.
A27: Tap & Earn | B27: 4 | C27: Energy or limit reached | D27: System | E27: System Event | F27: Yes | G27: tap_limit_reached | H27: Shows whether limits frustrate or protect.
A28: Tap & Earn | B28: 5 | C28: Points credited | D28: System | E28: Business Outcome | F28: Yes | G28: tap_points_credited | H28: Points issued from this feature.
A29: Tap & Earn | B29: 6 | C29: Tap session ended | D29: User | E29: User Event | F29: Derived | H29: Derived from the last batch and inactivity.
A30: Mining | B30: 1 | C30: Mining started | D30: User | E30: User Event | F30: Yes | G30: mining_started | H30: Start of the cycle.
A31: Mining | B31: 2 | C31: Mining timer ticking | D31: System | E31: System Event | F31: No | H31: Derived from start and claim times. Do not log ticks.
A32: Mining | B32: 3 | C32: Mining cycle ended | D32: System | E32: System Event | F32: Yes | G32: mining_cycle_ended | H32: Shows unclaimed cycles.
A33: Mining | B33: 4 | C33: Reward claimed | D33: User | E33: User Event | F33: Yes | G33: mining_claimed | H33: Conversion from cycle to claim.
A34: Mining | B34: 5 | C34: Claim validated | D34: System | E34: System Event | F34: Yes | G34: mining_claim_validated | H34: Server checks duration and amount.
A35: Mining | B35: 6 | C35: Reward credited | D35: System | E35: Business Outcome | F35: Yes | G35: mining_reward_credited | H35: Links to the ledger.
A36: Mining | B36: 7 | C36: Boost activated | D36: User | E36: User Event | F36: Yes | G36: mining_boost_activated | H36: Effect on rate and reward cost.
A37: Spin | B37: 1 | C37: Spin ticket earned | D37: System | E37: Business Outcome | F37: Yes | G37: spin_ticket_earned | H37: Source of spin supply.
A38: Spin | B38: 2 | C38: Spin started | D38: User | E38: User Event | F38: Yes | G38: spin_started | H38: Spin demand.
A39: Spin | B39: 3 | C39: Prize selected | D39: System | E39: System Event | F39: Yes | G39: spin_resulted | H39: Include prize table version for audit.
A40: Spin | B40: 4 | C40: Reward credited | D40: System | E40: Business Outcome | F40: Yes | G40: spin_reward_credited | H40: Reward cost of the feature.
A41: Spin | B41: 5 | C41: Wheel animation | D41: User | E41: User Event | F41: No | H41: No analytical value.
A42: Referrals | B42: 1 | C42: Invite shared | D42: User | E42: User Event | F42: Yes | G42: referral_link_shared | H42: Channel performance.
A43: Referrals | B43: 2 | C43: Link opened | D43: User | E43: User Event | F43: Yes | G43: referral_link_opened | H43: Top of the referral funnel.
A44: Referrals | B44: 3 | C44: Referee registered | D44: System | E44: System Event | F44: Yes | G44: referral_registered | H44: Attribution step.
...

Sheet A3 Event Classification
A1: A3. User Event vs System Event vs Business Outcome
A3: User Event | B3: A deliberate action by the user (tap, open, submit, claim). | C3: Describes behavior and funnels.
A4: System Event | B4: An automated step or decision by the platform (validate, approve, calculate, callback). | C4: Explains why something did or did not happen.
A5: Business Outcome | B5: The final result that changes a KPI, a balance or a status of record (credited, reversed, processed, activated). | C5: Feeds financial and executive reporting. Must reconcile with the ledger.
A7: Classification of proposed events
A8: Event / Item | B8: Classification | C8: Triggered By | D8: Why It Is Classified This Way | E8: Source | F8: Key Fields
A9: mission_started | B9: User Event | C9: User taps start | D9: Initiated by the user | E9: Frontend | F9: user_id, mission_id, version
A10: mission_completion_validated | B10: System Event | C10: Platform checks the proof | D10: Automated check, intermediate step | E10: Backend | F10: mission_id, result, reason
A11: mission_completed | B11: Business Outcome | C11: Validation passed | D11: Confirmed result that counts in KPIs | E11: Backend | F11: mission_id, completed_at
A12: reward_credited | B12: Business Outcome | C12: Any feature grants a reward | D12: Increases the balance and platform liability | E12: Backend | F12: transaction_id, amount, source_feature, balance_after
A13: reward_reversed | B13: Business Outcome | C13: Fraud or error correction | D13: Decreases the balance and must link to the original credit | E13: Backend | F13: transaction_id, original_transaction_id, reason
A14: ad_completed | B14: System Event | C14: Ad network confirms | D14: Third-party confirmation, intermediate | E14: Ad network / Backend | F14: ad_unit_id, network, completed_at
A15: ad_started | B15: User Event | C15: User starts watching | D15: User-initiated | E15: Frontend | F15: ad_unit_id, placement
A16: ad_revenue_reported | B16: Business Outcome | C16: Daily network report | D16: Revenue figure of record | E16: Ad network | F16: date, ad_unit_id, revenue
A17: daily_reward_claimed | B17: User Event | C17: User taps claim | D17: User-initiated | E17: Frontend | F17: claim_date, streak_day
A18: streak_broken | B18: System Event | C18: Day passes without a claim | D18: Automated state change | E18: Backend | F18: previous_streak
A19: tap_batch_submitted | B19: User Event | C19: Client sends tap count | D19: User behavior, aggregated | E19: Frontend | F19: tap_count, window
... A39: notification_opened | B39: User Event | C39: User taps notification | D39: User-initiated | E39: Frontend | F39: campaign_id

Sheet A4 Coverage Matrix
A1: A4. Data Coverage Matrix
A3: ID | B3: Product Area | C3: Feature/Module | D3: User Action | E3: System Action | F3: Business Outcome | G3: Data Required | H3: Proposed Event | I3: Source | J3: Business Question | K3: Status | L3: Priority | M3: Expected Output
A4: A4-01 | B4: Registration | C4: Sign-up | D4: Submits sign-up details | E4: Validates and creates account, assigns user_id | F4: New registered user | G4: user_id, timestamp, source, platform, UTM | H4: registration_started; account_created | I4: Frontend; Backend | J4: Which channels bring users, and what is the visitor-to-user rate? | K4: Confirmed | L4: Critical | M4: Registrations by source and platform
A5: A4-02 | B5: Registration | C5: Sign-up failure | D5: Receives an error | E5: Rejects and logs reason | F5: Lost sign-up | G5: error_type, step | H5: registration_failed | I5: Frontend; Backend | J5: Where do sign-ups fail? | K5: Proposed | L5: Medium | M5: Failure rate by reason
A6: A4-03 | B6: Login | C6: Login | D6: Enters credentials or uses social login | E6: Authenticates, opens session | F6: Active session | G6: timestamp, session_id, method, platform | H6: login_succeeded; login_failed | I6: Backend | J6: How often do users return, and how often does login fail? | K6: Confirmed | L6: Critical | M6: DAU/WAU/MAU, login failure rate
A7: A4-04 | B7: Onboarding | C7: Onboarding | D7: Views and completes steps | E7: Records milestones | F7: Activated user | G7: step, timestamps, milestone | H7: onboarding_started; onboarding_step_completed; onboarding_completed | I7: Frontend; Backend | J7: Where do new users drop off before first reward? | K7: Proposed | L7: High | M7: Onboarding funnel, time to first reward
A8: A4-05 | B8: Profile & Verification | C8: Verification | D8: Submits verification | E8: Approves or rejects | F8: Verified account | G8: status, timestamps, reason code | H8: verification_submitted; verification_resolved | I8: Backend; Provider | J8: Does verification block withdrawals? | K8: To Be Verified | L8: High | M8: Pass rate and time to verify
A9: A4-06 | B9: Watch Ads | C9: Rewarded ad | D9: Taps to watch and watches | E9: Requests ad, receives completion callback, credits reward | F9: Ad revenue and reward cost | G9: ad_unit_id, network, placement, completion, reward | H9: ad_offer_shown; ad_requested; ad_started; ad_completed; ad_reward_credited | I9: Frontend; Ad network; Backend | J9: Is ad revenue higher than reward cost? | K9: Confirmed | L9: Critical | M9: Completion rate, fill rate, margin per ad
A10: A4-07 | B10: Watch Ads | C10: Ad failure | D10: Ad fails or is closed early | E10: Logs error | F10: Lost impression | G10: error_code, network | H10: ad_failed; ad_skipped | I10: Frontend | J10: What is the fill rate and where do ads fail? | K10: Proposed | L10: High | M10: Failure rate by network and placement
A11: A4-08 | B11: Ad Revenue | C11: Revenue reporting | D11: None | E11: Imports network report | F11: Revenue of record | G11: date, ad_unit_id, impressions, revenue | H11: ad_revenue_reported | I11: Ad network | J11: What are unit economics? | K11: Proposed | L11: Critical | M11: Daily revenue vs reward cost
A12: A4-09 | B12: Daily Rewards | C12: Daily check-in | D12: Views and claims | E12: Checks eligibility, credits, updates streak | F12: Retention reward | G12: claim date, streak day, amount | H12: daily_reward_viewed; daily_reward_claimed; streak_updated; streak_broken; daily_reward_credited | I12: Frontend; Backend | J12: Does the daily reward improve retention? | K12: Confirmed | L12: High | M12: Claim rate, streak distribution
A13: A4-10 | B13: Tap & Earn | C13: Tapping | D13: Taps | E13: Aggregates, applies energy and limits, credits points | F13: Points issued | G13: tap_count (batched), energy, points | H13: tap_session_started; tap_batch_submitted; tap_limit_reached; tap_points_credited | I13: Frontend; Backend | J13: How much engagement and how many points does it generate? | K13: Confirmed | L13: High | M13: Taps per user, points issued, limit hits
A14: A4-11 | B14: Mining | C14: Start mining | D14: Starts a session | E14: Starts timer and accrual | F14: Active session | G14: start time, rate, boost | H14: mining_started | I14: Frontend; Backend | J14: How many users start mining? | K14: Confirmed | L14: High | M14: Mining participation rate
... A38: A4-35 | B38: Economy & Configuration | C38: Config change | D38: None | E38: Versions rates, limits, prize tables | F38: Config of record | G38: config_id, old/new value, effective time | H38: reward_config_changed | I38: Backend; Admin tool | J38: Which rules applied when a reward was issued? | K38: Proposed | L38: High | M38: Config history for audit

Sheet Analytics Gaps
A1: Analytics Gaps Affecting Future Production Reporting
A2: At least 10 required. This list contains more because each could change or block a production report.
A4: ID | B4: Analytics Gap | C4: Product Area | D4: Impact on Reporting | E4: Recommended Resolution | F4: Priority | G4: Suggested Owner | H4: Status
A5: G-01 | B5: Ad completion and revenue cannot be reconciled | C5: Watch Ads | D5: If completion relies on the client only, rewards may be paid for ads that never completed, and revenue per ad cannot be matched to the ad network report. | E5: Use server-side ad confirmation. Store network, ad_unit_id and impression ID. Import daily network revenue. | F5: Critical | G5: Engineering + Finance | H5: To Be Verified
A6: G-02 | B6: No single reward ledger across features | C6: Wallet | D6: Rewards from ads, missions, spins, mining and referrals may be stored separately, so total liability and balances cannot be reconciled. | E6: Create one ledger with transaction_id, type, amount, currency, source_feature and balance_after for every credit and debit. | F6: Critical | G6: Engineering + Finance | H6: To Be Verified
A7: G-03 | B7: Reward unit and conversion rate not defined or versioned | C7: Wallet / Economy | D7: Points, coins and cash value may be mixed. Without a versioned conversion rate, historical cost cannot be calculated. | E7: Define currency units and store the rate and its effective dates. | F7: Critical | G7: Product + Finance | H7: To Be Verified
A8: G-04 | B8: Reward reversals have no reason or link to the original credit | C8: Wallet | D8: Net reward cost and abuse rates will be overstated or unexplained. | E8: Require original_transaction_id and reason code on every reversal. | F8: High | G8: Engineering | H8: Proposed
A9: G-05 | B9: Withdrawal lifecycle statuses are not defined | C9: Withdrawals | D9: Without clear statuses and timestamps, approval rate, processing time and failures cannot be measured. | E9: Define states: requested, validated, under review, approved, submitted, processed, rejected, failed. Timestamp each change. | F9: Critical | G9: Product + Engineering | H9: To Be Verified
A10: G-06 | B10: Referral 'activation' rule is not defined | C10: Referrals | D10: Referral counts and bonus cost will differ between teams. Self-referrals and duplicates cannot be separated from valid ones. | E10: Document the activation rule and version it. Store attribution window and rejection reasons. | F10: Critical | G10: Product | H10: To Be Verified
A11: G-07 | B11: Mining time is not validated server-side | C11: Mining | D11: Client clocks can be changed, so accrued rewards and session lengths may be wrong. | E11: Use server timestamps for start, end and claim. Record the accrual calculation inputs. | F11: High | G11: Engineering | H11: To Be Verified
A12: G-08 | B12: Tap volume cannot be verified | C12: Tap & Earn | D12: Batched tap counts submitted by the client could be inflated, and per-tap logging is too costly. | E12: Define batch format, rate limits and server checks. Log limit hits and rejected batches. | F12: High | G12: Engineering | H12: Proposed
A13: G-09 | B13: Prize table and probabilities are not versioned | C13: Spin | D13: Payout cannot be audited against the intended design if the table changes without a record. | E13: Store prize_table_version on every spin and keep config history. | F13: High | G13: Product + Engineering | H13: Proposed
A14: G-10 | B14: Mission definitions change without version history | C14: Missions | D14: Completion rates before and after a change are not comparable. | E14: Add mission version and effective dates to every mission event. | F14: High | G14: Product | H14: Proposed
A15: G-11 | B15: Day boundary for daily rewards and streaks is undefined | C15: Daily Rewards | D15: UTC versus local time changes who keeps a streak and distorts daily KPIs. | E15: Choose one rule, document it and store it with each claim. | F15: High | G15: Product | H15: To Be Verified
... A23: G-19 | B23: No acquisition cost or marketing spend data | C23: Registration | D23: Channel quality cannot be tied to cost, so payback and return on acquisition cannot be measured. | E23: Import spend by channel and campaign, and store UTM data at registration. | F23: Medium | G23: Marketing + Data | H23: Proposed

Sheet Summary
A1: Summary
A2: All counts are formulas and update when rows change
A3: A4 Coverage Matrix by priority
A4: Priority | B4: Rows
A5: Critical | B5: =COUNTIF('A4 Coverage Matrix'!$L$4:$L$200,A5) -> 12
A6: High | B6: =COUNTIF('A4 Coverage Matrix'!$L$4:$L$200,A6) -> 15
A7: Medium | B7: =COUNTIF('A4 Coverage Matrix'!$L$4:$L$200,A7) -> 6
A8: Low | B8: =COUNTIF('A4 Coverage Matrix'!$L$4:$L$200,A8) -> 2
A9: Total | B9: =SUM(B5:B8) -> 35
A10: Status (A1, A4 and Gaps)
A11: Status | B11: A1 Features | C11: A4 Rows | D11: Gaps
A12: Confirmed | B12: =COUNTIF('A1 Product Area Map'!$G$4:$G$200,A12) -> 17 | C12: =COUNTIF('A4 Coverage Matrix'!$K$4:$K$200,A12) -> 20 | D12: =COUNTIF('Analytics Gaps'!$H$5:$H$200,A12) -> 0
A13: Proposed | B13: =COUNTIF('A1 Product Area Map'!$G$4:$G$200,A13) -> 9 | C13: =COUNTIF('A4 Coverage Matrix'!$K$4:$K$200,A13) -> 11 | D13: =COUNTIF('Analytics Gaps'!$H$5:$H$200,A13) -> 8
A14: To Be Verified | B14: =COUNTIF('A1 Product Area Map'!$G$4:$G$200,A14) -> 4 | C14: =COUNTIF('A4 Coverage Matrix'!$K$4:$K$200,A14) -> 4 | D14: =COUNTIF('Analytics Gaps'!$H$5:$H$200,A14) -> 11
A15: Total | B15: =SUM(B12:B14) -> 30 | C15: =SUM(C12:C14) -> 35 | D15: =SUM(D12:D14) -> 19
A16: Analytics gaps by priority
A17: Priority | B17: Gaps
A18: Critical | B18: =COUNTIF('Analytics Gaps'!$F$5:$F$200,A18) -> 6
A19: High | B19: =COUNTIF('Analytics Gaps'!$F$5:$F$200,A19) -> 11
A20: Medium | B20: =COUNTIF('Analytics Gaps'!$F$5:$F$200,A20) -> 2
A21: Low | B21: =COUNTIF('Analytics Gaps'!$F$5:$F$200,A21) -> 0
A22: Total | B22: =SUM(B18:B21) -> 19
A23: A2 steps: track as event?
A24: Decision | B24: Steps
A25: Yes | B25: =COUNTIF('A2 User Action Flows'!$F$5:$F$300,A25) -> 51
A26: Derived | B26: =COUNTIF('A2 User Action Flows'!$F$5:$F$300,A26) -> 2
A27: No | B27: =COUNTIF('A2 User Action Flows'!$F$5:$F$300,A27) -> 3
A28: Total | B28: =SUM(B25:B27) -> 56
A29: A3 events by classification
A30: Classification | B30: Items
A31: User Event | B31: =COUNTIF('A3 Event Classification'!$B$9:$B$200,A31) -> 9
A32: System Event | B32: =COUNTIF('A3 Event Classification'!$B$9:$B$200,A32) -> 10
A33: Business Outcome | B33: =COUNTIF('A3 Event Classification'!$B$9:$B$200,A33) -> 12
A34: Total | B34: =SUM(B31:B33) -> 31
A35: A4 coverage by product area
A36: Product Area | B36: A1 Features | C36: A4 Rows
A37: Registration | B37: =COUNTIF('A1 Product Area Map'!$A$4:$A$200,A37) -> 1 | C37: =COUNTIF('A4 Coverage Matrix'!$B$4:$B$200,A37) -> 2
A38: Login | B38: =COUNTIF('A1 Product Area Map'!$A$4:$A$200,A38) -> 1 | C38: =COUNTIF('A4 Coverage Matrix'!$B$4:$B$200,A38) -> 1
A39: Onboarding | B39: =COUNTIF('A1 Product Area Map'!$A$4:$A$200,A39) -> 1 | C39: =COUNTIF('A4 Coverage Matrix'!$B$4:$B$200,A39) -> 1
A40: Profile & Verification | B40: =COUNTIF('A1 Product Area Map'!$A$4:$A$200,A40) -> 1 | C40: =COUNTIF('A4 Coverage Matrix'!$B$4:$B$200,A40) -> 1
...
