Workbook

Sheet README
A1: VELOOP – Earning Activity Analytics Design
A2: Analyst workbook: lifecycle measurement, schemas, failure classification, reward events, third-party dependency, sample datasets and KPIs
A4: PURPOSE | B4: Define how VELOOP should measure earning activity across Discovery > Start > Completion > Validation > Reward, and separate 'activity occurred' from 'reward actually credited'.
A5: IMPORTANT – DATA STATUS | B5: No VELOOP data or internal schema was supplied. Every field, event name and failure class in this workbook is PROPOSED and must be confirmed against what VELOOP actually records. Nothing here is presented as an existing VELOOP code.
A6: IMPORTANT – SAMPLE DATA | B6: Sheets 'Data_Tasks' and 'Data_RewardEvents' are SYNTHETIC, generated only to demonstrate the dataset design and make the KPI formulas work. Rates, providers, feature names and reward amounts are illustrative. Replace them with real exports and the dashboard recalculates.
A7: STATUS LABELS | B7: Proposed = recommended design, not confirmed to exist. To confirm = needs a yes/no from VELOOP product/engineering. Given in brief = requested in the assignment.
A8: SHEET MAP | B8: Lifecycle > C1_Task_Schema > C2_Failure_Taxonomy > C3_Reward_Events > C4_Third_Party > Data_Tasks > Data_RewardEvents > KPI_Definitions > KPI_Dashboard > Open_Questions
A9: HOW TO USE | B9: 1) Review design sheets. 2) Answer Open_Questions. 3) Paste real data into Data_Tasks (cols A-P) and Data_RewardEvents (cols A-I); formula columns Q-AB in Data_Tasks must be filled down. 4) Extend the ranges in KPI_Dashboard if rows exceed the sample size.
A10: LEGEND | B10: Blue text = editable input/assumption. Black = formula or text. Yellow fill = Proposed. Orange fill = To confirm / given in brief.
A11: CORE PRINCIPLE | B11: Reward credited is a separate event from task completed. Never infer a credit from a completion; never design as if VELOOP controls outcomes decided by ad networks, survey providers, offer partners, game partners or tracking systems.
A13: ASSUMPTIONS (editable)
A14: Reward unit used in sample data | B14: points
A15: Data snapshot date (sample) | B15: 46319
A16: Source of assumptions | B16: Analyst assumptions for illustration; not VELOOP figures.

Sheet Lifecycle
A1: Analytical lifecycle – what to measure at each stage
A2: All event names are Proposed. 'Third-party influence' shows where external systems can change the data.
A4: Stage | B4: Question the stage answers | C4: Proposed event(s) | D4: Timestamp to capture | E4: Key fields | F4: Core metrics | G4: Likely data source | H4: Third-party influence | I4: Measurement risk / design note | J4: Status
A5: 1. Discovery | B5: Was the earning opportunity available and shown to the user? | C5: task_discovered (task listed / impression) | D5: discovered_at | E5: task_id, task_type, feature, user_id, source_provider, reward_expected, reward_unit | F5: Tasks exposed; unique users exposed; availability / fill rate; reward shown | G5: VELOOP app/server logs; provider inventory feeds | H5: High for ads/offers/surveys: provider decides inventory, targeting, no-fill. | I5: Distinguish 'not shown because no inventory' from 'shown but ignored'. Without a discovery event, start rate has no denominator. | J5: Proposed
A6: 2. Start | B6: Did the user begin the task, and did the system confirm it? | C6: task_started (user action) ; task_start_confirmed (provider/tracking confirmation, where applicable) | D6: start_time (+ confirmation time) | E6: task_id, user_id, start_time, external_ref_id, source_type | F6: Start rate; time-to-start; starts without tracking confirmation | G6: VELOOP logs; tracking / click-out records | H6: High: click-out to external offers/surveys/games may not be observable after leaving VELOOP. | I6: Record user intent (click) separately from confirmed start. Unconfirmed starts are a tracking-risk segment, not automatically user failures. | J6: Proposed
A7: 3. Completion | B7: Did the task finish, and who says so? | C7: task_completed ; task_failed ; task_abandoned | D7: completion_time | E7: status, completion_time, data_origin (first_party_observed / third_party_reported / inferred) | F7: Completion rate; duration; abandonment; completion by provider | G7: VELOOP logs; provider callbacks/postbacks | H7: High: completion is often reported by the provider, possibly late or never. | I7: Store when VELOOP RECEIVED a postback as well as when the activity happened. Never mark abandoned only because a postback is late – use a defined time window. | J7: Proposed
A8: 4. Validation | B8: Was the completion accepted as genuine/eligible? | C8: validation_requested ; validation_passed ; validation_rejected ; validation_timeout | D8: validation_time | E8: validation_status, validation_source (provider / VELOOP rules), rejection_reason | F8: Validation pass / rejection rate; time to validate; pending ageing; rejection by provider | G8: Provider confirmation; VELOOP validation rules | H8: High: provider may reject, reverse or never confirm. | I8: Keep validator identity so rejections are attributable. 'Pending' must age out into an explicit state, not stay pending forever. | J8: Proposed
A9: 5. Reward | B9: Was value actually credited, and does it still stand? | C9: reward_pending ; reward_credited ; reward_reversed ; reward_corrected | D9: event_time per reward event | E9: reward_amount, reward_unit, event_type, reason, task_id, user_id | F9: Credit rate; credit latency; reversal rate; correction rate; net credited vs expected | G9: VELOOP ledger / wallet records | H9: Medium-High: reversals and corrections frequently originate from provider decisions. | I9: Ledger is the source of truth for 'credited'. Use signed amounts (reversal negative) so net reward is a simple sum. | J9: Proposed

Sheet C1_Task_Schema
A1: C1 – Task-level analytics schema (one row per task attempt)
A2: Field names are Proposed. 'In brief' = field requested in the assignment.
A4: Field | B4: Definition | C4: Data type | D4: Lifecycle stage | E4: In brief? | F4: Allowed values / example | G4: Likely source | H4: Third-party sensitivity | I4: Status
A5: task_id | B5: Unique ID of one task attempt (one user x one task instance). Distinct from catalogue ID of the task offer. | C5: string | D5: All | E5: Yes | F5: T000123 | G5: VELOOP | H5: Low – but external IDs must be mapped (see external_ref_id) | I5: Proposed
A6: task_type | B6: Kind of activity the user performs. | C6: string (enum) | D6: Discovery | E6: Yes | F6: video_view, survey_complete, offer_install, game_milestone, in_app_action | G6: VELOOP / provider | H6: Medium | I6: Proposed
A7: feature | B7: Earning feature the task belongs to. | C7: string (enum) | D7: Discovery | E7: Yes | F7: Advertisements, Surveys, Offers, Games | G7: VELOOP | H7: Low | I7: Proposed
A8: user_id | B8: Pseudonymous user identifier. | C8: string | D8: All | E8: Yes | F8: U0007 | G8: VELOOP | H8: Low | I8: Proposed
A9: discovered_at | B9: When task was shown to the user. Needed as funnel denominator. | C9: datetime (UTC) | D9: Discovery | E9: No (added) | F9: 2026-10-02 14:03 | G9: VELOOP | H9: Medium | I9: Proposed
A10: start_time | B10: When the user began the task (intent). Blank if never started. | C10: datetime (UTC) | D10: Start | E10: Yes | F10: 2026-10-02 14:05 | G10: VELOOP / tracking | H10: High | I10: Proposed
A11: completion_time | B11: When completion happened (event time, not receipt time). Blank if not completed. | C11: datetime (UTC) | D11: Completion | E11: Yes | F11: 2026-10-02 14:21 | G11: VELOOP / provider | H11: High | I11: Proposed
A12: completion_received_at | B12: When VELOOP received the completion signal. Lets analysts measure external delay. | C12: datetime (UTC) | D12: Completion | E12: No (added) | F12: 2026-10-02 14:40 | G12: VELOOP | H12: High | I12: Proposed
A13: status | B13: Activity outcome: discovered, in_progress, completed, failed, abandoned. Says nothing about reward. | C13: string (enum) | D13: Completion | E13: Yes | F13: completed | G13: Derived | H13: High | I13: Proposed
A14: validation_status | B14: validated, rejected, pending, not_applicable, unknown_external. | C14: string (enum) | D14: Validation | E14: Yes | F14: validated | G14: Provider / VELOOP rules | H14: High | I14: Proposed
A15: reward_amount_expected | B15: Reward promised/displayed for the task. | C15: number | D15: Reward | E15: Yes (reward amount) | F15: 50 | G15: VELOOP / provider | H15: Medium | I15: Proposed
... A24: last_updated_at | B24: Last time the record changed; supports late-arriving data analysis. | C24: datetime (UTC) | D24: Any | E24: No (added) | F24: 2026-10-04 09:00 | G24: VELOOP | H24: Medium | I24: Proposed

Sheet C2_Failure_Taxonomy
A1: C2 – Failed activity: proposed structured classification
A2: No internal failure codes were supplied, so none are assumed. All classes below are Proposed. Use failure_class + failure_attribution + detection_basis together.
A4: failure_class | B4: Lifecycle stage | C4: Meaning | D4: Example sub-reasons (Proposed) | E4: Typical attribution | F4: Detection basis | G4: Counted in failure rate? | H4: Why it matters / caution | I4: Status
A5: task_failed | B5: Completion | C5: User attempted the task but did not meet the conditions. | D5: screen_out, quota_full, task_conditions_not_met, install_not_retained | E5: user or third_party | F5: Provider outcome or VELOOP rule | G5: Yes | H5: Screen-outs and quota-full are decided by the provider, not user quality. Do not label all as user failure. | I5: Proposed
A6: tracking_failed | B6: Start / Completion | C6: Activity may have happened but no (or late) tracking signal reached VELOOP. | D6: no_postback, postback_late, id_mismatch, click_not_recorded | E6: third_party, VELOOP or unknown | F6: Start without completion after defined window; provider report shows completion VELOOP lacks | G6: Yes – flagged as 'uncertain outcome' | H6: Possible true completion with missing data. Reconcile against provider reports before judging the user. | I6: Proposed
A7: validation_failed | B7: Validation | C7: Completion recorded but rejected as not eligible/genuine. | D7: provider_rejected, duplicate, fraud_suspected, ineligible_user | E7: third_party or VELOOP | F7: validation_status = rejected + validator | G7: Yes | H7: Activity occurred but reward is not due. Keep as separate from task_failed. | I7: Proposed
A8: user_abandoned | B8: Start / Completion | C8: User started and left without completing. | D8: closed_app, exited_provider, timeout_no_activity | E8: user | F8: Start without completion; exit event; window elapsed with no tracking issue | G8: Yes | H8: Only valid when tracking is healthy; otherwise it overlaps with tracking_failed. | I8: Proposed
A9: system_error | B9: Any | C9: Technical error stopped the activity or its recording. | D9: app_error, api_error, provider_outage, ad_no_fill, content_load_error | E9: VELOOP or third_party | F9: Error logs; provider status | G9: Yes | H9: Split internal vs external via attribution; external outages are outside VELOOP control but still affect users. | I9: Proposed
A10: reward_credit_failed | B10: Reward | C10: Task completed and validated, but no credit appears in the ledger. | D10: ledger_write_failed, credit_blocked, budget_cap_reached | E10: VELOOP or unknown | F10: Validated task with no reward_credited event after SLA window | G10: Yes (reward stage) | H10: Highest trust risk: user did the work and was validated. Alert when it occurs. | I10: Proposed
A11: unknown | B11: Any | C11: Outcome cannot be explained with available evidence. | D11: insufficient_data | E11: unknown | F11: None of the above | G11: Yes – tracked separately | H11: Keep as a first-class value; do not force into another class. | I11: Proposed
A14: failure_attribution values (Proposed)
A15: value | B15: when to use
A16: user | B16: Evidence points to user behaviour (e.g. explicit exit) with healthy tracking.
A17: VELOOP | B17: Failure occurred in VELOOP systems (app, ledger, internal tracking).
A18: third_party | B18: Failure occurred in an ad network, survey/offer/game provider or external tracker.
A19: unknown | B19: Evidence insufficient. Preferred over guessing.

Sheet C3_Reward_Events
A1: C3 – Reward events: activity occurred vs reward credited
A2: Reward events live in their own table (one row per event) and are never inferred from task status.
A4: event_type | B4: Meaning | C4: Trigger | D4: Amount sign / rule | E4: Required fields | F4: Analytics use | G4: Third-party link | H4: Status
A5: reward_pending | B5: Reward expected but not yet credited (awaiting validation or provider confirmation). | C5: Completion recorded and validation outstanding. | D5: Informational. Equals expected amount; NOT added to net credited. | E5: event_id, task_id, user_id, event_time, amount, unit, reason | F5: Pending value; ageing of pending; time-to-resolve | G5: High – waiting on provider | H5: Proposed
A6: reward_credited | B6: Value written to the user's balance/ledger. | C6: Ledger credit confirmed. | D6: Positive amount; added to net credited. | E6: as above + ledger_ref | F6: Credit rate; credit latency; gross credited | G6: Medium | H6: Proposed
A7: reward_reversed | B7: A previous credit was taken back. | C7: Provider chargeback, fraud review, duplicate found. | D7: Negative amount (equals reversed credit). | E7: as above + original_event_id, reversal_reason | F7: Reversal rate; reversal by provider; value clawed back | G7: High | H7: Proposed
A8: reward_corrected | B8: Credit amount adjusted without full reversal. | C8: Provider restates payout or VELOOP fixes an error. | D8: Signed delta (positive or negative). | E8: as above + original_event_id, correction_reason | F8: Correction rate; net impact of corrections | G8: High | H8: Proposed
A11: Activity vs reward – decision matrix
A12: task status | B12: validation | C12: reward events | D12: interpretation
A13: Completed | B13: validated | C13: credited, no reversal | D13: Normal path. Activity occurred AND reward credited.
A14: Completed | B14: pending | C14: reward_pending only | D14: Activity occurred; reward NOT credited yet. Report as pending value, not earned.
A15: Completed | B15: rejected | C15: none | D15: Activity occurred; no reward due. Count as validation_failed.
A16: Completed | B16: validated | C16: no credit event after SLA | D16: Activity + validation occurred; reward NOT credited. reward_credit_failed – investigate.
A17: Completed | B17: validated | C17: credited then reversed | D17: Credited at one time, not net-credited now. Report gross and net separately.
A18: Completed | B18: validated | C18: credited then corrected | D18: Net credited differs from expected; show correction delta.
A19: Not completed | B19: n/a | C19: none | D19: No reward. Failure type per C2.
A21: Reconciliation rule (Proposed): expected reward on completed tasks - rejected - open pending - credit failed = gross credited; gross credited + reversals + corrections = net credited. Any leftover is 'unexplained' and must be investigated (see KPI_Dashboard).

Sheet C4_Third_Party
A1: C4 – Third-party dependency: what VELOOP does and does not control
A2: Design principle: record who reported each fact, segment every KPI by provider, and keep 'unknown' as a valid outcome.
A4: Dependency | B4: What the external party controls | C4: How it can distort VELOOP data | D4: What VELOOP can observe | E4: Analytics design response (Proposed) | F4: Segment KPIs by | G4: Confidence in data
A5: Advertisements | B5: Ad inventory, fill, targeting, view verification, payout. | C5: No-fill looks like low engagement; view counts may differ from provider billing; invalid-traffic reversals arrive later. | D5: Ad request, ad shown, close events inside VELOOP. | E5: Log ad_requested and ad_shown separately; capture no_fill as system_error (external). Reconcile views with network report. | F5: ad network, placement, country | G5: Medium – first-party view, third-party verification
A6: Surveys | B6: Survey availability, screen-outs, quotas, quality checks, completion confirmation. | C6: Screen-out and quota-full look like user failure; long confirmation delays; late rejections. | D6: Click-out, return redirect, postback. | E6: Record screen_out as task_failed with attribution third_party; track postback latency; report rejection rate by provider. | F6: survey provider, survey length, country | G6: Low-Medium – outcome decided externally
A7: Offers | B7: Install/signup tracking, conversion rules, hold periods, chargebacks. | C7: Long pending periods; conversions may be rejected or reversed after crediting; user activity not visible after click-out. | D7: Click-out, postback, conversion status updates. | E7: Store pending ageing and reversal lag; never report offer reward as earned until credited; track reversal by provider. | F7: offer provider, offer type, hold period | G7: Low – long, external lifecycle
A8: Games | B8: Milestone tracking inside the game, game servers, payout rules. | C8: Milestones may not be reported; game outage interrupts progress; payout restated. | D8: Click-out, milestone postbacks. | E8: Treat missing milestone as tracking_failed until reconciled; record milestone definition per task. | F8: game partner, milestone type | G8: Low-Medium
A9: Tracking systems / postbacks | B9: Attribution, click-to-conversion matching, delivery of callbacks. | C9: Missing, duplicate or late postbacks create phantom failures or double counts; ID mismatches break joins. | D9: Postback received time, payload, error responses. | E9: Store event_time and received_time; de-duplicate on external_ref_id; define window after which a missing postback becomes tracking_failed (Proposed, e.g. provider-specific). | F9: tracking source, provider, postback delay band | G9: Variable – check postback delivery health first
A12: Design principles
A13: # | B13: principle
A14: 1 | B14: Record data_origin on every status (first_party_observed / third_party_reported / inferred).
A15: 2 | B15: Capture event time AND receipt time for every external signal.
A16: 3 | B16: Reconcile with provider reports on a schedule; track the match rate as a KPI (K22).
A17: 4 | B17: Attribute failures to the best-evidence owner; use 'unknown' instead of guessing.
A18: 5 | B18: Compare providers only after checking tracking health; poor tracking looks like poor engagement.
A19: 6 | B19: Report headline KPIs with third-party-attributable share alongside, so decline is not blamed on VELOOP or users by default.

Sheet Data_Tasks
A1: task_id | B1: task_type | C1: feature | D1: user_id | E1: source_provider | F1: source_type | G1: external_ref_id | H1: discovered_at | I1: start_time | J1: completion_time | K1: status | L1: validation_status | M1: reward_amount_expected | N1: reward_unit | O1: failure_class | P1: failure_attribution | Q1: duration_min | R1: n_pending | S1: n_credited | T1: n_reversed | U1: n_corrected | V1: net_reward_credited | W1: first_credit_time | X1: credit_latency_hrs | Y1: flag_started | Z1: flag_completed | AA1: flag_validated | AB1: flag_credited
A2: T00001 | B2: game_milestone | C2: Games | D2: U0027 | E2: GamePartner_A | F2: third_party | G2: EXT-88742 | H2: 46294.84 | I2: 46294.844 | J2: 46294.893 | K2: completed | L2: rejected | M2: 30 | N2: =README!$B$14 -> points | O2: validation_failed | P2: VELOOP | Q2: =IF(AND(I2<>"",J2<>""),(J2-I2)*1440,"") -> 71.152892 | R2: =COUNTIFS(Data_RewardEvents!$B$2:$B$160,A2,Data_RewardEvents!$D$2:$D$160,"reward_pending") -> 0 | S2: =COUNTIFS(Data_RewardEvents!$B$2:$B$160,A2,Data_RewardEvents!$D$2:$D$160,"reward_credited") -> 0 | T2: =COUNTIFS(Data_RewardEvents!$B$2:$B$160,A2,Data_RewardEvents!$D$2:$D$160,"reward_reversed") -> 0 | U2: =COUNTIFS(Data_RewardEvents!$B$2:$B$160,A2,Data_RewardEvents!$D$2:$D$160,"reward_corrected") -> 0 | V2: =SUMIFS(Data_RewardEvents!$F$2:$F$160,Data_RewardEvents!$B$2:$B$160,A2,Data_RewardEvents!$D$2:$D$160,"reward_credited")+SUMIFS(Data_RewardEvents!$F$2:$F$160,Data_RewardEvents!$B$2:$B$160,A2,Data_RewardEvents!$D$2:$D$160,"reward_reversed")+SUMIFS(Data_RewardEvents!$F$2:$F$160,Data_RewardEvents!$B$2:$B$160,A2,Data_RewardEvents!$D$2:$D$160,"reward_corrected") -> 0 | W2: =IF(S2>0,_xlfn.MINIFS(Data_RewardEvents!$E$2:$E$160,Data_RewardEvents!$B$2:$B$160,A2,Data_RewardEvents!$D$2:$D$160,"reward_credited"),"") | X2: =IF(W2="","",(W2-J2)*24) | Y2: =IF(I2<>"",1,0) -> 1 | Z2: =IF(K2="completed",1,0) -> 1 | AA2: =IF(L2="validated",1,0) -> 0 | AB2: =IF(S2>0,1,0) -> 0
A3: T00002 | B3: offer_install | C3: Offers | D3: U0032 | E3: Offerwall_B | F3: third_party | G3: EXT-63626 | H3: 46302.015 | K3: discovered | M3: 100 | N3: =README!$B$14 -> points | Q3: =IF(AND(I3<>"",J3<>""),(J3-I3)*1440,"") | R3: =COUNTIFS(Data_RewardEvents!$B$2:$B$160,A3,Data_RewardEvents!$D$2:$D$160,"reward_pending") -> 0 | S3: =COUNTIFS(Data_RewardEvents!$B$2:$B$160,A3,Data_RewardEvents!$D$2:$D$160,"reward_credited") -> 0 | T3: =COUNTIFS(Data_RewardEvents!$B$2:$B$160,A3,Data_RewardEvents!$D$2:$D$160,"reward_reversed") -> 0 | U3: =COUNTIFS(Data_RewardEvents!$B$2:$B$160,A3,Data_RewardEvents!$D$2:$D$160,"reward_corrected") -> 0 | V3: =SUMIFS(Data_RewardEvents!$F$2:$F$160,Data_RewardEvents!$B$2:$B$160,A3,Data_RewardEvents!$D$2:$D$160,"reward_credited")+SUMIFS(Data_RewardEvents!$F$2:$F$160,Data_RewardEvents!$B$2:$B$160,A3,Data_RewardEvents!$D$2:$D$160,"reward_reversed")+SUMIFS(Data_RewardEvents!$F$2:$F$160,Data_RewardEvents!$B$2:$B$160,A3,Data_RewardEvents!$D$2:$D$160,"reward_corrected") -> 0 | W3: =IF(S3>0,_xlfn.MINIFS(Data_RewardEvents!$E$2:$E$160,Data_RewardEvents!$B$2:$B$160,A3,Data_RewardEvents!$D$2:$D$160,"reward_credited"),"") | X3: =IF(W3="","",(W3-J3)*24) | Y3: =IF(I3<>"",1,0) -> 0 | Z3: =IF(K3="completed",1,0) -> 0 | AA3: =IF(L3="validated",1,0) -> 0 | AB3: =IF(S3>0,1,0) -> 0
A4: T00003 | B4: video_view | C4: Advertisements | D4: U0029 | E4: AdNetwork_A | F4: third_party | G4: EXT-26962 | H4: 46288.281 | I4: 46288.292 | J4: 46288.293 | K4: completed | L4: validated | M4: 5 | N4: =README!$B$14 -> points | Q4: =IF(AND(I4<>"",J4<>""),(J4-I4)*1440,"") -> 1.1696717 | R4: =COUNTIFS(Data_RewardEvents!$B$2:$B$160,A4,Data_RewardEvents!$D$2:$D$160,"reward_pending") -> 0 | S4: =COUNTIFS(Data_RewardEvents!$B$2:$B$160,A4,Data_RewardEvents!$D$2:$D$160,"reward_credited") -> 1 | T4: =COUNTIFS(Data_RewardEvents!$B$2:$B$160,A4,Data_RewardEvents!$D$2:$D$160,"reward_reversed") -> 0 | U4: =COUNTIFS(Data_RewardEvents!$B$2:$B$160,A4,Data_RewardEvents!$D$2:$D$160,"reward_corrected") -> 0 | V4: =SUMIFS(Data_RewardEvents!$F$2:$F$160,Data_RewardEvents!$B$2:$B$160,A4,Data_RewardEvents!$D$2:$D$160,"reward_credited")+SUMIFS(Data_RewardEvents!$F$2:$F$160,Data_RewardEvents!$B$2:$B$160,A4,Data_RewardEvents!$D$2:$D$160,"reward_reversed")+SUMIFS(Data_RewardEvents!$F$2:$F$160,Data_RewardEvents!$B$2:$B$160,A4,Data_RewardEvents!$D$2:$D$160,"reward_corrected") -> 5 | W4: =IF(S4>0,_xlfn.MINIFS(Data_RewardEvents!$E$2:$E$160,Data_RewardEvents!$B$2:$B$160,A4,Data_RewardEvents!$D$2:$D$160,"reward_credited"),"") -> 46288.294 | X4: =IF(W4="","",(W4-J4)*24) -> 0.021285266 | Y4: =IF(I4<>"",1,0) -> 1 | Z4: =IF(K4="completed",1,0) -> 1 | AA4: =IF(L4="validated",1,0) -> 1 | AB4: =IF(S4>0,1,0) -> 1
A5: T00004 | B5: survey_complete | C5: Surveys | D5: U0066 | E5: SurveyProv_A | F5: third_party | G5: EXT-94461 | H5: 46285.997 | I5: 46286.011 | J5: 46286.018 | K5: completed | L5: validated | M5: 50 | N5: =README!$B$14 -> points | Q5: =IF(AND(I5<>"",J5<>""),(J5-I5)*1440,"") -> 9.7042319 | R5: =COUNTIFS(Data_RewardEvents!$B$2:$B$160,A5,Data_RewardEvents!$D$2:$D$160,"reward_pending") -> 1 | S5: =COUNTIFS(Data_RewardEvents!$B$2:$B$160,A5,Data_RewardEvents!$D$2:$D$160,"reward_credited") -> 1 | T5: =COUNTIFS(Data_RewardEvents!$B$2:$B$160,A5,Data_RewardEvents!$D$2:$D$160,"reward_reversed") -> 0 | U5: =COUNTIFS(Data_RewardEvents!$B$2:$B$160,A5,Data_RewardEvents!$D$2:$D$160,"reward_corrected") -> 0 | V5: =SUMIFS(Data_RewardEvents!$F$2:$F$160,Data_RewardEvents!$B$2:$B$160,A5,Data_RewardEvents!$D$2:$D$160,"reward_credited")+SUMIFS(Data_RewardEvents!$F$2:$F$160,Data_RewardEvents!$B$2:$B$160,A5,Data_RewardEvents!$D$2:$D$160,"reward_reversed")+SUMIFS(Data_RewardEvents!$F$2:$F$160,Data_RewardEvents!$B$2:$B$160,A5,Data_RewardEvents!$D$2:$D$160,"reward_corrected") -> 50 | W5: =IF(S5>0,_xlfn.MINIFS(Data_RewardEvents!$E$2:$E$160,Data_RewardEvents!$B$2:$B$160,A5,Data_RewardEvents!$D$2:$D$160,"reward_credited"),"") -> 46287.338 | X5: =IF(W5="","",(W5-J5)*24) -> 31.672815 | Y5: =IF(I5<>"",1,0) -> 1 | Z5: =IF(K5="completed",1,0) -> 1 | AA5: =IF(L5="validated",1,0) -> 1 | AB5: =IF(S5>0,1,0) -> 1
A6: T00005 | B6: video_view | C6: Advertisements | D6: U0026 | E6: AdNetwork_B | F6: third_party | G6: EXT-60372 | H6: 46299.204 | K6: discovered | M6: 5 | N6: =README!$B$14 -> points | Q6: =IF(AND(I6<>"",J6<>""),(J6-I6)*1440,"") | R6: =COUNTIFS(Data_RewardEvents!$B$2:$B$160,A6,Data_RewardEvents!$D$2:$D$160,"reward_pending") -> 0 | S6: =COUNTIFS(Data_RewardEvents!$B$2:$B$160,A6,Data_RewardEvents!$D$2:$D$160,"reward_credited") -> 0 | T6: =COUNTIFS(Data_RewardEvents!$B$2:$B$160,A6,Data_RewardEvents!$D$2:$D$160,"reward_reversed") -> 0 | U6: =COUNTIFS(Data_RewardEvents!$B$2:$B$160,A6,Data_RewardEvents!$D$2:$D$160,"reward_corrected") -> 0 | V6: =SUMIFS(Data_RewardEvents!$F$2:$F$160,Data_RewardEvents!$B$2:$B$160,A6,Data_RewardEvents!$D$2:$D$160,"reward_credited")+SUMIFS(Data_RewardEvents!$F$2:$F$160,Data_RewardEvents!$B$2:$B$160,A6,Data_RewardEvents!$D$2:$D$160,"reward_reversed")+SUMIFS(Data_RewardEvents!$F$2:$F$160,Data_RewardEvents!$B$2:$B$160,A6,Data_RewardEvents!$D$2:$D$160,"reward_corrected") -> 0 | W6: =IF(S6>0,_xlfn.MINIFS(Data_RewardEvents!$E$2:$E$160,Data_RewardEvents!$B$2:$B$160,A6,Data_RewardEvents!$D$2:$D$160,"reward_credited"),"") | X6: =IF(W6="","",(W6-J6)*24) | Y6: =IF(I6<>"",1,0) -> 0 | Z6: =IF(K6="completed",1,0) -> 0 | AA6: =IF(L6="validated",1,0) -> 0 | AB6: =IF(S6>0,1,0) -> 0
A7: T00006 | B7: offer_install | C7: Offers | D7: U0008 | E7: Offerwall_A | F7: third_party | G7: EXT-19816 | H7: 46287.262 | I7: 46287.274 | J7: 46287.3 | K7: completed | L7: validated | M7: 100 | N7: =README!$B$14 -> points | Q7: =IF(AND(I7<>"",J7<>""),(J7-I7)*1440,"") -> 36.401773 | R7: =COUNTIFS(Data_RewardEvents!$B$2:$B$160,A7,Data_RewardEvents!$D$2:$D$160,"reward_pending") -> 1 | S7: =COUNTIFS(Data_RewardEvents!$B$2:$B$160,A7,Data_RewardEvents!$D$2:$D$160,"reward_credited") -> 1 | T7: =COUNTIFS(Data_RewardEvents!$B$2:$B$160,A7,Data_RewardEvents!$D$2:$D$160,"reward_reversed") -> 0 | U7: =COUNTIFS(Data_RewardEvents!$B$2:$B$160,A7,Data_RewardEvents!$D$2:$D$160,"reward_corrected") -> 0 | V7: =SUMIFS(Data_RewardEvents!$F$2:$F$160,Data_RewardEvents!$B$2:$B$160,A7,Data_RewardEvents!$D$2:$D$160,"reward_credited")+SUMIFS(Data_RewardEvents!$F$2:$F$160,Data_RewardEvents!$B$2:$B$160,A7,Data_RewardEvents!$D$2:$D$160,"reward_reversed")+SUMIFS(Data_RewardEvents!$F$2:$F$160,Data_RewardEvents!$B$2:$B$160,A7,Data_RewardEvents!$D$2:$D$160,"reward_corrected") -> 100 | W7: =IF(S7>0,_xlfn.MINIFS(Data_RewardEvents!$E$2:$E$160,Data_RewardEvents!$B$2:$B$160,A7,Data_RewardEvents!$D$2:$D$160,"reward_credited"),"") -> 46289.652 | X7: =IF(W7="","",(W7-J7)*24) -> 56.461972 | Y7: =IF(I7<>"",1,0) -> 1 | Z7: =IF(K7="completed",1,0) -> 1 | AA7: =IF(L7="validated",1,0) -> 1 | AB7: =IF(S7>0,1,0) -> 1
A8: T00007 | B8: video_view | C8: Advertisements | D8: U0014 | E8: AdNetwork_B | F8: third_party | G8: EXT-15901 | H8: 46294.267 | K8: discovered | M8: 5 | N8: =README!$B$14 -> points | Q8: =IF(AND(I8<>"",J8<>""),(J8-I8)*1440,"") | R8: =COUNTIFS(Data_RewardEvents!$B$2:$B$160,A8,Data_RewardEvents!$D$2:$D$160,"reward_pending") -> 0 | S8: =COUNTIFS(Data_RewardEvents!$B$2:$B$160,A8,Data_RewardEvents!$D$2:$D$160,"reward_credited") -> 0 | T8: =COUNTIFS(Data_RewardEvents!$B$2:$B$160,A8,Data_RewardEvents!$D$2:$D$160,"reward_reversed") -> 0 | U8: =COUNTIFS(Data_RewardEvents!$B$2:$B$160,A8,Data_RewardEvents!$D$2:$D$160,"reward_corrected") -> 0 | V8: =SUMIFS(Data_RewardEvents!$F$2:$F$160,Data_RewardEvents!$B$2:$B$160,A8,Data_RewardEvents!$D$2:$D$160,"reward_credited")+SUMIFS(Data_RewardEvents!$F$2:$F$160,Data_RewardEvents!$B$2:$B$160,A8,Data_RewardEvents!$D$2:$D$160,"reward_reversed")+SUMIFS(Data_RewardEvents!$F$2:$F$160,Data_RewardEvents!$B$2:$B$160,A8,Data_RewardEvents!$D$2:$D$160,"reward_corrected") -> 0 | W8: =IF(S8>0,_xlfn.MINIFS(Data_RewardEvents!$E$2:$E$160,Data_RewardEvents!$B$2:$B$160,A8,Data_RewardEvents!$D$2:$D$160,"reward_credited"),"") | X8: =IF(W8="","",(W8-J8)*24) | Y8: =IF(I8<>"",1,0) -> 0 | Z8: =IF(K8="completed",1,0) -> 0 | AA8: =IF(L8="validated",1,0) -> 0 | AB8: =IF(S8>0,1,0) -> 0
A9: T00008 | B9: game_milestone | C9: Games | D9: U0006 | E9: GamePartner_A | F9: third_party | G9: EXT-22617 | H9: 46293.016 | K9: discovered | M9: 30 | N9: =README!$B$14 -> points | Q9: =IF(AND(I9<>"",J9<>""),(J9-I9)*1440,"") | R9: =COUNTIFS(Data_RewardEvents!$B$2:$B$160,A9,Data_RewardEvents!$D$2:$D$160,"reward_pending") -> 0 | S9: =COUNTIFS(Data_RewardEvents!$B$2:$B$160,A9,Data_RewardEvents!$D$2:$D$160,"reward_credited") -> 0 | T9: =COUNTIFS(Data_RewardEvents!$B$2:$B$160,A9,Data_RewardEvents!$D$2:$D$160,"reward_reversed") -> 0 | U9: =COUNTIFS(Data_RewardEvents!$B$2:$B$160,A9,Data_RewardEvents!$D$2:$D$160,"reward_corrected") -> 0 | V9: =SUMIFS(Data_RewardEvents!$F$2:$F$160,Data_RewardEvents!$B$2:$B$160,A9,Data_RewardEvents!$D$2:$D$160,"reward_credited")+SUMIFS(Data_RewardEvents!$F$2:$F$160,Data_RewardEvents!$B$2:$B$160,A9,Data_RewardEvents!$D$2:$D$160,"reward_reversed")+SUMIFS(Data_RewardEvents!$F$2:$F$160,Data_RewardEvents!$B$2:$B$160,A9,Data_RewardEvents!$D$2:$D$160,"reward_corrected") -> 0 | W9: =IF(S9>0,_xlfn.MINIFS(Data_RewardEvents!$E$2:$E$160,Data_RewardEvents!$B$2:$B$160,A9,Data_RewardEvents!$D$2:$D$160,"reward_credited"),"") | X9: =IF(W9="","",(W9-J9)*24) | Y9: =IF(I9<>"",1,0) -> 0 | Z9: =IF(K9="completed",1,0) -> 0 | AA9: =IF(L9="validated",1,0) -> 0 | AB9: =IF(S9>0,1,0) -> 0
A10: T00009 | B10: game_milestone | C10: Games | D10: U0036 | E10: GamePartner_A | F10: third_party | G10: EXT-89303 | H10: 46292.917 | K10: discovered | M10: 30 | N10: =README!$B$14 -> points | Q10: =IF(AND(I10<>"",J10<>""),(J10-I10)*1440,"") | R10: =COUNTIFS(Data_RewardEvents!$B$2:$B$160,A10,Data_RewardEvents!$D$2:$D$160,"reward_pending") -> 0 | S10: =COUNTIFS(Data_RewardEvents!$B$2:$B$160,A10,Data_RewardEvents!$D$2:$D$160,"reward_credited") -> 0 | T10: =COUNTIFS(Data_RewardEvents!$B$2:$B$160,A10,Data_RewardEvents!$D$2:$D$160,"reward_reversed") -> 0 | U10: =COUNTIFS(Data_RewardEvents!$B$2:$B$160,A10,Data_RewardEvents!$D$2:$D$160,"reward_corrected") -> 0 | V10: =SUMIFS(Data_RewardEvents!$F$2:$F$160,Data_RewardEvents!$B$2:$B$160,A10,Data_RewardEvents!$D$2:$D$160,"reward_credited")+SUMIFS(Data_RewardEvents!$F$2:$F$160,Data_RewardEvents!$B$2:$B$160,A10,Data_RewardEvents!$D$2:$D$160,"reward_reversed")+SUMIFS(Data_RewardEvents!$F$2:$F$160,Data_RewardEvents!$B$2:$B$160,A10,Data_RewardEvents!$D$2:$D$160,"reward_corrected") -> 0 | W10: =IF(S10>0,_xlfn.MINIFS(Data_RewardEvents!$E$2:$E$160,Data_RewardEvents!$B$2:$B$160,A10,Data_RewardEvents!$D$2:$D$160,"reward_credited"),"") | X10: =IF(W10="","",(W10-J10)*24) | Y10: =IF(I10<>"",1,0) -> 0 | Z10: =IF(K10="completed",1,0) -> 0 | AA10: =IF(L10="validated",1,0) -> 0 | AB10: =IF(S10>0,1,0) -> 0
A11: T00010 | B11: in_app_action | C11: In-app tasks | D11: U0045 | E11: VELOOP | F11: first_party | H11: 46296.86 | I11: 46296.869 | J11: 46296.873 | K11: completed | L11: validated | M11: 10 | N11: =README!$B$14 -> points | O11: reward_credit_failed | P11: VELOOP | Q11: =IF(AND(I11<>"",J11<>""),(J11-I11)*1440,"") -> 4.8659754 | R11: =COUNTIFS(Data_RewardEvents!$B$2:$B$160,A11,Data_RewardEvents!$D$2:$D$160,"reward_pending") -> 0 | S11: =COUNTIFS(Data_RewardEvents!$B$2:$B$160,A11,Data_RewardEvents!$D$2:$D$160,"reward_credited") -> 0 | T11: =COUNTIFS(Data_RewardEvents!$B$2:$B$160,A11,Data_RewardEvents!$D$2:$D$160,"reward_reversed") -> 0 | U11: =COUNTIFS(Data_RewardEvents!$B$2:$B$160,A11,Data_RewardEvents!$D$2:$D$160,"reward_corrected") -> 0 | V11: =SUMIFS(Data_RewardEvents!$F$2:$F$160,Data_RewardEvents!$B$2:$B$160,A11,Data_RewardEvents!$D$2:$D$160,"reward_credited")+SUMIFS(Data_RewardEvents!$F$2:$F$160,Data_RewardEvents!$B$2:$B$160,A11,Data_RewardEvents!$D$2:$D$160,"reward_reversed")+SUMIFS(Data_RewardEvents!$F$2:$F$160,Data_RewardEvents!$B$2:$B$160,A11,Data_RewardEvents!$D$2:$D$160,"reward_corrected") -> 0 | W11: =IF(S11>0,_xlfn.MINIFS(Data_RewardEvents!$E$2:$E$160,Data_RewardEvents!$B$2:$B$160,A11,Data_RewardEvents!$D$2:$D$160,"reward_credited"),"") | X11: =IF(W11="","",(W11-J11)*24) | Y11: =IF(I11<>"",1,0) -> 1 | Z11: =IF(K11="completed",1,0) -> 1 | AA11: =IF(L11="validated",1,0) -> 1 | AB11: =IF(S11>0,1,0) -> 0
A12: T00011 | B12: video_view | C12: Advertisements | D12: U0005 | E12: AdNetwork_B | F12: third_party | G12: EXT-33990 | H12: 46298.244 | I12: 46298.245 | J12: 46298.246 | K12: completed | L12: validated | M12: 5 | N12: =README!$B$14 -> points | Q12: =IF(AND(I12<>"",J12<>""),(J12-I12)*1440,"") -> 1.0656455 | R12: =COUNTIFS(Data_RewardEvents!$B$2:$B$160,A12,Data_RewardEvents!$D$2:$D$160,"reward_pending") -> 0 | S12: =COUNTIFS(Data_RewardEvents!$B$2:$B$160,A12,Data_RewardEvents!$D$2:$D$160,"reward_credited") -> 1 | T12: =COUNTIFS(Data_RewardEvents!$B$2:$B$160,A12,Data_RewardEvents!$D$2:$D$160,"reward_reversed") -> 0 | U12: =COUNTIFS(Data_RewardEvents!$B$2:$B$160,A12,Data_RewardEvents!$D$2:$D$160,"reward_corrected") -> 0 | V12: =SUMIFS(Data_RewardEvents!$F$2:$F$160,Data_RewardEvents!$B$2:$B$160,A12,Data_RewardEvents!$D$2:$D$160,"reward_credited")+SUMIFS(Data_RewardEvents!$F$2:$F$160,Data_RewardEvents!$B$2:$B$160,A12,Data_RewardEvents!$D$2:$D$160,"reward_reversed")+SUMIFS(Data_RewardEvents!$F$2:$F$160,Data_RewardEvents!$B$2:$B$160,A12,Data_RewardEvents!$D$2:$D$160,"reward_corrected") -> 5 | W12: =IF(S12>0,_xlfn.MINIFS(Data_RewardEvents!$E$2:$E$160,Data_RewardEvents!$B$2:$B$160,A12,Data_RewardEvents!$D$2:$D$160,"reward_credited"),"") -> 46298.248 | X12: =IF(W12="","",(W12-J12)*24) -> 0.041248576 | Y12: =IF(I12<>"",1,0) -> 1 | Z12: =IF(K12="completed",1,0) -> 1 | AA12: =IF(L12="validated",1,0) -> 1 | AB12: =IF(S12>0,1,0) -> 1
A13: T00012 | B13: in_app_action | C13: In-app tasks | D13: U0005 | E13: VELOOP | F13: first_party | H13: 46285.467 | I13: 46285.488 | J13: 46285.488 | K13: completed | L13: validated | M13: 10 | N13: =README!$B$14 -> points | Q13: =IF(AND(I13<>"",J13<>""),(J13-I13)*1440,"") -> 1.0910502 | R13: =COUNTIFS(Data_RewardEvents!$B$2:$B$160,A13,Data_RewardEvents!$D$2:$D$160,"reward_pending") -> 0 | S13: =COUNTIFS(Data_RewardEvents!$B$2:$B$160,A13,Data_RewardEvents!$D$2:$D$160,"reward_credited") -> 1 | T13: =COUNTIFS(Data_RewardEvents!$B$2:$B$160,A13,Data_RewardEvents!$D$2:$D$160,"reward_reversed") -> 0 | U13: =COUNTIFS(Data_RewardEvents!$B$2:$B$160,A13,Data_RewardEvents!$D$2:$D$160,"reward_corrected") -> 0 | V13: =SUMIFS(Data_RewardEvents!$F$2:$F$160,Data_RewardEvents!$B$2:$B$160,A13,Data_RewardEvents!$D$2:$D$160,"reward_credited")+SUMIFS(Data_RewardEvents!$F$2:$F$160,Data_RewardEvents!$B$2:$B$160,A13,Data_RewardEvents!$D$2:$D$160,"reward_reversed")+SUMIFS(Data_RewardEvents!$F$2:$F$160,Data_RewardEvents!$B$2:$B$160,A13,Data_RewardEvents!$D$2:$D$160,"reward_corrected") -> 10 | W13: =IF(S13>0,_xlfn.MINIFS(Data_RewardEvents!$E$2:$E$160,Data_RewardEvents!$B$2:$B$160,A13,Data_RewardEvents!$D$2:$D$160,"reward_credited"),"") -> 46285.495 | X13: =IF(W13="","",(W13-J13)*24) -> 0.15722889 | Y13: =IF(I13<>"",1,0) -> 1 | Z13: =IF(K13="completed",1,0) -> 1 | AA13: =IF(L13="validated",1,0) -> 1 | AB13: =IF(S13>0,1,0) -> 1
A14: T00013 | B14: offer_install | C14: Offers | D14: U0004 | E14: Offerwall_B | F14: third_party | G14: EXT-24530 | H14: 46287.29 | K14: discovered | M14: 100 | N14: =README!$B$14 -> points | Q14: =IF(AND(I14<>"",J14<>""),(J14-I14)*1440,"") | R14: =COUNTIFS(Data_RewardEvents!$B$2:$B$160,A14,Data_RewardEvents!$D$2:$D$160,"reward_pending") -> 0 | S14: =COUNTIFS(Data_RewardEvents!$B$2:$B$160,A14,Data_RewardEvents!$D$2:$D$160,"reward_credited") -> 0 | T14: =COUNTIFS(Data_RewardEvents!$B$2:$B$160,A14,Data_RewardEvents!$D$2:$D$160,"reward_reversed") -> 0 | U14: =COUNTIFS(Data_RewardEvents!$B$2:$B$160,A14,Data_RewardEvents!$D$2:$D$160,"reward_corrected") -> 0 | V14: =SUMIFS(Data_RewardEvents!$F$2:$F$160,Data_RewardEvents!$B$2:$B$160,A14,Data_RewardEvents!$D$2:$D$160,"reward_credited")+SUMIFS(Data_RewardEvents!$F$2:$F$160,Data_RewardEvents!$B$2:$B$160,A14,Data_RewardEvents!$D$2:$D$160,"reward_reversed")+SUMIFS(Data_RewardEvents!$F$2:$F$160,Data_RewardEvents!$B$2:$B$160,A14,Data_RewardEvents!$D$2:$D$160,"reward_corrected") -> 0 | W14: =IF(S14>0,_xlfn.MINIFS(Data_RewardEvents!$E$2:$E$160,Data_RewardEvents!$B$2:$B$160,A14,Data_RewardEvents!$D$2:$D$160,"reward_credited"),"") | X14: =IF(W14="","",(W14-J14)*24) | Y14: =IF(I14<>"",1,0) -> 0 | Z14: =IF(K14="completed",1,0) -> 0 | AA14: =IF(L14="validated",1,0) -> 0 | AB14: =IF(S14>0,1,0) -> 0
A15: T00014 | B15: survey_complete | C15: Surveys | D15: U0030 | E15: SurveyProv_B | F15: third_party | G15: EXT-88090 | H15: 46288.31 | I15: 46288.319 | J15: 46288.331 | K15: completed | L15: validated | M15: 50 | N15: =README!$B$14 -> points | Q15: =IF(AND(I15<>"",J15<>""),(J15-I15)*1440,"") -> 17.105936 | R15: =COUNTIFS(Data_RewardEvents!$B$2:$B$160,A15,Data_RewardEvents!$D$2:$D$160,"reward_pending") -> 1 | S15: =COUNTIFS(Data_RewardEvents!$B$2:$B$160,A15,Data_RewardEvents!$D$2:$D$160,"reward_credited") -> 1 | T15: =COUNTIFS(Data_RewardEvents!$B$2:$B$160,A15,Data_RewardEvents!$D$2:$D$160,"reward_reversed") -> 0 | U15: =COUNTIFS(Data_RewardEvents!$B$2:$B$160,A15,Data_RewardEvents!$D$2:$D$160,"reward_corrected") -> 0 | V15: =SUMIFS(Data_RewardEvents!$F$2:$F$160,Data_RewardEvents!$B$2:$B$160,A15,Data_RewardEvents!$D$2:$D$160,"reward_credited")+SUMIFS(Data_RewardEvents!$F$2:$F$160,Data_RewardEvents!$B$2:$B$160,A15,Data_RewardEvents!$D$2:$D$160,"reward_reversed")+SUMIFS(Data_RewardEvents!$F$2:$F$160,Data_RewardEvents!$B$2:$B$160,A15,Data_RewardEvents!$D$2:$D$160,"reward_corrected") -> 50 | W15: =IF(S15>0,_xlfn.MINIFS(Data_RewardEvents!$E$2:$E$160,Data_RewardEvents!$B$2:$B$160,A15,Data_RewardEvents!$D$2:$D$160,"reward_credited"),"") -> 46290.306 | X15: =IF(W15="","",(W15-J15)*24) -> 47.388018 | Y15: =IF(I15<>"",1,0) -> 1 | Z15: =IF(K15="completed",1,0) -> 1 | AA15: =IF(L15="validated",1,0) -> 1 | AB15: =IF(S15>0,1,0) -> 1
A16: T00015 | B16: in_app_action | C16: In-app tasks | D16: U0004 | E16: VELOOP | F16: first_party | H16: 46288.273 | I16: 46288.281 | K16: abandoned | M16: 10 | N16: =README!$B$14 -> points | O16: user_abandoned | P16: user | Q16: =IF(AND(I16<>"",J16<>""),(J16-I16)*1440,"") | R16: =COUNTIFS(Data_RewardEvents!$B$2:$B$160,A16,Data_RewardEvents!$D$2:$D$160,"reward_pending") -> 0 | S16: =COUNTIFS(Data_RewardEvents!$B$2:$B$160,A16,Data_RewardEvents!$D$2:$D$160,"reward_credited") -> 0 | T16: =COUNTIFS(Data_RewardEvents!$B$2:$B$160,A16,Data_RewardEvents!$D$2:$D$160,"reward_reversed") -> 0 | U16: =COUNTIFS(Data_RewardEvents!$B$2:$B$160,A16,Data_RewardEvents!$D$2:$D$160,"reward_corrected") -> 0 | V16: =SUMIFS(Data_RewardEvents!$F$2:$F$160,Data_RewardEvents!$B$2:$B$160,A16,Data_RewardEvents!$D$2:$D$160,"reward_credited")+SUMIFS(Data_RewardEvents!$F$2:$F$160,Data_RewardEvents!$B$2:$B$160,A16,Data_RewardEvents!$D$2:$D$160,"reward_reversed")+SUMIFS(Data_RewardEvents!$F$2:$F$160,Data_RewardEvents!$B$2:$B$160,A16,Data_RewardEvents!$D$2:$D$160,"reward_corrected") -> 0 | W16: =IF(S16>0,_xlfn.MINIFS(Data_RewardEvents!$E$2:$E$160,Data_RewardEvents!$B$2:$B$160,A16,Data_RewardEvents!$D$2:$D$160,"reward_credited"),"") | X16: =IF(W16="","",(W16-J16)*24) | Y16: =IF(I16<>"",1,0) -> 1 | Z16: =IF(K16="completed",1,0) -> 0 | AA16: =IF(L16="validated",1,0) -> 0 | AB16: =IF(S16>0,1,0) -> 0
A17: T00016 | B17: survey_complete | C17: Surveys | D17: U0061 | E17: SurveyProv_B | F17: third_party | G17: EXT-96019 | H17: 46289.969 | I17: 46289.969 | J17: 46289.983 | K17: completed | L17: pending | M17: 50 | N17: =README!$B$14 -> points | Q17: =IF(AND(I17<>"",J17<>""),(J17-I17)*1440,"") -> 19.626038 | R17: =COUNTIFS(Data_RewardEvents!$B$2:$B$160,A17,Data_RewardEvents!$D$2:$D$160,"reward_pending") -> 1 | S17: =COUNTIFS(Data_RewardEvents!$B$2:$B$160,A17,Data_RewardEvents!$D$2:$D$160,"reward_credited") -> 0 | T17: =COUNTIFS(Data_RewardEvents!$B$2:$B$160,A17,Data_RewardEvents!$D$2:$D$160,"reward_reversed") -> 0 | U17: =COUNTIFS(Data_RewardEvents!$B$2:$B$160,A17,Data_RewardEvents!$D$2:$D$160,"reward_corrected") -> 0 | V17: =SUMIFS(Data_RewardEvents!$F$2:$F$160,Data_RewardEvents!$B$2:$B$160,A17,Data_RewardEvents!$D$2:$D$160,"reward_credited")+SUMIFS(Data_RewardEvents!$F$2:$F$160,Data_RewardEvents!$B$2:$B$160,A17,Data_RewardEvents!$D$2:$D$160,"reward_reversed")+SUMIFS(Data_RewardEvents!$F$2:$F$160,Data_RewardEvents!$B$2:$B$160,A17,Data_RewardEvents!$D$2:$D$160,"reward_corrected") -> 0 | W17: =IF(S17>0,_xlfn.MINIFS(Data_RewardEvents!$E$2:$E$160,Data_RewardEvents!$B$2:$B$160,A17,Data_RewardEvents!$D$2:$D$160,"reward_credited"),"") | X17: =IF(W17="","",(W17-J17)*24) | Y17: =IF(I17<>"",1,0) -> 1 | Z17: =IF(K17="completed",1,0) -> 1 | AA17: =IF(L17="validated",1,0) -> 0 | AB17: =IF(S17>0,1,0) -> 0
A18: T00017 | B18: video_view | C18: Advertisements | D18: U0013 | E18: AdNetwork_A | F18: third_party | G18: EXT-82787 | H18: 46288.248 | I18: 46288.249 | J18: 46288.25 | K18: completed | L18: validated | M18: 5 | N18: =README!$B$14 -> points | Q18: =IF(AND(I18<>"",J18<>""),(J18-I18)*1440,"") -> 1.1807031 | R18: =COUNTIFS(Data_RewardEvents!$B$2:$B$160,A18,Data_RewardEvents!$D$2:$D$160,"reward_pending") -> 0 | S18: =COUNTIFS(Data_RewardEvents!$B$2:$B$160,A18,Data_RewardEvents!$D$2:$D$160,"reward_credited") -> 1 | T18: =COUNTIFS(Data_RewardEvents!$B$2:$B$160,A18,Data_RewardEvents!$D$2:$D$160,"reward_reversed") -> 0 | U18: =COUNTIFS(Data_RewardEvents!$B$2:$B$160,A18,Data_RewardEvents!$D$2:$D$160,"reward_corrected") -> 0 | V18: =SUMIFS(Data_RewardEvents!$F$2:$F$160,Data_RewardEvents!$B$2:$B$160,A18,Data_RewardEvents!$D$2:$D$160,"reward_credited")+SUMIFS(Data_RewardEvents!$F$2:$F$160,Data_RewardEvents!$B$2:$B$160,A18,Data_RewardEvents!$D$2:$D$160,"reward_reversed")+SUMIFS(Data_RewardEvents!$F$2:$F$160,Data_RewardEvents!$B$2:$B$160,A18,Data_RewardEvents!$D$2:$D$160,"reward_corrected") -> 5 | W18: =IF(S18>0,_xlfn.MINIFS(Data_RewardEvents!$E$2:$E$160,Data_RewardEvents!$B$2:$B$160,A18,Data_RewardEvents!$D$2:$D$160,"reward_credited"),"") -> 46288.252 | X18: =IF(W18="","",(W18-J18)*24) -> 0.041278296 | Y18: =IF(I18<>"",1,0) -> 1 | Z18: =IF(K18="completed",1,0) -> 1 | AA18: =IF(L18="validated",1,0) -> 1 | AB18: =IF(S18>0,1,0) -> 1
A19: T00018 | B19: video_view | C19: Advertisements | D19: U0063 | E19: AdNetwork_B | F19: third_party | G19: EXT-25210 | H19: 46297.219 | I19: 46297.236 | J19: 46297.237 | K19: completed | L19: validated | M19: 5 | N19: =README!$B$14 -> points | Q19: =IF(AND(I19<>"",J19<>""),(J19-I19)*1440,"") -> 0.61743745 | R19: =COUNTIFS(Data_RewardEvents!$B$2:$B$160,A19,Data_RewardEvents!$D$2:$D$160,"reward_pending") -> 0 | S19: =COUNTIFS(Data_RewardEvents!$B$2:$B$160,A19,Data_RewardEvents!$D$2:$D$160,"reward_credited") -> 1 | T19: =COUNTIFS(Data_RewardEvents!$B$2:$B$160,A19,Data_RewardEvents!$D$2:$D$160,"reward_reversed") -> 0 | U19: =COUNTIFS(Data_RewardEvents!$B$2:$B$160,A19,Data_RewardEvents!$D$2:$D$160,"reward_corrected") -> 0 | V19: =SUMIFS(Data_RewardEvents!$F$2:$F$160,Data_RewardEvents!$B$2:$B$160,A19,Data_RewardEvents!$D$2:$D$160,"reward_credited")+SUMIFS(Data_RewardEvents!$F$2:$F$160,Data_RewardEvents!$B$2:$B$160,A19,Data_RewardEvents!$D$2:$D$160,"reward_reversed")+SUMIFS(Data_RewardEvents!$F$2:$F$160,Data_RewardEvents!$B$2:$B$160,A19,Data_RewardEvents!$D$2:$D$160,"reward_corrected") -> 5 | W19: =IF(S19>0,_xlfn.MINIFS(Data_RewardEvents!$E$2:$E$160,Data_RewardEvents!$B$2:$B$160,A19,Data_RewardEvents!$D$2:$D$160,"reward_credited"),"") -> 46297.239 | X19: =IF(W19="","",(W19-J19)*24) -> 0.055881369 | Y19: =IF(I19<>"",1,0) -> 1 | Z19: =IF(K19="completed",1,0) -> 1 | AA19: =IF(L19="validated",1,0) -> 1 | AB19: =IF(S19>0,1,0) -> 1
A20: T00019 | B20: offer_install | C20: Offers | D20: U0042 | E20: Offerwall_B | F20: third_party | G20: EXT-46081 | H20: 46290.826 | K20: discovered | M20: 100 | N20: =README!$B$14 -> points | Q20: =IF(AND(I20<>"",J20<>""),(J20-I20)*1440,"") | R20: =COUNTIFS(Data_RewardEvents!$B$2:$B$160,A20,Data_RewardEvents!$D$2:$D$160,"reward_pending") -> 0 | S20: =COUNTIFS(Data_RewardEvents!$B$2:$B$160,A20,Data_RewardEvents!$D$2:$D$160,"reward_credited") -> 0 | T20: =COUNTIFS(Data_RewardEvents!$B$2:$B$160,A20,Data_RewardEvents!$D$2:$D$160,"reward_reversed") -> 0 | U20: =COUNTIFS(Data_RewardEvents!$B$2:$B$160,A20,Data_RewardEvents!$D$2:$D$160,"reward_corrected") -> 0 | V20: =SUMIFS(Data_RewardEvents!$F$2:$F$160,Data_RewardEvents!$B$2:$B$160,A20,Data_RewardEvents!$D$2:$D$160,"reward_credited")+SUMIFS(Data_RewardEvents!$F$2:$F$160,Data_RewardEvents!$B$2:$B$160,A20,Data_RewardEvents!$D$2:$D$160,"reward_reversed")+SUMIFS(Data_RewardEvents!$F$2:$F$160,Data_RewardEvents!$B$2:$B$160,A20,Data_RewardEvents!$D$2:$D$160,"reward_corrected") -> 0 | W20: =IF(S20>0,_xlfn.MINIFS(Data_RewardEvents!$E$2:$E$160,Data_RewardEvents!$B$2:$B$160,A20,Data_RewardEvents!$D$2:$D$160,"reward_credited"),"") | X20: =IF(W20="","",(W20-J20)*24) | Y20: =IF(I20<>"",1,0) -> 0 | Z20: =IF(K20="completed",1,0) -> 0 | AA20: =IF(L20="validated",1,0) -> 0 | AB20: =IF(S20>0,1,0) -> 0
A21: T00020 | B21: survey_complete | C21: Surveys | D21: U0007 | E21: SurveyProv_B | F21: third_party | G21: EXT-44310 | H21: 46303.974 | I21: 46303.994 | K21: abandoned | M21: 50 | N21: =README!$B$14 -> points | O21: user_abandoned | P21: user | Q21: =IF(AND(I21<>"",J21<>""),(J21-I21)*1440,"") | R21: =COUNTIFS(Data_RewardEvents!$B$2:$B$160,A21,Data_RewardEvents!$D$2:$D$160,"reward_pending") -> 0 | S21: =COUNTIFS(Data_RewardEvents!$B$2:$B$160,A21,Data_RewardEvents!$D$2:$D$160,"reward_credited") -> 0 | T21: =COUNTIFS(Data_RewardEvents!$B$2:$B$160,A21,Data_RewardEvents!$D$2:$D$160,"reward_reversed") -> 0 | U21: =COUNTIFS(Data_RewardEvents!$B$2:$B$160,A21,Data_RewardEvents!$D$2:$D$160,"reward_corrected") -> 0 | V21: =SUMIFS(Data_RewardEvents!$F$2:$F$160,Data_RewardEvents!$B$2:$B$160,A21,Data_RewardEvents!$D$2:$D$160,"reward_credited")+SUMIFS(Data_RewardEvents!$F$2:$F$160,Data_RewardEvents!$B$2:$B$160,A21,Data_RewardEvents!$D$2:$D$160,"reward_reversed")+SUMIFS(Data_RewardEvents!$F$2:$F$160,Data_RewardEvents!$B$2:$B$160,A21,Data_RewardEvents!$D$2:$D$160,"reward_corrected") -> 0 | W21: =IF(S21>0,_xlfn.MINIFS(Data_RewardEvents!$E$2:$E$160,Data_RewardEvents!$B$2:$B$160,A21,Data_RewardEvents!$D$2:$D$160,"reward_credited"),"") | X21: =IF(W21="","",(W21-J21)*24) | Y21: =IF(I21<>"",1,0) -> 1 | Z21: =IF(K21="completed",1,0) -> 0 | AA21: =IF(L21="validated",1,0) -> 0 | AB21: =IF(S21>0,1,0) -> 0
A22: T00021 | B22: video_view | C22: Advertisements | D22: U0024 | E22: AdNetwork_B | F22: third_party | G22: EXT-48875 | H22: 46298.625 | I22: 46298.631 | J22: 46298.631 | K22: completed | L22: validated | M22: 5 | N22: =README!$B$14 -> points | Q22: =IF(AND(I22<>"",J22<>""),(J22-I22)*1440,"") -> 0.85292699 | R22: =COUNTIFS(Data_RewardEvents!$B$2:$B$160,A22,Data_RewardEvents!$D$2:$D$160,"reward_pending") -> 0 | S22: =COUNTIFS(Data_RewardEvents!$B$2:$B$160,A22,Data_RewardEvents!$D$2:$D$160,"reward_credited") -> 1 | T22: =COUNTIFS(Data_RewardEvents!$B$2:$B$160,A22,Data_RewardEvents!$D$2:$D$160,"reward_reversed") -> 0 | U22: =COUNTIFS(Data_RewardEvents!$B$2:$B$160,A22,Data_RewardEvents!$D$2:$D$160,"reward_corrected") -> 0 | V22: =SUMIFS(Data_RewardEvents!$F$2:$F$160,Data_RewardEvents!$B$2:$B$160,A22,Data_RewardEvents!$D$2:$D$160,"reward_credited")+SUMIFS(Data_RewardEvents!$F$2:$F$160,Data_RewardEvents!$B$2:$B$160,A22,Data_RewardEvents!$D$2:$D$160,"reward_reversed")+SUMIFS(Data_RewardEvents!$F$2:$F$160,Data_RewardEvents!$B$2:$B$160,A22,Data_RewardEvents!$D$2:$D$160,"reward_corrected") -> 5 | W22: =IF(S22>0,_xlfn.MINIFS(Data_RewardEvents!$E$2:$E$160,Data_RewardEvents!$B$2:$B$160,A22,Data_RewardEvents!$D$2:$D$160,"reward_credited"),"") -> 46298.636 | X22: =IF(W22="","",(W22-J22)*24) -> 0.10786847 | Y22: =IF(I22<>"",1,0) -> 1 | Z22: =IF(K22="completed",1,0) -> 1 | AA22: =IF(L22="validated",1,0) -> 1 | AB22: =IF(S22>0,1,0) -> 1
A23: T00022 | B23: video_view | C23: Advertisements | D23: U0013 | E23: AdNetwork_B | F23: third_party | G23: EXT-11746 | H23: 46303.916 | I23: 46303.928 | K23: abandoned | M23: 5 | N23: =README!$B$14 -> points | O23: user_abandoned | P23: user | Q23: =IF(AND(I23<>"",J23<>""),(J23-I23)*1440,"") | R23: =COUNTIFS(Data_RewardEvents!$B$2:$B$160,A23,Data_RewardEvents!$D$2:$D$160,"reward_pending") -> 0 | S23: =COUNTIFS(Data_RewardEvents!$B$2:$B$160,A23,Data_RewardEvents!$D$2:$D$160,"reward_credited") -> 0 | T23: =COUNTIFS(Data_RewardEvents!$B$2:$B$160,A23,Data_RewardEvents!$D$2:$D$160,"reward_reversed") -> 0 | U23: =COUNTIFS(Data_RewardEvents!$B$2:$B$160,A23,Data_RewardEvents!$D$2:$D$160,"reward_corrected") -> 0 | V23: =SUMIFS(Data_RewardEvents!$F$2:$F$160,Data_RewardEvents!$B$2:$B$160,A23,Data_RewardEvents!$D$2:$D$160,"reward_credited")+SUMIFS(Data_RewardEvents!$F$2:$F$160,Data_RewardEvents!$B$2:$B$160,A23,Data_RewardEvents!$D$2:$D$160,"reward_reversed")+SUMIFS(Data_RewardEvents!$F$2:$F$160,Data_RewardEvents!$B$2:$B$160,A23,Data_RewardEvents!$D$2:$D$160,"reward_corrected") -> 0 | W23: =IF(S23>0,_xlfn.MINIFS(Data_RewardEvents!$E$2:$E$160,Data_RewardEvents!$B$2:$B$160,A23,Data_RewardEvents!$D$2:$D$160,"reward_credited"),"") | X23: =IF(W23="","",(W23-J23)*24) | Y23: =IF(I23<>"",1,0) -> 1 | Z23: =IF(K23="completed",1,0) -> 0 | AA23: =IF(L23="validated",1,0) -> 0 | AB23: =IF(S23>0,1,0) -> 0
A24: T00023 | B24: video_view | C24: Advertisements | D24: U0010 | E24: AdNetwork_A | F24: third_party | G24: EXT-59664 | H24: 46288.064 | I24: 46288.08 | K24: abandoned | M24: 5 | N24: =README!$B$14 -> points | O24: user_abandoned | P24: user | Q24: =IF(AND(I24<>"",J24<>""),(J24-I24)*1440,"") | R24: =COUNTIFS(Data_RewardEvents!$B$2:$B$160,A24,Data_RewardEvents!$D$2:$D$160,"reward_pending") -> 0 | S24: =COUNTIFS(Data_RewardEvents!$B$2:$B$160,A24,Data_RewardEvents!$D$2:$D$160,"reward_credited") -> 0 | T24: =COUNTIFS(Data_RewardEvents!$B$2:$B$160,A24,Data_RewardEvents!$D$2:$D$160,"reward_reversed") -> 0 | U24: =COUNTIFS(Data_RewardEvents!$B$2:$B$160,A24,Data_RewardEvents!$D$2:$D$160,"reward_corrected") -> 0 | V24: =SUMIFS(Data_RewardEvents!$F$2:$F$160,Data_RewardEvents!$B$2:$B$160,A24,Data_RewardEvents!$D$2:$D$160,"reward_credited")+SUMIFS(Data_RewardEvents!$F$2:$F$160,Data_RewardEvents!$B$2:$B$160,A24,Data_RewardEvents!$D$2:$D$160,"reward_reversed")+SUMIFS(Data_RewardEvents!$F$2:$F$160,Data_RewardEvents!$B$2:$B$160,A24,Data_RewardEvents!$D$2:$D$160,"reward_corrected") -> 0 | W24: =IF(S24>0,_xlfn.MINIFS(Data_RewardEvents!$E$2:$E$160,Data_RewardEvents!$B$2:$B$160,A24,Data_RewardEvents!$D$2:$D$160,"reward_credited"),"") | X24: =IF(W24="","",(W24-J24)*24) | Y24: =IF(I24<>"",1,0) -> 1 | Z24: =IF(K24="completed",1,0) -> 0 | AA24: =IF(L24="validated",1,0) -> 0 | AB24: =IF(S24>0,1,0) -> 0
A25: T00024 | B25: game_milestone | C25: Games | D25: U0016 | E25: GamePartner_B | F25: third_party | G25: EXT-61879 | H25: 46296.008 | I25: 46296.025 | J25: 46296.043 | K25: completed | L25: validated | M25: 30 | N25: =README!$B$14 -> points | Q25: =IF(AND(I25<>"",J25<>""),(J25-I25)*1440,"") -> 25.206708 | R25: =COUNTIFS(Data_RewardEvents!$B$2:$B$160,A25,Data_RewardEvents!$D$2:$D$160,"reward_pending") -> 1 | S25: =COUNTIFS(Data_RewardEvents!$B$2:$B$160,A25,Data_RewardEvents!$D$2:$D$160,"reward_credited") -> 1 | T25: =COUNTIFS(Data_RewardEvents!$B$2:$B$160,A25,Data_RewardEvents!$D$2:$D$160,"reward_reversed") -> 0 | U25: =COUNTIFS(Data_RewardEvents!$B$2:$B$160,A25,Data_RewardEvents!$D$2:$D$160,"reward_corrected") -> 0 | V25: =SUMIFS(Data_RewardEvents!$F$2:$F$160,Data_RewardEvents!$B$2:$B$160,A25,Data_RewardEvents!$D$2:$D$160,"reward_credited")+SUMIFS(Data_RewardEvents!$F$2:$F$160,Data_RewardEvents!$B$2:$B$160,A25,Data_RewardEvents!$D$2:$D$160,"reward_reversed")+SUMIFS(Data_RewardEvents!$F$2:$F$160,Data_RewardEvents!$B$2:$B$160,A25,Data_RewardEvents!$D$2:$D$160,"reward_corrected") -> 30 | W25: =IF(S25>0,_xlfn.MINIFS(Data_RewardEvents!$E$2:$E$160,Data_RewardEvents!$B$2:$B$160,A25,Data_RewardEvents!$D$2:$D$160,"reward_credited"),"") -> 46296.857 | X25: =IF(W25="","",(W25-J25)*24) -> 19.547657 | Y25: =IF(I25<>"",1,0) -> 1 | Z25: =IF(K25="completed",1,0) -> 1 | AA25: =IF(L25="validated",1,0) -> 1 | AB25: =IF(S25>0,1,0) -> 1
A26: T00025 | B26: in_app_action | C26: In-app tasks | D26: U0048 | E26: VELOOP | F26: first_party | H26: 46303.679 | I26: 46303.685 | K26: failed | M26: 10 | N26: =README!$B$14 -> points | O26: task_failed | P26: user | Q26: =IF(AND(I26<>"",J26<>""),(J26-I26)*1440,"") | R26: =COUNTIFS(Data_RewardEvents!$B$2:$B$160,A26,Data_RewardEvents!$D$2:$D$160,"reward_pending") -> 0 | S26: =COUNTIFS(Data_RewardEvents!$B$2:$B$160,A26,Data_RewardEvents!$D$2:$D$160,"reward_credited") -> 0 | T26: =COUNTIFS(Data_RewardEvents!$B$2:$B$160,A26,Data_RewardEvents!$D$2:$D$160,"reward_reversed") -> 0 | U26: =COUNTIFS(Data_RewardEvents!$B$2:$B$160,A26,Data_RewardEvents!$D$2:$D$160,"reward_corrected") -> 0 | V26: =SUMIFS(Data_RewardEvents!$F$2:$F$160,Data_RewardEvents!$B$2:$B$160,A26,Data_RewardEvents!$D$2:$D$160,"reward_credited")+SUMIFS(Data_RewardEvents!$F$2:$F$160,Data_RewardEvents!$B$2:$B$160,A26,Data_RewardEvents!$D$2:$D$160,"reward_reversed")+SUMIFS(Data_RewardEvents!$F$2:$F$160,Data_RewardEvents!$B$2:$B$160,A26,Data_RewardEvents!$D$2:$D$160,"reward_corrected") -> 0 | W26: =IF(S26>0,_xlfn.MINIFS(Data_RewardEvents!$E$2:$E$160,Data_RewardEvents!$B$2:$B$160,A26,Data_RewardEvents!$D$2:$D$160,"reward_credited"),"") | X26: =IF(W26="","",(W26-J26)*24) | Y26: =IF(I26<>"",1,0) -> 1 | Z26: =IF(K26="completed",1,0) -> 0 | AA26: =IF(L26="validated",1,0) -> 0 | AB26: =IF(S26>0,1,0) -> 0
A27: T00026 | B27: video_view | C27: Advertisements | D27: U0045 | E27: AdNetwork_A | F27: third_party | G27: EXT-75197 | H27: 46288.101 | K27: discovered | M27: 5 | N27: =README!$B$14 -> points | Q27: =IF(AND(I27<>"",J27<>""),(J27-I27)*1440,"") | R27: =COUNTIFS(Data_RewardEvents!$B$2:$B$160,A27,Data_RewardEvents!$D$2:$D$160,"reward_pending") -> 0 | S27: =COUNTIFS(Data_RewardEvents!$B$2:$B$160,A27,Data_RewardEvents!$D$2:$D$160,"reward_credited") -> 0 | T27: =COUNTIFS(Data_RewardEvents!$B$2:$B$160,A27,Data_RewardEvents!$D$2:$D$160,"reward_reversed") -> 0 | U27: =COUNTIFS(Data_RewardEvents!$B$2:$B$160,A27,Data_RewardEvents!$D$2:$D$160,"reward_corrected") -> 0 | V27: =SUMIFS(Data_RewardEvents!$F$2:$F$160,Data_RewardEvents!$B$2:$B$160,A27,Data_RewardEvents!$D$2:$D$160,"reward_credited")+SUMIFS(Data_RewardEvents!$F$2:$F$160,Data_RewardEvents!$B$2:$B$160,A27,Data_RewardEvents!$D$2:$D$160,"reward_reversed")+SUMIFS(Data_RewardEvents!$F$2:$F$160,Data_RewardEvents!$B$2:$B$160,A27,Data_RewardEvents!$D$2:$D$160,"reward_corrected") -> 0 | W27: =IF(S27>0,_xlfn.MINIFS(Data_RewardEvents!$E$2:$E$160,Data_RewardEvents!$B$2:$B$160,A27,Data_RewardEvents!$D$2:$D$160,"reward_credited"),"") | X27: =IF(W27="","",(W27-J27)*24) | Y27: =IF(I27<>"",1,0) -> 0 | Z27: =IF(K27="completed",1,0) -> 0 | AA27: =IF(L27="validated",1,0) -> 0 | AB27: =IF(S27>0,1,0) -> 0
A28: T00027 | B28: offer_install | C28: Offers | D28: U0014 | E28: Offerwall_B | F28: third_party | G28: EXT-73235 | H28: 46295.171 | I28: 46295.187 | J28: 46295.499 | K28: completed | L28: validated | M28: 100 | N28: =README!$B$14 -> points | Q28: =IF(AND(I28<>"",J28<>""),(J28-I28)*1440,"") -> 449.77694 | R28: =COUNTIFS(Data_RewardEvents!$B$2:$B$160,A28,Data_RewardEvents!$D$2:$D$160,"reward_pending") -> 1 | S28: =COUNTIFS(Data_RewardEvents!$B$2:$B$160,A28,Data_RewardEvents!$D$2:$D$160,"reward_credited") -> 1 | T28: =COUNTIFS(Data_RewardEvents!$B$2:$B$160,A28,Data_RewardEvents!$D$2:$D$160,"reward_reversed") -> 0 | U28: =COUNTIFS(Data_RewardEvents!$B$2:$B$160,A28,Data_RewardEvents!$D$2:$D$160,"reward_corrected") -> 0 | V28: =SUMIFS(Data_RewardEvents!$F$2:$F$160,Data_RewardEvents!$B$2:$B$160,A28,Data_RewardEvents!$D$2:$D$160,"reward_credited")+SUMIFS(Data_RewardEvents!$F$2:$F$160,Data_RewardEvents!$B$2:$B$160,A28,Data_RewardEvents!$D$2:$D$160,"reward_reversed")+SUMIFS(Data_RewardEvents!$F$2:$F$160,Data_RewardEvents!$B$2:$B$160,A28,Data_RewardEvents!$D$2:$D$160,"reward_corrected") -> 100 | W28: =IF(S28>0,_xlfn.MINIFS(Data_RewardEvents!$E$2:$E$160,Data_RewardEvents!$B$2:$B$160,A28,Data_RewardEvents!$D$2:$D$160,"reward_credited"),"") -> 46296.359 | X28: =IF(W28="","",(W28-J28)*24) -> 20.626474 | Y28: =IF(I28<>"",1,0) -> 1 | Z28: =IF(K28="completed",1,0) -> 1 | AA28: =IF(L28="validated",1,0) -> 1 | AB28: =IF(S28>0,1,0) -> 1
A29: T00028 | B29: offer_install | C29: Offers | D29: U0005 | E29: Offerwall_A | F29: third_party | G29: EXT-45347 | H29: 46287.414 | K29: discovered | M29: 100 | N29: =README!$B$14 -> points | Q29: =IF(AND(I29<>"",J29<>""),(J29-I29)*1440,"") | R29: =COUNTIFS(Data_RewardEvents!$B$2:$B$160,A29,Data_RewardEvents!$D$2:$D$160,"reward_pending") -> 0 | S29: =COUNTIFS(Data_RewardEvents!$B$2:$B$160,A29,Data_RewardEvents!$D$2:$D$160,"reward_credited") -> 0 | T29: =COUNTIFS(Data_RewardEvents!$B$2:$B$160,A29,Data_RewardEvents!$D$2:$D$160,"reward_reversed") -> 0 | U29: =COUNTIFS(Data_RewardEvents!$B$2:$B$160,A29,Data_RewardEvents!$D$2:$D$160,"reward_corrected") -> 0 | V29: =SUMIFS(Data_RewardEvents!$F$2:$F$160,Data_RewardEvents!$B$2:$B$160,A29,Data_RewardEvents!$D$2:$D$160,"reward_credited")+SUMIFS(Data_RewardEvents!$F$2:$F$160,Data_RewardEvents!$B$2:$B$160,A29,Data_RewardEvents!$D$2:$D$160,"reward_reversed")+SUMIFS(Data_RewardEvents!$F$2:$F$160,Data_RewardEvents!$B$2:$B$160,A29,Data_RewardEvents!$D$2:$D$160,"reward_corrected") -> 0 | W29: =IF(S29>0,_xlfn.MINIFS(Data_RewardEvents!$E$2:$E$160,Data_RewardEvents!$B$2:$B$160,A29,Data_RewardEvents!$D$2:$D$160,"reward_credited"),"") | X29: =IF(W29="","",(W29-J29)*24) | Y29: =IF(I29<>"",1,0) -> 0 | Z29: =IF(K29="completed",1,0) -> 0 | AA29: =IF(L29="validated",1,0) -> 0 | AB29: =IF(S29>0,1,0) -> 0
A30: T00029 | B30: game_milestone | C30: Games | D30: U0016 | E30: GamePartner_B | F30: third_party | G30: EXT-56204 | H30: 46289.037 | I30: 46289.047 | J30: 46289.078 | K30: completed | L30: validated | M30: 30 | N30: =README!$B$14 -> points | Q30: =IF(AND(I30<>"",J30<>""),(J30-I30)*1440,"") -> 43.83968 | R30: =COUNTIFS(Data_RewardEvents!$B$2:$B$160,A30,Data_RewardEvents!$D$2:$D$160,"reward_pending") -> 1 | S30: =COUNTIFS(Data_RewardEvents!$B$2:$B$160,A30,Data_RewardEvents!$D$2:$D$160,"reward_credited") -> 1 | T30: =COUNTIFS(Data_RewardEvents!$B$2:$B$160,A30,Data_RewardEvents!$D$2:$D$160,"reward_reversed") -> 0 | U30: =COUNTIFS(Data_RewardEvents!$B$2:$B$160,A30,Data_RewardEvents!$D$2:$D$160,"reward_corrected") -> 0 | V30: =SUMIFS(Data_RewardEvents!$F$2:$F$160,Data_RewardEvents!$B$2:$B$160,A30,Data_RewardEvents!$D$2:$D$160,"reward_credited")+SUMIFS(Data_RewardEvents!$F$2:$F$160,Data_RewardEvents!$B$2:$B$160,A30,Data_RewardEvents!$D$2:$D$160,"reward_reversed")+SUMIFS(Data_RewardEvents!$F$2:$F$160,Data_RewardEvents!$B$2:$B$160,A30,Data_RewardEvents!$D$2:$D$160,"reward_corrected") -> 30 | W30: =IF(S30>0,_xlfn.MINIFS(Data_RewardEvents!$E$2:$E$160,Data_RewardEvents!$B$2:$B$160,A30,Data_RewardEvents!$D$2:$D$160,"reward_credited"),"") -> 46289.417 | X30: =IF(W30="","",(W30-J30)*24) -> 8.13724 | Y30: =IF(I30<>"",1,0) -> 1 | Z30: =IF(K30="completed",1,0) -> 1 | AA30: =IF(L30="validated",1,0) -> 1 | AB30: =IF(S30>0,1,0) -> 1
