Workbook

Sheet README
A1: Veloop Production Event Tracking Plan - Work Package F
A2: Purpose: a catalogue engineering can review, build and test. Every event lists its trigger, definition, required and optional properties, validation, source, business purpose and the KPIs that depend on it.
A3: ASSUMPTION: Veloop is a tasks-and-rewards app with wallet and withdrawals. Product specifics (task types, reward units, payout methods, activation and conversion rules) are PROPOSED and must be confirmed with product and engineering.
A5: Sheets
A6: Event Catalogue - the main deliverable, one row per event (see columns below).
A7: Naming Standard - the convention (object_action, snake_case, past tense), rules and the reasoning.
A8: Common Properties - fields every event must carry (event_id, user_id, event_timestamp, etc.).
A9: Property Dictionary - every event property with type, definition and allowed values; usage counts are formulas.
A10: KPI Map - each KPI and how many events it depends on (formula).
A11: Coverage Check - verifies every minimum-list event is in the catalogue and that names follow the standard.
A13: How this plan was made
A14: 1. List the business questions and KPIs first (KPI Map).
... A25: Conditional events (daily reward, streak, mission, badge, spin, KYC, reward expiry) exist only if the product has that feature. Delete rows for features that do not exist.

Sheet Event Catalogue
A1: Cat # | B1: Feature | C1: Event Name | D1: Coverage Type | E1: Trigger | F1: Definition | G1: User ID | H1: Event ID | I1: Timestamp | J1: Status | K1: Required Properties | L1: Optional Properties | M1: Data Type | N1: Validation | O1: Source | P1: Business Purpose | Q1: KPI Dependency | R1: Implementation Status | S1: Naming Check
A2: E001 | B2: Account | C2: user_registered | D2: Minimum list | E2: Server confirms a new account was created and verified. | F2: A new user account exists. | G2: user_id (string) - required, newly created ID | H2: event_id (UUID v4) - required, generated at source | I2: event_timestamp (UTC ISO 8601) - required; received_at added by pipeline | J2: Proposed | K2: signup_method | L2: referral_code, signup_entry_point | M2: signup_method:enum; referral_code:string; signup_entry_point:string | N2: Fires exactly once per user_id; signup_method in list; referral_code valid if present. | O2: Backend (auth service) | P2: Measures acquisition and seeds every cohort. | Q2: K01 New registrations; K02 Activation rate; K05 Retention; K11 Referral conversion | R2: Not started | S2: =IF(AND(EXACT(C2,LOWER(C2)),LEN(C2)<=40,ISERROR(FIND(" ",C2)),ISERROR(FIND("-",C2))),"OK","CHECK") -> OK
A3: E002 | B3: Account | C3: user_logged_in | D3: Minimum list | E3: Server accepts credentials and starts a session. | F3: A user authenticated successfully. | G3: user_id (string) - required | H3: event_id (UUID v4) - required, generated at source | I3: event_timestamp (UTC ISO 8601) - required; received_at added by pipeline | J3: Proposed | K3: login_method | L3: is_first_login, device_changed | M3: login_method:enum; is_first_login:boolean; device_changed:boolean | N3: user_id must exist; login_method in list; one event per new session. | O3: Backend (auth service) | P3: Counts active users and return frequency. | Q3: K04 DAU/WAU/MAU; K05 Retention | R3: Not started | S3: =IF(AND(EXACT(C3,LOWER(C3)),LEN(C3)<=40,ISERROR(FIND(" ",C3)),ISERROR(FIND("-",C3))),"OK","CHECK") -> OK
A4: E003 | B4: Account | C4: user_logged_out | D4: Minimum list | E4: User taps log out, or system ends session by force. | F4: A session ended deliberately or by security action. | G4: user_id (string) - required | H4: event_id (UUID v4) - required, generated at source | I4: event_timestamp (UTC ISO 8601) - required; received_at added by pipeline | J4: Proposed - low priority | K4: logout_reason | M4: logout_reason:enum | N4: Do NOT fire for silent token expiry or app close; logout_reason in list. | O4: Client (app) + Backend | P4: Diagnoses forced logouts and security resets; low priority. | Q4: K04 DAU/WAU/MAU | R4: Not started | S4: =IF(AND(EXACT(C4,LOWER(C4)),LEN(C4)<=40,ISERROR(FIND(" ",C4)),ISERROR(FIND("-",C4))),"OK","CHECK") -> OK
A5: E004 | B5: Account | C5: app_opened | D5: Analyst-added | E5: App enters foreground (cold or warm start). | F5: User opened the app. | G5: user_id (string) - nullable if logged out; anonymous_id required then | H5: event_id (UUID v4) - required, generated at source | I5: event_timestamp (UTC ISO 8601) - required; received_at added by pipeline | J5: Proposed | L5: open_source | M5: open_source:enum | N5: At most once per foreground transition; user_id null allowed (use anonymous_id). | O5: Client (app) | P5: Top of funnel for engagement; links push campaigns to opens. | Q5: K04 DAU/WAU/MAU; K05 Retention | R5: Not started | S5: =IF(AND(EXACT(C5,LOWER(C5)),LEN(C5)<=40,ISERROR(FIND(" ",C5)),ISERROR(FIND("-",C5))),"OK","CHECK") -> OK
A6: E005 | B6: Account | C6: onboarding_started | D6: Minimum list | E6: First onboarding screen is shown after registration. | F6: User began the onboarding flow. | G6: user_id (string) - required | H6: event_id (UUID v4) - required, generated at source | I6: event_timestamp (UTC ISO 8601) - required; received_at added by pipeline | J6: Proposed | K6: onboarding_flow_version, onboarding_total_steps | L6: signup_entry_point | M6: onboarding_flow_version:string; onboarding_total_steps:integer; signup_entry_point:string | N6: Once per user per flow version; must follow user_registered. | O6: Client (app) | P6: Start of onboarding funnel. | Q6: K03 Onboarding completion; K02 Activation rate | R6: Not started | S6: =IF(AND(EXACT(C6,LOWER(C6)),LEN(C6)<=40,ISERROR(FIND(" ",C6)),ISERROR(FIND("-",C6))),"OK","CHECK") -> OK
A7: E006 | B7: Account | C7: onboarding_step_completed | D7: Analyst-added | E7: User completes one step of onboarding. | F7: One onboarding step finished. | G7: user_id (string) - required | H7: event_id (UUID v4) - required, generated at source | I7: event_timestamp (UTC ISO 8601) - required; received_at added by pipeline | J7: Proposed | K7: onboarding_step_id, onboarding_step_index | L7: step_duration_sec | M7: onboarding_step_id:string; onboarding_step_index:integer; step_duration_sec:integer | N7: Index between 1 and onboarding_total_steps; ordered by index. | O7: Client (app) | P7: Finds drop-off step inside onboarding. | Q7: K03 Onboarding completion | R7: Not started | S7: =IF(AND(EXACT(C7,LOWER(C7)),LEN(C7)<=40,ISERROR(FIND(" ",C7)),ISERROR(FIND("-",C7))),"OK","CHECK") -> OK
A8: E007 | B8: Account | C8: onboarding_completed | D8: Minimum list | E8: User finishes last required onboarding step. | F8: User completed onboarding. | G8: user_id (string) - required | H8: event_id (UUID v4) - required, generated at source | I8: event_timestamp (UTC ISO 8601) - required; received_at added by pipeline | J8: Proposed | K8: onboarding_flow_version, onboarding_duration_sec | L8: skipped_steps_count | M8: onboarding_flow_version:string; onboarding_duration_sec:integer; skipped_steps_count:integer | N8: Once per user; requires prior onboarding_started; duration >= 0. | O8: Client (app) | P8: End of onboarding funnel; activation prerequisite. | Q8: K03 Onboarding completion; K02 Activation rate | R8: Not started | S8: =IF(AND(EXACT(C8,LOWER(C8)),LEN(C8)<=40,ISERROR(FIND(" ",C8)),ISERROR(FIND("-",C8))),"OK","CHECK") -> OK
A9: E008 | B9: Account | C9: kyc_submitted | D9: Analyst-added | E9: User submits identity documents or details. | F9: Identity verification was submitted. | G9: user_id (string) - required | H9: event_id (UUID v4) - required, generated at source | I9: event_timestamp (UTC ISO 8601) - required; received_at added by pipeline | J9: Proposed - confirm feature exists | K9: kyc_request_id, kyc_level | M9: kyc_request_id:string; kyc_level:enum | N9: Unique kyc_request_id; no raw personal data in properties. | O9: Client (app) + Backend | P9: Tracks verification funnel that gates withdrawals. | Q9: K13 Withdrawal success rate; K14 Time to payout | R9: Not started | S9: =IF(AND(EXACT(C9,LOWER(C9)),LEN(C9)<=40,ISERROR(FIND(" ",C9)),ISERROR(FIND("-",C9))),"OK","CHECK") -> OK
A10: E009 | B10: Account | C10: kyc_completed | D10: Analyst-added | E10: Verification provider returns a final result. | F10: Identity verification reached a final state. | G10: user_id (string) - required | H10: event_id (UUID v4) - required, generated at source | I10: event_timestamp (UTC ISO 8601) - required; received_at added by pipeline | J10: Proposed - confirm feature exists | K10: kyc_request_id, kyc_result | L10: kyc_level | M10: kyc_request_id:string; kyc_result:enum; kyc_level:enum | N10: Matches an earlier kyc_submitted; result in list. | O10: Backend (verification provider webhook) | P10: Explains withdrawal rejections and delays. | Q10: K13 Withdrawal success rate; K15 Withdrawal rejection rate | R10: Not started | S10: =IF(AND(EXACT(C10,LOWER(C10)),LEN(C10)<=40,ISERROR(FIND(" ",C10)),ISERROR(FIND("-",C10))),"OK","CHECK") -> OK
A11: E010 | B11: Tasks | C11: task_viewed | D11: Minimum list | E11: Task card is visible on screen for at least 1 second. | F11: A task was shown to the user (impression). | G11: user_id (string) - required | H11: event_id (UUID v4) - required, generated at source | I11: event_timestamp (UTC ISO 8601) - required; received_at added by pipeline | J11: Proposed | K11: task_id, task_type, list_position | L11: task_provider, task_payout_amount, view_source | M11: task_id:string; task_type:enum; list_position:integer; task_provider:string; task_payout_amount:decimal; view_source:enum | N11: list_position >= 1; dedupe per task per list render; consider sampling if volume is high. | O11: Client (app) | P11: Impression denominator for task conversion. | Q11: K06 Task completion rate | R11: Not started | S11: =IF(AND(EXACT(C11,LOWER(C11)),LEN(C11)<=40,ISERROR(FIND(" ",C11)),ISERROR(FIND("-",C11))),"OK","CHECK") -> OK
A12: E011 | B12: Tasks | C12: task_opened | D12: Minimum list | E12: User taps a task to see its detail. | F12: User opened a task. | G12: user_id (string) - required | H12: event_id (UUID v4) - required, generated at source | I12: event_timestamp (UTC ISO 8601) - required; received_at added by pipeline | J12: Proposed | K12: task_id, task_type | L12: list_position, view_source, task_provider | M12: task_id:string; task_type:enum; list_position:integer; view_source:enum; task_provider:string | N12: Must follow a task_viewed for same task in session (except deep links). | O12: Client (app) | P12: Measures interest and view-to-open rate. | Q12: K06 Task completion rate | R12: Not started | S12: =IF(AND(EXACT(C12,LOWER(C12)),LEN(C12)<=40,ISERROR(FIND(" ",C12)),ISERROR(FIND("-",C12))),"OK","CHECK") -> OK
A13: E012 | B13: Tasks | C13: task_started | D13: Minimum list | E13: User begins the task (taps start / is sent to partner). | F13: A task attempt began. | G13: user_id (string) - required | H13: event_id (UUID v4) - required, generated at source | I13: event_timestamp (UTC ISO 8601) - required; received_at added by pipeline | J13: Proposed | K13: task_id, task_attempt_id, task_type | L13: task_provider | M13: task_id:string; task_attempt_id:string; task_type:enum; task_provider:string | N13: task_attempt_id unique; one active attempt per task per user. | O13: Backend (task service) | P13: Start of attempt; denominator for completion and failure. | Q13: K06 Task completion rate; K07 Task failure rate | R13: Not started | S13: =IF(AND(EXACT(C13,LOWER(C13)),LEN(C13)<=40,ISERROR(FIND(" ",C13)),ISERROR(FIND("-",C13))),"OK","CHECK") -> OK
A14: E013 | B14: Tasks | C14: task_completed | D14: Minimum list | E14: Server verifies the task was completed. | F14: A task attempt was completed and verified. | G14: user_id (string) - required | H14: event_id (UUID v4) - required, generated at source | I14: event_timestamp (UTC ISO 8601) - required; received_at added by pipeline | J14: Proposed | K14: task_id, task_attempt_id, task_type, completion_duration_sec | L14: task_provider, completion_source | M14: task_id:string; task_attempt_id:string; task_type:enum; completion_duration_sec:integer; task_provider:string; completion_source:enum | N14: Matches a task_started with same attempt id; at most one completion per attempt. | O14: Backend (task service / partner postback) | P14: Core engagement and earning action. | Q14: K06 Task completion rate; K02 Activation rate; K08 Reward cost | R14: Not started | S14: =IF(AND(EXACT(C14,LOWER(C14)),LEN(C14)<=40,ISERROR(FIND(" ",C14)),ISERROR(FIND("-",C14))),"OK","CHECK") -> OK
A15: E014 | B15: Tasks | C15: task_failed | D15: Minimum list | E15: Attempt ends unsuccessfully (timeout, rejection, error). | F15: A task attempt did not succeed. | G15: user_id (string) - required | H15: event_id (UUID v4) - required, generated at source | I15: event_timestamp (UTC ISO 8601) - required; received_at added by pipeline | J15: Proposed | K15: task_id, task_attempt_id, failure_reason | L15: failure_stage, task_provider | M15: task_id:string; task_attempt_id:string; failure_reason:enum; failure_stage:enum; task_provider:string | N15: Matches a task_started; mutually exclusive with task_completed for the same attempt. | O15: Backend (task service / partner postback) | P15: Finds broken tasks, partners and fraud patterns. | Q15: K07 Task failure rate; K16 Fraud rate | R15: Not started | S15: =IF(AND(EXACT(C15,LOWER(C15)),LEN(C15)<=40,ISERROR(FIND(" ",C15)),ISERROR(FIND("-",C15))),"OK","CHECK") -> OK
A16: E015 | B16: Rewards | C16: reward_credited | D16: Minimum list | E16: Reward amount is posted to the user's available balance. | F16: A reward became spendable/withdrawable. | G16: user_id (string) - required | H16: event_id (UUID v4) - required, generated at source | I16: event_timestamp (UTC ISO 8601) - required; received_at added by pipeline | J16: Proposed | K16: reward_id, reward_amount, reward_unit, reward_source | L16: source_entity_id, wallet_ledger_entry_id | M16: reward_id:string; reward_amount:decimal; reward_unit:enum; reward_source:enum; source_entity_id:string; wallet_ledger_entry_id:string | N16: reward_amount > 0; reward_id unique; must reconcile to a wallet_transaction_completed. | O16: Backend (rewards service) | P16: Measures reward cost and user earnings. | Q16: K08 Reward cost; K09 Reward liability; K18 Ledger reconciliation | R16: Not started | S16: =IF(AND(EXACT(C16,LOWER(C16)),LEN(C16)<=40,ISERROR(FIND(" ",C16)),ISERROR(FIND("-",C16))),"OK","CHECK") -> OK
A17: E016 | B17: Rewards | C17: reward_pending | D17: Minimum list | E17: Reward is earned but held for validation. | F17: A reward is earned but not yet available. | G17: user_id (string) - required | H17: event_id (UUID v4) - required, generated at source | I17: event_timestamp (UTC ISO 8601) - required; received_at added by pipeline | J17: Proposed | K17: reward_id, reward_amount, reward_unit, reward_source, pending_reason | L17: source_entity_id, expected_release_at | M17: reward_id:string; reward_amount:decimal; reward_unit:enum; reward_source:enum; pending_reason:enum; source_entity_id:string; expected_release_at:timestamp | N17: expected_release_at in the future; later followed by reward_credited or reward_reversed. | O17: Backend (rewards service) | P17: Sizes pending liability and hold times. | Q17: K09 Reward liability; K10 Reward reversal rate | R17: Not started | S17: =IF(AND(EXACT(C17,LOWER(C17)),LEN(C17)<=40,ISERROR(FIND(" ",C17)),ISERROR(FIND("-",C17))),"OK","CHECK") -> OK
A18: E017 | B18: Rewards | C18: reward_reversed | D18: Minimum list | E18: A pending or credited reward is cancelled and clawed back. | F18: A reward was taken back. | G18: user_id (string) - required | H18: event_id (UUID v4) - required, generated at source | I18: event_timestamp (UTC ISO 8601) - required; received_at added by pipeline | J18: Proposed | K18: reward_id, reward_amount, reward_unit, reversal_reason | L18: original_reward_status, wallet_ledger_entry_id | M18: reward_id:string; reward_amount:decimal; reward_unit:enum; reversal_reason:enum; original_reward_status:enum; wallet_ledger_entry_id:string | N18: reward_id must exist; reason in list; amount <= original. | O18: Backend (rewards service) | P18: Tracks fraud, chargebacks and overpayment. | Q18: K10 Reward reversal rate; K16 Fraud rate; K09 Reward liability | R18: Not started | S18: =IF(AND(EXACT(C18,LOWER(C18)),LEN(C18)<=40,ISERROR(FIND(" ",C18)),ISERROR(FIND("-",C18))),"OK","CHECK") -> OK
A19: E018 | B19: Rewards | C19: reward_expired | D19: Analyst-added | E19: Unclaimed or unused reward passes its expiry. | F19: A reward expired unused. | G19: user_id (string) - required | H19: event_id (UUID v4) - required, generated at source | I19: event_timestamp (UTC ISO 8601) - required; received_at added by pipeline | J19: Proposed - only if rewards expire | K19: reward_id, reward_amount, reward_unit, expiry_at | M19: reward_id:string; reward_amount:decimal; reward_unit:enum; expiry_at:timestamp | N19: Only if rewards expire; expiry_at <= event time. | O19: Backend (rewards service) | P19: Reduces liability; signals poor reward UX. | Q19: K09 Reward liability | R19: Not started | S19: =IF(AND(EXACT(C19,LOWER(C19)),LEN(C19)<=40,ISERROR(FIND(" ",C19)),ISERROR(FIND("-",C19))),"OK","CHECK") -> OK
A20: E019 | B20: Engagement | C20: daily_reward_claimed | D20: Minimum list (conditional) | E20: User claims the daily reward and server accepts it. | F20: The daily reward was claimed. | G20: user_id (string) - required | H20: event_id (UUID v4) - required, generated at source | I20: event_timestamp (UTC ISO 8601) - required; received_at added by pipeline | J20: Proposed - confirm feature exists | K20: daily_reward_day_index, reward_id | L20: current_streak | M20: daily_reward_day_index:integer; reward_id:string; current_streak:integer | N20: One claim per user per day (user's timezone); links to reward_credited. | O20: Backend (engagement service) | P20: Daily habit measurement. | Q20: K04 DAU/WAU/MAU; K17 Engagement-mechanic participation | R20: Not started | S20: =IF(AND(EXACT(C20,LOWER(C20)),LEN(C20)<=40,ISERROR(FIND(" ",C20)),ISERROR(FIND("-",C20))),"OK","CHECK") -> OK
A21: E020 | B21: Engagement | C21: streak_updated | D21: Minimum list (conditional) | E21: Server increments, resets or freezes a streak. | F21: A streak value changed. | G21: user_id (string) - required | H21: event_id (UUID v4) - required, generated at source | I21: event_timestamp (UTC ISO 8601) - required; received_at added by pipeline | J21: Proposed - confirm feature exists | K21: current_streak, previous_streak, streak_action | M21: current_streak:integer; previous_streak:integer; streak_action:enum | N21: increment: current = previous + 1; reset: current = 0. | O21: Backend (engagement service) | P21: Streak health and retention driver. | Q21: K05 Retention; K17 Engagement-mechanic participation | R21: Not started | S21: =IF(AND(EXACT(C21,LOWER(C21)),LEN(C21)<=40,ISERROR(FIND(" ",C21)),ISERROR(FIND("-",C21))),"OK","CHECK") -> OK
A22: E021 | B22: Engagement | C22: mission_started | D22: Minimum list (conditional) | E22: User accepts or is auto-enrolled in a mission. | F22: A mission began. | G22: user_id (string) - required | H22: event_id (UUID v4) - required, generated at source | I22: event_timestamp (UTC ISO 8601) - required; received_at added by pipeline | J22: Proposed - confirm feature exists | K22: mission_id, mission_type | L22: mission_target_value | M22: mission_id:string; mission_type:string; mission_target_value:integer | N22: mission_id exists in catalogue; once per user per mission instance. | O22: Backend (engagement service) | P22: Mission funnel start. | Q22: K17 Engagement-mechanic participation | R22: Not started | S22: =IF(AND(EXACT(C22,LOWER(C22)),LEN(C22)<=40,ISERROR(FIND(" ",C22)),ISERROR(FIND("-",C22))),"OK","CHECK") -> OK
A23: E022 | B23: Engagement | C23: mission_completed | D23: Minimum list (conditional) | E23: Mission goal is met and verified. | F23: A mission was completed. | G23: user_id (string) - required | H23: event_id (UUID v4) - required, generated at source | I23: event_timestamp (UTC ISO 8601) - required; received_at added by pipeline | J23: Proposed - confirm feature exists | K23: mission_id, mission_type, mission_duration_sec | L23: reward_id | M23: mission_id:string; mission_type:string; mission_duration_sec:integer; reward_id:string | N23: Requires prior mission_started. | O23: Backend (engagement service) | P23: Mission effectiveness and reward cost. | Q23: K17 Engagement-mechanic participation; K08 Reward cost | R23: Not started | S23: =IF(AND(EXACT(C23,LOWER(C23)),LEN(C23)<=40,ISERROR(FIND(" ",C23)),ISERROR(FIND("-",C23))),"OK","CHECK") -> OK
A24: E023 | B24: Engagement | C24: badge_earned | D24: Minimum list (conditional) | E24: User meets a badge condition. | F24: A badge was awarded. | G24: user_id (string) - required | H24: event_id (UUID v4) - required, generated at source | I24: event_timestamp (UTC ISO 8601) - required; received_at added by pipeline | J24: Proposed - confirm feature exists | K24: badge_id | L24: badge_trigger | M24: badge_id:string; badge_trigger:string | N24: Each badge at most once per user. | O24: Backend (engagement service) | P24: Measures achievement mechanics. | Q24: K17 Engagement-mechanic participation | R24: Not started | S24: =IF(AND(EXACT(C24,LOWER(C24)),LEN(C24)<=40,ISERROR(FIND(" ",C24)),ISERROR(FIND("-",C24))),"OK","CHECK") -> OK
A25: E024 | B25: Engagement | C25: spin_started | D25: Minimum list (conditional) | E25: User starts a spin. | F25: A spin was initiated. | G25: user_id (string) - required | H25: event_id (UUID v4) - required, generated at source | I25: event_timestamp (UTC ISO 8601) - required; received_at added by pipeline | J25: Proposed - confirm feature exists | K25: spin_id, spin_entry_method | M25: spin_id:string; spin_entry_method:enum | N25: spin_id unique; user eligible for a spin. | O25: Client (app) + Backend | P25: Spin funnel start. | Q25: K17 Engagement-mechanic participation | R25: Not started | S25: =IF(AND(EXACT(C25,LOWER(C25)),LEN(C25)<=40,ISERROR(FIND(" ",C25)),ISERROR(FIND("-",C25))),"OK","CHECK") -> OK
A26: E025 | B26: Engagement | C26: spin_completed | D26: Minimum list (conditional) | E26: Server resolves the spin outcome. | F26: A spin outcome was determined. | G26: user_id (string) - required | H26: event_id (UUID v4) - required, generated at source | I26: event_timestamp (UTC ISO 8601) - required; received_at added by pipeline | J26: Proposed - confirm feature exists | K26: spin_id, spin_outcome_type | L26: reward_id | M26: spin_id:string; spin_outcome_type:enum; reward_id:string | N26: Matches spin_started; reward_id required if outcome is reward. | O26: Backend (engagement service) | P26: Spin cost and outcome distribution. | Q26: K17 Engagement-mechanic participation; K08 Reward cost | R26: Not started | S26: =IF(AND(EXACT(C26,LOWER(C26)),LEN(C26)<=40,ISERROR(FIND(" ",C26)),ISERROR(FIND("-",C26))),"OK","CHECK") -> OK
A27: E026 | B27: Referrals | C27: referral_created | D27: Minimum list | E27: User generates or shares a referral code or link. | F27: A referral invite was created. | G27: user_id (string) - required | H27: event_id (UUID v4) - required, generated at source | I27: event_timestamp (UTC ISO 8601) - required; received_at added by pipeline | J27: Proposed | K27: referral_id, referral_code, referral_channel | M27: referral_id:string; referral_code:string; referral_channel:enum | N27: referral_id unique; one code per user stays stable. | O27: Client (app) + Backend | P27: Top of referral funnel. | Q27: K11 Referral conversion; K12 Referral cost | R27: Not started | S27: =IF(AND(EXACT(C27,LOWER(C27)),LEN(C27)<=40,ISERROR(FIND(" ",C27)),ISERROR(FIND("-",C27))),"OK","CHECK") -> OK
A28: E027 | B28: Referrals | C28: referral_registered | D28: Minimum list | E28: A new user registers using the referral code or link. | F28: A referred person signed up. | G28: user_id (string) - required; equals referred_user_id | H28: event_id (UUID v4) - required, generated at source | I28: event_timestamp (UTC ISO 8601) - required; received_at added by pipeline | J28: Proposed | K28: referral_id, referrer_user_id, referred_user_id | L28: referral_channel | M28: referral_id:string; referrer_user_id:string; referred_user_id:string; referral_channel:enum | N28: referrer_user_id <> referred_user_id; matches a referral_created. | O28: Backend (auth/referral service) | P28: Referral signups and channel quality. | Q28: K11 Referral conversion; K01 New registrations | R28: Not started | S28: =IF(AND(EXACT(C28,LOWER(C28)),LEN(C28)<=40,ISERROR(FIND(" ",C28)),ISERROR(FIND("-",C28))),"OK","CHECK") -> OK
A29: E028 | B29: Referrals | C29: referral_activated | D29: Minimum list | E29: Referred user reaches the activation rule. | F29: Referred user became active. | G29: user_id (string) - required; equals referred_user_id | H29: event_id (UUID v4) - required, generated at source | I29: event_timestamp (UTC ISO 8601) - required; received_at added by pipeline | J29: Proposed | K29: referral_id, referrer_user_id, referred_user_id, activation_criterion | M29: referral_id:string; referrer_user_id:string; referred_user_id:string; activation_criterion:string | N29: Follows referral_registered; criterion must be documented by product. | O29: Backend (referral service) | P29: Quality of referred users. | Q29: K11 Referral conversion; K02 Activation rate | R29: Not started | S29: =IF(AND(EXACT(C29,LOWER(C29)),LEN(C29)<=40,ISERROR(FIND(" ",C29)),ISERROR(FIND("-",C29))),"OK","CHECK") -> OK
A30: E029 | B30: Referrals | C30: referral_converted | D30: Minimum list | E30: Referred user reaches the rewarding milestone. | F30: Referral qualified for the referrer's bonus. | G30: user_id (string) - required; equals referred_user_id | H30: event_id (UUID v4) - required, generated at source | I30: event_timestamp (UTC ISO 8601) - required; received_at added by pipeline | J30: Proposed | K30: referral_id, referrer_user_id, referred_user_id, conversion_criterion | L30: referrer_bonus_id | M30: referral_id:string; referrer_user_id:string; referred_user_id:string; conversion_criterion:string; referrer_bonus_id:string | N30: Follows referral_activated; at most once per referral; open definition to agree with product. | O30: Backend (referral service) | P30: Referral payoff and cost per converted referral. | Q30: K11 Referral conversion; K12 Referral cost; K08 Reward cost | R30: Not started | S30: =IF(AND(EXACT(C30,LOWER(C30)),LEN(C30)<=40,ISERROR(FIND(" ",C30)),ISERROR(FIND("-",C30))),"OK","CHECK") -> OK
A31: E030 | B31: Wallet | C31: wallet_transaction_created | D31: Minimum list | E31: Ledger service writes a new transaction entry. | F31: A wallet ledger entry was created. | G31: user_id (string) - required | H31: event_id (UUID v4) - required, generated at source | I31: event_timestamp (UTC ISO 8601) - required; received_at added by pipeline | J31: Proposed | K31: wallet_transaction_id, transaction_type, transaction_amount, transaction_unit | L31: related_entity_type, related_entity_id | M31: wallet_transaction_id:string; transaction_type:enum; transaction_amount:decimal; transaction_unit:enum; related_entity_type:enum; related_entity_id:string | N31: transaction_amount > 0; unique id; links to a reward or withdrawal. | O31: Backend (wallet ledger) | P31: Source of truth for money movement. | Q31: K18 Ledger reconciliation; K09 Reward liability | R31: Not started | S31: =IF(AND(EXACT(C31,LOWER(C31)),LEN(C31)<=40,ISERROR(FIND(" ",C31)),ISERROR(FIND("-",C31))),"OK","CHECK") -> OK
A32: E031 | B32: Wallet | C32: wallet_transaction_completed | D32: Minimum list | E32: Ledger entry is settled and balance updated. | F32: A wallet transaction finalised. | G32: user_id (string) - required | H32: event_id (UUID v4) - required, generated at source | I32: event_timestamp (UTC ISO 8601) - required; received_at added by pipeline | J32: Proposed | K32: wallet_transaction_id, transaction_type, transaction_amount, transaction_unit, balance_after | L32: related_entity_type, related_entity_id | M32: wallet_transaction_id:string; transaction_type:enum; transaction_amount:decimal; transaction_unit:enum; balance_after:decimal; related_entity_type:enum; related_entity_id:string | N32: Follows wallet_transaction_created; balance_after >= 0. | O32: Backend (wallet ledger) | P32: Balance integrity and liability. | Q32: K18 Ledger reconciliation; K09 Reward liability | R32: Not started | S32: =IF(AND(EXACT(C32,LOWER(C32)),LEN(C32)<=40,ISERROR(FIND(" ",C32)),ISERROR(FIND("-",C32))),"OK","CHECK") -> OK
A33: E032 | B33: Wallet | C33: wallet_transaction_reversed | D33: Minimum list | E33: A completed or created transaction is reversed. | F33: A wallet entry was reversed. | G33: user_id (string) - required | H33: event_id (UUID v4) - required, generated at source | I33: event_timestamp (UTC ISO 8601) - required; received_at added by pipeline | J33: Proposed | K33: wallet_transaction_id, transaction_amount, reversal_reason, reversal_transaction_id | L33: balance_after | M33: wallet_transaction_id:string; transaction_amount:decimal; reversal_reason:enum; reversal_transaction_id:string; balance_after:decimal | N33: Original transaction must exist; reversal_transaction_id unique. | O33: Backend (wallet ledger) | P33: Detects errors, fraud and failed payouts. | Q33: K10 Reward reversal rate; K18 Ledger reconciliation | R33: Not started | S33: =IF(AND(EXACT(C33,LOWER(C33)),LEN(C33)<=40,ISERROR(FIND(" ",C33)),ISERROR(FIND("-",C33))),"OK","CHECK") -> OK
A34: E033 | B34: Withdrawals | C34: withdrawal_requested | D34: Minimum list | E34: User confirms a withdrawal and server accepts the request. | F34: A withdrawal request exists. | G34: user_id (string) - required | H34: event_id (UUID v4) - required, generated at source | I34: event_timestamp (UTC ISO 8601) - required; received_at added by pipeline | J34: Proposed | K34: withdrawal_id, withdrawal_amount, withdrawal_currency, payout_method | L34: withdrawal_fee, payout_provider, saved_payout_token | M34: withdrawal_id:string; withdrawal_amount:decimal; withdrawal_currency:string; payout_method:enum; withdrawal_fee:decimal; payout_provider:string; saved_payout_token:string | N34: Amount >= minimum and <= available balance; payout_method in list; no raw bank/card data. | O34: Backend (withdrawal service) | P34: Start of cash-out funnel. | Q34: K13 Withdrawal success rate; K14 Time to payout | R34: Not started | S34: =IF(AND(EXACT(C34,LOWER(C34)),LEN(C34)<=40,ISERROR(FIND(" ",C34)),ISERROR(FIND("-",C34))),"OK","CHECK") -> OK
A35: E034 | B35: Withdrawals | C35: withdrawal_processing | D35: Minimum list | E35: Request passes checks and is sent to the payout provider. | F35: A withdrawal is being processed. | G35: user_id (string) - required | H35: event_id (UUID v4) - required, generated at source | I35: event_timestamp (UTC ISO 8601) - required; received_at added by pipeline | J35: Proposed | K35: withdrawal_id, payout_provider, review_type | L35: provider_reference | M35: withdrawal_id:string; payout_provider:string; review_type:enum; provider_reference:string | N35: Follows withdrawal_requested. | O35: Backend (withdrawal service) | P35: Measures review delay and automation rate. | Q35: K14 Time to payout; K13 Withdrawal success rate | R35: Not started | S35: =IF(AND(EXACT(C35,LOWER(C35)),LEN(C35)<=40,ISERROR(FIND(" ",C35)),ISERROR(FIND("-",C35))),"OK","CHECK") -> OK
A36: E035 | B36: Withdrawals | C36: withdrawal_completed | D36: Minimum list | E36: Provider confirms the money was sent. | F36: A withdrawal was paid out. | G36: user_id (string) - required | H36: event_id (UUID v4) - required, generated at source | I36: event_timestamp (UTC ISO 8601) - required; received_at added by pipeline | J36: Proposed | K36: withdrawal_id, withdrawal_amount, withdrawal_currency, payout_method, provider_reference | L36: processing_duration_sec | M36: withdrawal_id:string; withdrawal_amount:decimal; withdrawal_currency:string; payout_method:enum; provider_reference:string; processing_duration_sec:integer | N36: Follows withdrawal_processing; once per withdrawal. | O36: Payout provider webhook + Backend | P36: Successful payout and cash cost. | Q36: K13 Withdrawal success rate; K14 Time to payout; K08 Reward cost | R36: Not started | S36: =IF(AND(EXACT(C36,LOWER(C36)),LEN(C36)<=40,ISERROR(FIND(" ",C36)),ISERROR(FIND("-",C36))),"OK","CHECK") -> OK
A37: E036 | B37: Withdrawals | C37: withdrawal_rejected | D37: Minimum list | E37: Request is declined by system or reviewer. | F37: A withdrawal was refused. | G37: user_id (string) - required | H37: event_id (UUID v4) - required, generated at source | I37: event_timestamp (UTC ISO 8601) - required; received_at added by pipeline | J37: Proposed | K37: withdrawal_id, rejection_reason | L37: rejected_by, withdrawal_amount | M37: withdrawal_id:string; rejection_reason:enum; rejected_by:enum; withdrawal_amount:decimal | N37: Mutually exclusive with completed unless later reversed. | O37: Backend (withdrawal service) | P37: Shows why users cannot cash out. | Q37: K15 Withdrawal rejection rate; K16 Fraud rate | R37: Not started | S37: =IF(AND(EXACT(C37,LOWER(C37)),LEN(C37)<=40,ISERROR(FIND(" ",C37)),ISERROR(FIND("-",C37))),"OK","CHECK") -> OK
A38: E037 | B38: Withdrawals | C38: withdrawal_reversed | D38: Minimum list | E38: Payout fails or is returned after completion/processing. | F38: A withdrawal was reversed and funds returned. | G38: user_id (string) - required | H38: event_id (UUID v4) - required, generated at source | I38: event_timestamp (UTC ISO 8601) - required; received_at added by pipeline | J38: Proposed | K38: withdrawal_id, reversal_reason, withdrawal_amount | L38: provider_reference | M38: withdrawal_id:string; reversal_reason:enum; withdrawal_amount:decimal; provider_reference:string | N38: Follows processing or completed; funds return via wallet_transaction_reversed. | O38: Payout provider webhook + Backend | P38: Payout failure and loss tracking. | Q38: K15 Withdrawal rejection rate; K18 Ledger reconciliation | R38: Not started | S38: =IF(AND(EXACT(C38,LOWER(C38)),LEN(C38)<=40,ISERROR(FIND(" ",C38)),ISERROR(FIND("-",C38))),"OK","CHECK") -> OK
A39: E038 | B39: Withdrawals | C39: payout_method_added | D39: Analyst-added | E39: User saves a payout method. | F39: A payout method was added. | G39: user_id (string) - required | H39: event_id (UUID v4) - required, generated at source | I39: event_timestamp (UTC ISO 8601) - required; received_at added by pipeline | J39: Proposed | K39: saved_payout_token, payout_method | M39: saved_payout_token:string; payout_method:enum | N39: Store only tokenised ID; never raw account numbers. | O39: Client (app) + Backend | P39: Explains payout failures and conversion to cash-out. | Q39: K13 Withdrawal success rate | R39: Not started | S39: =IF(AND(EXACT(C39,LOWER(C39)),LEN(C39)<=40,ISERROR(FIND(" ",C39)),ISERROR(FIND("-",C39))),"OK","CHECK") -> OK
A40: E039 | B40: Risk | C40: fraud_flag_raised | D40: Analyst-added | E40: A fraud rule or reviewer flags an entity. | F40: A potential abuse case was flagged. | G40: user_id (string) - required | H40: event_id (UUID v4) - required, generated at source | I40: event_timestamp (UTC ISO 8601) - required; received_at added by pipeline | J40: Proposed | K40: fraud_flag_id, fraud_rule_id, flagged_entity_type, action_taken | L40: risk_score | M40: fraud_flag_id:string; fraud_rule_id:string; flagged_entity_type:enum; action_taken:enum; risk_score:integer | N40: Entity must exist; no sensitive evidence in properties. | O40: Backend (risk service) | P40: Measures abuse and its financial impact. | Q40: K16 Fraud rate; K10 Reward reversal rate | R40: Not started | S40: =IF(AND(EXACT(C40,LOWER(C40)),LEN(C40)<=40,ISERROR(FIND(" ",C40)),ISERROR(FIND("-",C40))),"OK","CHECK") -> OK

Sheet Naming Standard
A1: Selected convention: object_action (lowercase snake_case, action in past tense)
A3: Rule | B3: Standard | C3: Good example | D3: Bad example | E3: Why
A4: Pattern | B4: object_action: the thing, then what happened to it | C4: task_completed | D4: completeTask, TaskComplete | E4: One predictable shape makes events easy to guess, search and group.
A5: Case | B5: lowercase snake_case only; no spaces, hyphens or capitals | C5: withdrawal_requested | D5: Withdrawal Requested | E5: Avoids mismatches across iOS, Android, backend and SQL.
A6: Tense | B6: Action is past tense: the fact has already happened | C6: reward_credited | D6: reward_credit | E6: Events record facts, not commands; clear for analysts.
A7: Object | B7: Business object, not a screen or button; compound objects allowed | C7: wallet_transaction_created | D7: tap_green_button | E7: Business objects stay stable when the UI changes.
A8: Granularity | B8: One event per business fact; variants go in properties | C8: task_completed with task_type | D8: task_completed_survey | E8: Stops event count exploding; lets us group and filter.
A9: Lifecycle verbs | B9: Use a fixed verb set: viewed, opened, started, completed, failed, created, requested, processing, credited, pending, reversed, rejected, earned, claimed, updated | C9: withdrawal_rejected | D9: withdrawal_declined / withdrawal_denied | E9: One verb per meaning prevents synonyms.
A10: Domain | B10: Feature domain lives in the 'feature' attribute of the plan, not in the name, unless needed for clarity | C10: feature = Withdrawals | D10: withdrawals_withdrawal_requested | E10: Keeps names short (max 40 characters).
A11: Properties | B11: snake_case, same name and type everywhere; IDs end in _id; timestamps end in _at or _ts; amounts end in _amount | C11: withdrawal_amount | D11: amt, WithdrawAmt | E11: Lets one property definition serve all events.
A12: Source | B12: Server events for money, rewards, status changes; client events for UI actions only | C12: reward_credited = server | D12: reward_credited from the app | E12: Client events can be lost, blocked or faked.
A13: Versioning | B13: Do not rename live events; add schema_version and a new property instead | C13: schema_version = 2 | D13: task_completed_v2 | E13: Keeps history comparable.
A14: Privacy | B14: No names, emails, phone numbers, raw bank or card data in any event | C14: saved_payout_token (token) | D14: bank_account_number | E14: Reduces legal and security risk.
A16: Why object_action and not domain_object_action?
A17: 1. It matches the minimum event list we were given (user_registered, task_viewed, wallet_transaction_created), so the standard fits existing language with no exceptions.
A18: 2. The object already carries the domain: 'withdrawal_' means withdrawals, 'wallet_' means wallet. An extra prefix would make names long (withdrawals_withdrawal_requested).
A19: 3. Alphabetical sorting groups events by object, so one object's lifecycle (requested, processing, completed, rejected, reversed) appears together.
A20: 4. Past tense separates facts from commands and makes lifecycles read naturally.
A21: 5. Feature grouping is still available through the Feature column and an event property, so no information is lost.
A22: Trade-off: object_action gives less automatic grouping than a domain prefix. We accept this because the object names are already distinctive.

Sheet Common Properties
A1: Property | B1: Data Type | C1: Required | D1: Definition | E1: Validation | F1: Example
A2: event_id | B2: UUID v4 | C2: Yes | D2: Unique ID of this event, generated where it fires. | E2: Unique across all events; used to deduplicate | F2: 3f1c...e9
A3: event_name | B3: string | C3: Yes | D3: Name of the event following the naming standard. | E3: Must match an entry in the Event Catalogue | F3: task_completed
A4: event_timestamp | B4: timestamp | C4: Yes | D4: When the action happened, UTC ISO 8601. | E4: Not in the future by more than 5 min; not older than 7 days at ingestion | F4: 2026-10-17T08:03:55Z
A5: received_at | B5: timestamp | C5: Yes | D5: When the pipeline received the event (added by server). | E5: received_at >= event_timestamp | F5: 2026-10-17T08:03:57Z
A6: user_id | B6: string | C6: Yes (null allowed only pre-login) | D6: Stable internal user identifier. | E6: Must exist in the user table; never email or phone | F6: U-00048213
A7: anonymous_id | B7: string | C7: If user_id is null | D7: Device-level ID before login. | E7: UUID | F7: 8d2a...
A8: session_id | B8: string | C8: Yes for client events | D8: Identifier of the app session. | E8: Not null | F8: SES-aa91f
A9: platform | B9: enum | C9: Yes | D9: Client platform (server events use 'server'). | E9: ios, android, web, server | F9: android
A10: app_version | B10: string | C10: Yes for client events | D10: Version of the app. | E10: Semantic version | F10: 5.12.0
A11: schema_version | B11: integer | C11: Yes | D11: Version of this event's schema. | E11: Integer >= 1 | F11: 1
A12: country_code | B12: string | C12: Yes | D12: ISO 3166-1 alpha-2 country of the user. | E12: In ISO list | F12: IN
A13: event_source | B13: enum | C13: Yes | D13: Where the event was generated. | E13: client, backend, provider_webhook | F13: backend

Sheet Property Dictionary
A1: Property | B1: Data Type | C1: Definition | D1: Allowed Values / Format | E1: Example | F1: Used as Required (events) | G1: Used as Optional (events)
A2: action_taken | B2: enum | C2: Automated response. | D2: none, hold, block, review | E2: hold | F2: =COUNTIF('Event Catalogue'!$K$2:$K$100,"*"&A2&"*") -> 1 | G2: =COUNTIF('Event Catalogue'!$L$2:$L$100,"*"&A2&"*") -> 0
A3: activation_criterion | B3: string | C3: Rule defining activation (to be set by product). | E3: first_task_completed | F3: =COUNTIF('Event Catalogue'!$K$2:$K$100,"*"&A3&"*") -> 1 | G3: =COUNTIF('Event Catalogue'!$L$2:$L$100,"*"&A3&"*") -> 0
A4: badge_id | B4: string | C4: Identifier of the badge. | E4: BDG-10 | F4: =COUNTIF('Event Catalogue'!$K$2:$K$100,"*"&A4&"*") -> 1 | G4: =COUNTIF('Event Catalogue'!$L$2:$L$100,"*"&A4&"*") -> 0
A5: badge_trigger | B5: string | C5: Condition that earned the badge. | E5: 10_tasks_completed | F5: =COUNTIF('Event Catalogue'!$K$2:$K$100,"*"&A5&"*") -> 0 | G5: =COUNTIF('Event Catalogue'!$L$2:$L$100,"*"&A5&"*") -> 1
A6: balance_after | B6: decimal | C6: Available balance after the event. | D6: >= 0 | E6: 180.00 | F6: =COUNTIF('Event Catalogue'!$K$2:$K$100,"*"&A6&"*") -> 1 | G6: =COUNTIF('Event Catalogue'!$L$2:$L$100,"*"&A6&"*") -> 1
A7: completion_duration_sec | B7: integer | C7: Seconds from task_started to completion. | D7: >= 0 | E7: 240 | F7: =COUNTIF('Event Catalogue'!$K$2:$K$100,"*"&A7&"*") -> 1 | G7: =COUNTIF('Event Catalogue'!$L$2:$L$100,"*"&A7&"*") -> 0
A8: completion_source | B8: enum | C8: How completion was verified. | D8: internal, partner_postback, manual | E8: partner_postback | F8: =COUNTIF('Event Catalogue'!$K$2:$K$100,"*"&A8&"*") -> 0 | G8: =COUNTIF('Event Catalogue'!$L$2:$L$100,"*"&A8&"*") -> 1
A9: conversion_criterion | B9: string | C9: Rule defining conversion (to be set by product). | E9: first_withdrawal_completed | F9: =COUNTIF('Event Catalogue'!$K$2:$K$100,"*"&A9&"*") -> 1 | G9: =COUNTIF('Event Catalogue'!$L$2:$L$100,"*"&A9&"*") -> 0
A10: current_streak | B10: integer | C10: Streak length after the update. | D10: >= 0 | E10: 4 | F10: =COUNTIF('Event Catalogue'!$K$2:$K$100,"*"&A10&"*") -> 1 | G10: =COUNTIF('Event Catalogue'!$L$2:$L$100,"*"&A10&"*") -> 1
A11: daily_reward_day_index | B11: integer | C11: Day number in the daily reward cycle. | D11: 1-31 | E11: 3 | F11: =COUNTIF('Event Catalogue'!$K$2:$K$100,"*"&A11&"*") -> 1 | G11: =COUNTIF('Event Catalogue'!$L$2:$L$100,"*"&A11&"*") -> 0
A12: device_changed | B12: boolean | C12: True if device differs from the previous login. | D12: true, false | E12: false | F12: =COUNTIF('Event Catalogue'!$K$2:$K$100,"*"&A12&"*") -> 0 | G12: =COUNTIF('Event Catalogue'!$L$2:$L$100,"*"&A12&"*") -> 1
A13: expected_release_at | B13: timestamp | C13: Expected time reward becomes available. | D13: UTC ISO 8601 > event time | E13: 2026-10-24T08:00:00Z | F13: =COUNTIF('Event Catalogue'!$K$2:$K$100,"*"&A13&"*") -> 0 | G13: =COUNTIF('Event Catalogue'!$L$2:$L$100,"*"&A13&"*") -> 1
A14: expiry_at | B14: timestamp | C14: Time the reward expires. | D14: UTC ISO 8601 | E14: 2026-12-31T23:59:59Z | F14: =COUNTIF('Event Catalogue'!$K$2:$K$100,"*"&A14&"*") -> 1 | G14: =COUNTIF('Event Catalogue'!$L$2:$L$100,"*"&A14&"*") -> 0
A15: failure_reason | B15: enum | C15: Why the task attempt failed. | D15: timeout, partner_rejected, technical_error, ineligible, fraud_detected | E15: timeout | F15: =COUNTIF('Event Catalogue'!$K$2:$K$100,"*"&A15&"*") -> 1 | G15: =COUNTIF('Event Catalogue'!$L$2:$L$100,"*"&A15&"*") -> 0
A16: failure_stage | B16: enum | C16: Stage at which the attempt failed. | D16: before_start, in_progress, verification | E16: verification | F16: =COUNTIF('Event Catalogue'!$K$2:$K$100,"*"&A16&"*") -> 0 | G16: =COUNTIF('Event Catalogue'!$L$2:$L$100,"*"&A16&"*") -> 1
A17: flagged_entity_type | B17: enum | C17: What was flagged. | D17: user, task_attempt, reward, referral, withdrawal | E17: referral | F17: =COUNTIF('Event Catalogue'!$K$2:$K$100,"*"&A17&"*") -> 1 | G17: =COUNTIF('Event Catalogue'!$L$2:$L$100,"*"&A17&"*") -> 0
A18: fraud_flag_id | B18: string | C18: Unique ID of a fraud flag. | E18: FF-8801 | F18: =COUNTIF('Event Catalogue'!$K$2:$K$100,"*"&A18&"*") -> 1 | G18: =COUNTIF('Event Catalogue'!$L$2:$L$100,"*"&A18&"*") -> 0
A19: fraud_rule_id | B19: string | C19: Rule that fired. | E19: RULE-multi-acct | F19: =COUNTIF('Event Catalogue'!$K$2:$K$100,"*"&A19&"*") -> 1 | G19: =COUNTIF('Event Catalogue'!$L$2:$L$100,"*"&A19&"*") -> 0
A20: is_first_login | B20: boolean | C20: True if first login after registration. | D20: true, false | E20: false | F20: =COUNTIF('Event Catalogue'!$K$2:$K$100,"*"&A20&"*") -> 0 | G20: =COUNTIF('Event Catalogue'!$L$2:$L$100,"*"&A20&"*") -> 1
A21: kyc_level | B21: enum | C21: Verification level requested. | D21: basic, enhanced | E21: basic | F21: =COUNTIF('Event Catalogue'!$K$2:$K$100,"*"&A21&"*") -> 1 | G21: =COUNTIF('Event Catalogue'!$L$2:$L$100,"*"&A21&"*") -> 1
A22: kyc_request_id | B22: string | C22: Unique ID of an identity verification submission. | E22: KYC-3381 | F22: =COUNTIF('Event Catalogue'!$K$2:$K$100,"*"&A22&"*") -> 2 | G22: =COUNTIF('Event Catalogue'!$L$2:$L$100,"*"&A22&"*") -> 0
A23: kyc_result | B23: enum | C23: Outcome of verification. | D23: approved, rejected, needs_more_info | E23: approved | F23: =COUNTIF('Event Catalogue'!$K$2:$K$100,"*"&A23&"*") -> 1 | G23: =COUNTIF('Event Catalogue'!$L$2:$L$100,"*"&A23&"*") -> 0
A24: list_position | B24: integer | C24: Position of task in the list (1-based). | D24: >= 1 | E24: 3 | F24: =COUNTIF('Event Catalogue'!$K$2:$K$100,"*"&A24&"*") -> 1 | G24: =COUNTIF('Event Catalogue'!$L$2:$L$100,"*"&A24&"*") -> 1
A25: login_method | B25: enum | C25: Authentication method used. | D25: password, otp, google, apple, biometric | E25: otp | F25: =COUNTIF('Event Catalogue'!$K$2:$K$100,"*"&A25&"*") -> 1 | G25: =COUNTIF('Event Catalogue'!$L$2:$L$100,"*"&A25&"*") -> 0
A26: logout_reason | B26: enum | C26: Why the session ended. | D26: user_initiated, forced_by_system, security_reset | E26: user_initiated | F26: =COUNTIF('Event Catalogue'!$K$2:$K$100,"*"&A26&"*") -> 1 | G26: =COUNTIF('Event Catalogue'!$L$2:$L$100,"*"&A26&"*") -> 0
A27: mission_duration_sec | B27: integer | C27: Seconds from start to completion. | D27: >= 0 | E27: 86400 | F27: =COUNTIF('Event Catalogue'!$K$2:$K$100,"*"&A27&"*") -> 1 | G27: =COUNTIF('Event Catalogue'!$L$2:$L$100,"*"&A27&"*") -> 0
A28: mission_id | B28: string | C28: Identifier of the mission. | E28: MS-120 | F28: =COUNTIF('Event Catalogue'!$K$2:$K$100,"*"&A28&"*") -> 2 | G28: =COUNTIF('Event Catalogue'!$L$2:$L$100,"*"&A28&"*") -> 0
A29: mission_target_value | B29: integer | C29: Goal value required to finish. | D29: > 0 | E29: 5 | F29: =COUNTIF('Event Catalogue'!$K$2:$K$100,"*"&A29&"*") -> 0 | G29: =COUNTIF('Event Catalogue'!$L$2:$L$100,"*"&A29&"*") -> 1
A30: mission_type | B30: string | C30: Mission category. | E30: invite_friends | F30: =COUNTIF('Event Catalogue'!$K$2:$K$100,"*"&A30&"*") -> 2 | G30: =COUNTIF('Event Catalogue'!$L$2:$L$100,"*"&A30&"*") -> 0
A31: onboarding_duration_sec | B31: integer | C31: Seconds between onboarding start and completion. | D31: 0-86400 | E31: 95 | F31: =COUNTIF('Event Catalogue'!$K$2:$K$100,"*"&A31&"*") -> 1 | G31: =COUNTIF('Event Catalogue'!$L$2:$L$100,"*"&A31&"*") -> 0
A32: onboarding_flow_version | B32: string | C32: Version of the onboarding flow shown. | D32: semver or A/B label | E32: v2.1 | F32: =COUNTIF('Event Catalogue'!$K$2:$K$100,"*"&A32&"*") -> 2 | G32: =COUNTIF('Event Catalogue'!$L$2:$L$100,"*"&A32&"*") -> 0
A33: onboarding_step_id | B33: string | C33: Identifier of the onboarding step. | D33: from step catalogue | E33: permissions | F33: =COUNTIF('Event Catalogue'!$K$2:$K$100,"*"&A33&"*") -> 1 | G33: =COUNTIF('Event Catalogue'!$L$2:$L$100,"*"&A33&"*") -> 0
A34: onboarding_step_index | B34: integer | C34: Position of the step in the flow (1-based). | D34: 1-20 | E34: 2 | F34: =COUNTIF('Event Catalogue'!$K$2:$K$100,"*"&A34&"*") -> 1 | G34: =COUNTIF('Event Catalogue'!$L$2:$L$100,"*"&A34&"*") -> 0
A35: onboarding_total_steps | B35: integer | C35: Number of steps in the flow shown. | D35: 1-20 | E35: 4 | F35: =COUNTIF('Event Catalogue'!$K$2:$K$100,"*"&A35&"*") -> 1 | G35: =COUNTIF('Event Catalogue'!$L$2:$L$100,"*"&A35&"*") -> 0
A36: open_source | B36: enum | C36: What caused the app to open. | D36: organic, push, deep_link, widget | E36: push | F36: =COUNTIF('Event Catalogue'!$K$2:$K$100,"*"&A36&"*") -> 0 | G36: =COUNTIF('Event Catalogue'!$L$2:$L$100,"*"&A36&"*") -> 1
A37: original_reward_status | B37: enum | C37: Status of the reward before reversal. | D37: pending, credited | E37: credited | F37: =COUNTIF('Event Catalogue'!$K$2:$K$100,"*"&A37&"*") -> 0 | G37: =COUNTIF('Event Catalogue'!$L$2:$L$100,"*"&A37&"*") -> 1
A38: payout_method | B38: enum | C38: Payout channel. | D38: bank_transfer, mobile_money, paypal, gift_card, other | E38: paypal | F38: =COUNTIF('Event Catalogue'!$K$2:$K$100,"*"&A38&"*") -> 3 | G38: =COUNTIF('Event Catalogue'!$L$2:$L$100,"*"&A38&"*") -> 0
A39: payout_provider | B39: string | C39: External provider handling payout. | E39: provider_a | F39: =COUNTIF('Event Catalogue'!$K$2:$K$100,"*"&A39&"*") -> 1 | G39: =COUNTIF('Event Catalogue'!$L$2:$L$100,"*"&A39&"*") -> 1
A40: pending_reason | B40: enum | C40: Why the reward is held. | D40: partner_validation, fraud_review, cooling_period | E40: partner_validation | F40: =COUNTIF('Event Catalogue'!$K$2:$K$100,"*"&A40&"*") -> 1 | G40: =COUNTIF('Event Catalogue'!$L$2:$L$100,"*"&A40&"*") -> 0
...

Sheet KPI Map
A1: KPI ID | B1: KPI | C1: Definition | D1: Events Depending (count)
A2: K01 | B2: New registrations | C2: Count of unique new accounts per period. | D2: =COUNTIF('Event Catalogue'!$Q$2:$Q$100,"*"&A2&" *") -> 2
A3: K02 | B3: Activation rate | C3: Share of registered users who complete a first task within 7 days. | D3: =COUNTIF('Event Catalogue'!$Q$2:$Q$100,"*"&A3&" *") -> 5
A4: K03 | B4: Onboarding completion | C4: Share of users who start onboarding and complete it. | D4: =COUNTIF('Event Catalogue'!$Q$2:$Q$100,"*"&A4&" *") -> 3
A5: K04 | B5: DAU/WAU/MAU | C5: Distinct users active (login or core action) per day, week and month; DAU/MAU for stickiness. | D5: =COUNTIF('Event Catalogue'!$Q$2:$Q$100,"*"&A5&" *") -> 4
A6: K05 | B6: Retention | C6: Share of a signup cohort active on day 1, 7 and 30. | D6: =COUNTIF('Event Catalogue'!$Q$2:$Q$100,"*"&A6&" *") -> 4
A7: K06 | B7: Task completion rate | C7: task_completed / task_started (and view-to-start funnel). | D7: =COUNTIF('Event Catalogue'!$Q$2:$Q$100,"*"&A7&" *") -> 4
A8: K07 | B8: Task failure rate | C8: task_failed / task_started. | D8: =COUNTIF('Event Catalogue'!$Q$2:$Q$100,"*"&A8&" *") -> 2
A9: K08 | B9: Reward cost | C9: Total reward value credited, per active user and per completed task. | D9: =COUNTIF('Event Catalogue'!$Q$2:$Q$100,"*"&A9&" *") -> 6
A10: K09 | B10: Reward liability | C10: Pending plus credited-but-unwithdrawn balance owed to users. | D10: =COUNTIF('Event Catalogue'!$Q$2:$Q$100,"*"&A10&" *") -> 6
A11: K10 | B11: Reward reversal rate | C11: Reversed reward value / credited reward value. | D11: =COUNTIF('Event Catalogue'!$Q$2:$Q$100,"*"&A11&" *") -> 4
A12: K11 | B12: Referral conversion | C12: Converted referrals / registered referrals. | D12: =COUNTIF('Event Catalogue'!$Q$2:$Q$100,"*"&A12&" *") -> 5
A13: K12 | B13: Referral cost | C13: Reward spend on referrals per converted referral. | D13: =COUNTIF('Event Catalogue'!$Q$2:$Q$100,"*"&A13&" *") -> 2
... A19: K18 | B19: Ledger reconciliation | C19: Share of rewards and withdrawals matching ledger entries one-to-one. | D19: =COUNTIF('Event Catalogue'!$Q$2:$Q$100,"*"&A19&" *") -> 5

Sheet Coverage Check
A1: Minimum Event | B1: In Catalogue? | C1: Status | D1: Implementation Status
A2: user_registered | B2: =IF(COUNTIF('Event Catalogue'!$C$2:$C$100,A2)=1,"Covered","MISSING") -> Covered | C2: =IFERROR(INDEX('Event Catalogue'!$J$2:$J$100,MATCH(A2,'Event Catalogue'!$C$2:$C$100,0)),"") -> Proposed | D2: =IFERROR(INDEX('Event Catalogue'!$R$2:$R$100,MATCH(A2,'Event Catalogue'!$C$2:$C$100,0)),"") -> Not started
A3: user_logged_in | B3: =IF(COUNTIF('Event Catalogue'!$C$2:$C$100,A3)=1,"Covered","MISSING") -> Covered | C3: =IFERROR(INDEX('Event Catalogue'!$J$2:$J$100,MATCH(A3,'Event Catalogue'!$C$2:$C$100,0)),"") -> Proposed | D3: =IFERROR(INDEX('Event Catalogue'!$R$2:$R$100,MATCH(A3,'Event Catalogue'!$C$2:$C$100,0)),"") -> Not started
A4: user_logged_out | B4: =IF(COUNTIF('Event Catalogue'!$C$2:$C$100,A4)=1,"Covered","MISSING") -> Covered | C4: =IFERROR(INDEX('Event Catalogue'!$J$2:$J$100,MATCH(A4,'Event Catalogue'!$C$2:$C$100,0)),"") -> Proposed - low priority | D4: =IFERROR(INDEX('Event Catalogue'!$R$2:$R$100,MATCH(A4,'Event Catalogue'!$C$2:$C$100,0)),"") -> Not started
A5: onboarding_started | B5: =IF(COUNTIF('Event Catalogue'!$C$2:$C$100,A5)=1,"Covered","MISSING") -> Covered | C5: =IFERROR(INDEX('Event Catalogue'!$J$2:$J$100,MATCH(A5,'Event Catalogue'!$C$2:$C$100,0)),"") -> Proposed | D5: =IFERROR(INDEX('Event Catalogue'!$R$2:$R$100,MATCH(A5,'Event Catalogue'!$C$2:$C$100,0)),"") -> Not started
A6: onboarding_completed | B6: =IF(COUNTIF('Event Catalogue'!$C$2:$C$100,A6)=1,"Covered","MISSING") -> Covered | C6: =IFERROR(INDEX('Event Catalogue'!$J$2:$J$100,MATCH(A6,'Event Catalogue'!$C$2:$C$100,0)),"") -> Proposed | D6: =IFERROR(INDEX('Event Catalogue'!$R$2:$R$100,MATCH(A6,'Event Catalogue'!$C$2:$C$100,0)),"") -> Not started
A7: task_viewed | B7: =IF(COUNTIF('Event Catalogue'!$C$2:$C$100,A7)=1,"Covered","MISSING") -> Covered | C7: =IFERROR(INDEX('Event Catalogue'!$J$2:$J$100,MATCH(A7,'Event Catalogue'!$C$2:$C$100,0)),"") -> Proposed | D7: =IFERROR(INDEX('Event Catalogue'!$R$2:$R$100,MATCH(A7,'Event Catalogue'!$C$2:$C$100,0)),"") -> Not started
A8: task_opened | B8: =IF(COUNTIF('Event Catalogue'!$C$2:$C$100,A8)=1,"Covered","MISSING") -> Covered | C8: =IFERROR(INDEX('Event Catalogue'!$J$2:$J$100,MATCH(A8,'Event Catalogue'!$C$2:$C$100,0)),"") -> Proposed | D8: =IFERROR(INDEX('Event Catalogue'!$R$2:$R$100,MATCH(A8,'Event Catalogue'!$C$2:$C$100,0)),"") -> Not started
A9: task_started | B9: =IF(COUNTIF('Event Catalogue'!$C$2:$C$100,A9)=1,"Covered","MISSING") -> Covered | C9: =IFERROR(INDEX('Event Catalogue'!$J$2:$J$100,MATCH(A9,'Event Catalogue'!$C$2:$C$100,0)),"") -> Proposed | D9: =IFERROR(INDEX('Event Catalogue'!$R$2:$R$100,MATCH(A9,'Event Catalogue'!$C$2:$C$100,0)),"") -> Not started
A10: task_completed | B10: =IF(COUNTIF('Event Catalogue'!$C$2:$C$100,A10)=1,"Covered","MISSING") -> Covered | C10: =IFERROR(INDEX('Event Catalogue'!$J$2:$J$100,MATCH(A10,'Event Catalogue'!$C$2:$C$100,0)),"") -> Proposed | D10: =IFERROR(INDEX('Event Catalogue'!$R$2:$R$100,MATCH(A10,'Event Catalogue'!$C$2:$C$100,0)),"") -> Not started
A11: task_failed | B11: =IF(COUNTIF('Event Catalogue'!$C$2:$C$100,A11)=1,"Covered","MISSING") -> Covered | C11: =IFERROR(INDEX('Event Catalogue'!$J$2:$J$100,MATCH(A11,'Event Catalogue'!$C$2:$C$100,0)),"") -> Proposed | D11: =IFERROR(INDEX('Event Catalogue'!$R$2:$R$100,MATCH(A11,'Event Catalogue'!$C$2:$C$100,0)),"") -> Not started
A12: reward_credited | B12: =IF(COUNTIF('Event Catalogue'!$C$2:$C$100,A12)=1,"Covered","MISSING") -> Covered | C12: =IFERROR(INDEX('Event Catalogue'!$J$2:$J$100,MATCH(A12,'Event Catalogue'!$C$2:$C$100,0)),"") -> Proposed | D12: =IFERROR(INDEX('Event Catalogue'!$R$2:$R$100,MATCH(A12,'Event Catalogue'!$C$2:$C$100,0)),"") -> Not started
A13: reward_pending | B13: =IF(COUNTIF('Event Catalogue'!$C$2:$C$100,A13)=1,"Covered","MISSING") -> Covered | C13: =IFERROR(INDEX('Event Catalogue'!$J$2:$J$100,MATCH(A13,'Event Catalogue'!$C$2:$C$100,0)),"") -> Proposed | D13: =IFERROR(INDEX('Event Catalogue'!$R$2:$R$100,MATCH(A13,'Event Catalogue'!$C$2:$C$100,0)),"") -> Not started
... A33: withdrawal_reversed | B33: =IF(COUNTIF('Event Catalogue'!$C$2:$C$100,A33)=1,"Covered","MISSING") -> Covered | C33: =IFERROR(INDEX('Event Catalogue'!$J$2:$J$100,MATCH(A33,'Event Catalogue'!$C$2:$C$100,0)),"") -> Proposed | D33: =IFERROR(INDEX('Event Catalogue'!$R$2:$R$100,MATCH(A33,'Event Catalogue'!$C$2:$C$100,0)),"") -> Not started
A35: Minimum events required | B35: =COUNTA(A2:A33) -> 32
A36: Minimum events covered | B36: =COUNTIF(B2:B33,"Covered") -> 32
A37: Total events in catalogue | B37: =COUNTA('Event Catalogue'!$C$2:$C$100) -> 39
A38: Analyst-added events | B38: =COUNTIF('Event Catalogue'!$D$2:$D$100,"Analyst-added") -> 7
A39: Conditional events (confirm feature exists) | B39: =COUNTIF('Event Catalogue'!$J$2:$J$100,"Proposed - confirm feature exists") -> 9
A40: Duplicate event names | B40: =SUMPRODUCT(('Event Catalogue'!$C$2:$C$100<>"")*(COUNTIF('Event Catalogue'!$C$2:$C$100,'Event Catalogue'!$C$2:$C$100)>1)) -> 0
A41: Names failing naming standard | B41: =COUNTIF('Event Catalogue'!$S$2:$S$100,"CHECK") -> 0
A42: Events still Not started | B42: =COUNTIF('Event Catalogue'!$R$2:$R$100,"Not started") -> 39
A43: Overall coverage result | B43: =IF(AND(B36=B35,B40=0,B41=0),"PASS","FAIL") -> PASS
