Workbook

Sheet README
A1: Work Package D - Wallet & Withdrawal Analytics (VELOOP)
A3: Purpose | B3: A transaction model and KPI set that lets VELOOP understand wallet movements and the withdrawal lifecycle.
A4: Wallet flow | B4: Reward Credit (+) | Redemption (-) | Reversal (undoes a prior entry) | Adjustment (+/-) - other types are marked PROPOSED.
A5: Withdrawal flow | B5: Requested -> Under Review / Processing -> Completed. Alternative end states: Rejected, Reversed (Cancelled = Proposed).
A7: SHEETS
A8: KPI_Dashboard | B8: Live KPIs vs targets: status counts, rates, processing times, pending queue, volume, method and reason mix, wallet KPIs, data-quality checks, charts.
A9: Withdrawals | B9: D2 - one row per withdrawal with timestamps, status, reason and calculated times / checks.
A10: Wallet_Transactions | B10: D1 - one row per ledger entry incl. reversal / correction links and automatic validation.
A11: Wallet_Balances | B11: Balance per user from Posted entries, plus pending withdrawal exposure.
A12: Daily_Operations | B12: Daily requests, completions, backlog, credits, redemptions and charts.
A13: Transaction_Types | B13: Catalogue of transaction types with Supported / Proposed status and direction.
A14: Withdrawal_Lifecycle | B14: State model, allowed transitions, reason categories and methods (all with Supported / Proposed marking).
A15: Settings | B15: As-of time, base unit, SLA, thresholds, targets and the wallet-debit timing assumption.
A16: D1 / D2 Data Dictionary | B16: Field definitions and rules for the wallet and withdrawal models.
A17: D3_KPI_Definitions | B17: Every KPI with Name, Definition, Formula, Data Required, Source, Frequency, Stakeholder Purpose, Limitation, live value.
A19: HOW TO USE
A20: 1 | B20: Replace the sample rows in Withdrawals and Wallet_Transactions (blue) with real data. All sample data is invented for illustration.
A21: 2 | B21: Copy the grey formula cells down for new rows. Summary formulas read to row 1000 (withdrawals) and 3000 (transactions).
A22: 3 | B22: Confirm the yellow assumptions in Settings and Transaction_Types, then change Proposed items to Supported once verified with Product / Engineering.
A23: 4 | B23: Update the As-of Timestamp on each refresh; extend Daily_Operations if the period exceeds 45 days; add users to Wallet_Balances.
A24: 5 | B24: Keep section 8 of the dashboard at 0 flags - these catch missing links, bad signs, wrong timestamps and wallet / withdrawal mismatches.
A26: KEY ASSUMPTIONS
A27: A | B27: I could not verify which transaction types, methods or reason categories exist in VELOOP. The four core types are marked Supported as an assumption; everything else is Proposed.
A28: B | B28: One base unit (Points) is used for all amounts; the currency conversion is illustrative.
A29: C | B29: The wallet is debited (Redemption) when a withdrawal is Completed; Rejected, pending and cancelled withdrawals have no wallet movement.
A30: D | B30: Targets, SLA hours and thresholds are placeholders, not benchmarks.
A32: COLOR LEGEND
A33: Blue text | B33: Input data / assumptions you can edit.
A34: Black text | B34: Formulas - do not overwrite.
A35: Green text | B35: Link pulled from another sheet.
A36: Yellow fill | B36: Assumption to confirm.
A37: Orange fill | B37: Proposed item - not confirmed as existing in VELOOP.

Sheet KPI_Dashboard
A1: Wallet & Withdrawal KPI Dashboard
A2: As-of: | B2: =Settings!B5 -> 46310.75
A4: 1. WITHDRAWAL LIFECYCLE - STATUS COUNTS | B4: Count | C4: % of Requests | D4: Amount (Base Unit) | E4: Notes
A5: Requested | B5: =COUNTIF(Withdrawals!$I$5:$I$1000,$A5) -> 0 | C5: =IFERROR(B5/$B$12,0) -> 0 | D5: =SUMIFS(Withdrawals!$C$5:$C$1000,Withdrawals!$I$5:$I$1000,$A5,Withdrawals!$D$5:$D$1000,Settings!$B$6) -> 0 | E5: Open: submitted, review not started.
A6: Under Review | B6: =COUNTIF(Withdrawals!$I$5:$I$1000,$A6) -> 9 | C6: =IFERROR(B6/$B$12,0) -> 0.1875 | D6: =SUMIFS(Withdrawals!$C$5:$C$1000,Withdrawals!$I$5:$I$1000,$A6,Withdrawals!$D$5:$D$1000,Settings!$B$6) -> 8600 | E6: Open: checks in progress.
A7: Processing | B7: =COUNTIF(Withdrawals!$I$5:$I$1000,$A7) -> 2 | C7: =IFERROR(B7/$B$12,0) -> 0.041666667 | D7: =SUMIFS(Withdrawals!$C$5:$C$1000,Withdrawals!$I$5:$I$1000,$A7,Withdrawals!$D$5:$D$1000,Settings!$B$6) -> 1500 | E7: Open: payout in progress.
A8: Completed | B8: =COUNTIF(Withdrawals!$I$5:$I$1000,$A8) -> 29 | C8: =IFERROR(B8/$B$12,0) -> 0.60416667 | D8: =SUMIFS(Withdrawals!$C$5:$C$1000,Withdrawals!$I$5:$I$1000,$A8,Withdrawals!$D$5:$D$1000,Settings!$B$6) -> 29650 | E8: Final: paid out and not reversed.
A9: Rejected | B9: =COUNTIF(Withdrawals!$I$5:$I$1000,$A9) -> 5 | C9: =IFERROR(B9/$B$12,0) -> 0.10416667 | D9: =SUMIFS(Withdrawals!$C$5:$C$1000,Withdrawals!$I$5:$I$1000,$A9,Withdrawals!$D$5:$D$1000,Settings!$B$6) -> 6450 | E9: Final: denied.
A10: Reversed | B10: =COUNTIF(Withdrawals!$I$5:$I$1000,$A10) -> 1 | C10: =IFERROR(B10/$B$12,0) -> 0.020833333 | D10: =SUMIFS(Withdrawals!$C$5:$C$1000,Withdrawals!$I$5:$I$1000,$A10,Withdrawals!$D$5:$D$1000,Settings!$B$6) -> 550 | E10: Final: paid then undone.
A11: Cancelled | B11: =COUNTIF(Withdrawals!$I$5:$I$1000,$A11) -> 2 | C11: =IFERROR(B11/$B$12,0) -> 0.041666667 | D11: =SUMIFS(Withdrawals!$C$5:$C$1000,Withdrawals!$I$5:$I$1000,$A11,Withdrawals!$D$5:$D$1000,Settings!$B$6) -> 3350 | E11: Final: PROPOSED state - user cancelled.
A12: Total Requests | B12: =COUNTA(Withdrawals!$A$5:$A$1000) -> 48 | C12: =IFERROR(SUM(C5:C11),0) -> 1 | D12: =SUM(D5:D11) -> 50100 | E12: Every request is in exactly one status.
A13: Check: sum of statuses minus total (should be 0) | B13: =SUM(B5:B11)-B12 -> 0
A15: 2. WITHDRAWAL KPIs vs TARGET | B15: Value | C15: Target | D15: Status | E15: Definition
A16: Withdrawal Requests | B16: =B12 -> 48 | E16: All requests created.
A17: Completed Withdrawals | B17: =B8 -> 29 | E17: Status = Completed (reversed ones are excluded).
A18: Pending Withdrawals (queue) | B18: =B5+B6+B7 -> 11 | E18: Requested + Under Review + Processing.
A19: Rejected Withdrawals | B19: =B9 -> 5 | E19: Status = Rejected.
A20: Reversed Withdrawals | B20: =B10 -> 1 | E20: Status = Reversed.
A21: Completion Rate | B21: =IFERROR(B17/B16,0) -> 0.60416667 | C21: =Settings!B13 -> 0.8 | D21: =IF(B21>=C21,"On track","Below target") -> Below target | E21: Completed / all requests.
A22: Completion Rate of Resolved Requests | B22: =IFERROR(B17/(B17+B19+B20),0) -> 0.82857143 | E22: Completed / (Completed + Rejected + Reversed). Ignores pending and cancelled.
A23: Rejection Rate | B23: =IFERROR(B19/B16,0) -> 0.10416667 | C23: =Settings!B14 -> 0.15 | D23: =IF(B23<=C23,"On track","Above target") -> On track | E23: Rejected / all requests.
A24: Reversal Rate | B24: =IFERROR(B20/(B17+B20),0) -> 0.033333333 | C24: =Settings!B15 -> 0.03 | D24: =IF(B24<=C24,"On track","Above target") -> Above target | E24: Reversed / (Completed + Reversed): share of payouts later undone.
A25: SLA Compliance | B25: =IFERROR(COUNTIF(Withdrawals!$P$5:$P$1000,"Yes")/B17,0) -> 0.65517241 | C25: =Settings!B16 -> 0.9 | D25: =IF(B25>=C25,"On track","Below target") -> Below target | E25: Completed within SLA hours / Completed.
A26: Avg End-to-End Processing Time (hrs) | B26: =IFERROR(AVERAGE(Withdrawals!$O$5:$O$1000),0) -> 44.364422 | C26: =Settings!B17 -> 36 | D26: =IF(B26<=C26,"On track","Above target") -> Above target | E26: Requested to Final, Completed only.
A27: Median End-to-End Time (hrs) | B27: =IFERROR(MEDIAN(Withdrawals!$O$5:$O$1000),0) -> 43.718908 | E27: Less sensitive to outliers than the average.
A28: P90 End-to-End Time (hrs) | B28: =IFERROR(PERCENTILE(Withdrawals!$O$5:$O$1000,0.9),0) -> 71.223395 | E28: 9 in 10 completed withdrawals finish within this time.
A29: Avg Queue Wait (hrs) | B29: =IFERROR(AVERAGE(Withdrawals!$M$5:$M$1000),0) -> 12.818641 | E29: Requested to Processing start, all requests that started.
A30: Avg Processing Time (hrs) | B30: =IFERROR(AVERAGE(Withdrawals!$N$5:$N$1000),0) -> 30.078528 | E30: Processing start to Final, Completed only.
A31: Avg Time to Rejection (hrs) | B31: =IFERROR(AVERAGE(Withdrawals!$Q$5:$Q$1000),0) -> 32.344435 | E31: Requested to Final, Rejected only.
A33: 3. PENDING QUEUE | B33: Value | C33: Target | D33: Status | E33: Definition
A34: Pending Count | B34: =B18 -> 11 | E34: Open requests right now.
A35: Pending Amount (Base Unit) | B35: =D5+D6+D7 -> 10100 | E35: Sum of requested amounts still open.
A36: Oldest Pending Age (hrs) | B36: =IFERROR(MAX(Withdrawals!$R$5:$R$1000),0) -> 217.98333 | E36: Age of the longest-waiting open request at the as-of time.
A37: Average Pending Age (hrs) | B37: =IFERROR(AVERAGE(Withdrawals!$R$5:$R$1000),0) -> 77.360125 | E37: Mean age of open requests.
A38: Aged Pending (> threshold) | B38: =COUNTIF(Withdrawals!$R$5:$R$1000,">"&Settings!B9) -> 4 | C38: =Settings!B18 -> 0 | D38: =IF(B38<=C38,"On track","Above target") -> Above target | E38: Open requests older than the aged-pending threshold.
A40: 4. WITHDRAWAL VOLUME | B40: Base Unit | C40: Currency Equivalent | D40: % of Requested | E40: Definition
A41: Requested Volume | B41: =SUMIFS(Withdrawals!$C$5:$C$1000,Withdrawals!$D$5:$D$1000,Settings!$B$6) -> 50100 | C41: =B41*Settings!$B$7 -> 501 | E41: All requested amounts.
A42: Completed Volume | B42: =D8 -> 29650 | C42: =B42*Settings!$B$7 -> 296.5 | D42: =IFERROR(B42/$B$41,0) -> 0.59181637 | E42: Paid out and not reversed.
A43: Pending Volume | B43: =D5+D6+D7 -> 10100 | C43: =B43*Settings!$B$7 -> 101 | D43: =IFERROR(B43/$B$41,0) -> 0.20159681 | E43: Open requests.
A44: Rejected Volume | B44: =D9 -> 6450 | C44: =B44*Settings!$B$7 -> 64.5 | D44: =IFERROR(B44/$B$41,0) -> 0.12874251 | E44: Denied requests.
...

Sheet Withdrawals
A1: Withdrawals (D2) - one row per withdrawal request
A2: Blue = input (replace sample rows with real data). Grey = formulas (copy down for new rows). Rule: Processing Timestamp = when review/payout work started; Final Timestamp = when a terminal state (Completed / Rejected / Reversed / Cancelled) was reached.
A4: Withdrawal ID | B4: User ID | C4: Requested Amount | D4: Unit | E4: Method | F4: Requested Timestamp | G4: Processing Timestamp | H4: Final Timestamp | I4: Status | J4: Reason Category | K4: Data Check | L4: Is Pending (1/0) | M4: Queue Wait Hrs (Requested to Processing) | N4: Processing Hrs (Processing to Final, Completed) | O4: End-to-End Hrs (Requested to Final, Completed) | P4: SLA Met? (Completed) | Q4: Hrs to Rejection (Rejected) | R4: Pending Age Hrs (as-of) | S4: First Request of User (1/0) | T4: Wallet Reconciliation
A5: WD-0001 | B5: U002 | C5: 800 | D5: Points | E5: E-Wallet | F5: 46270.307 | G5: 46271.061 | H5: 46272.148 | I5: Completed | K5: =IF(ISNA(MATCH(I5,Withdrawal_Lifecycle!$A$5:$A$11,0)),"CHECK status",IF(AND(I5="Requested",OR(G5<>"",H5<>"")),"CHECK timestamps",IF(AND(OR(I5="Under Review",I5="Processing"),OR(G5="",H5<>"")),"CHECK timestamps",IF(AND(OR(I5="Completed",I5="Reversed",I5="Rejected"),OR(G5="",H5="")),"CHECK timestamps",IF(AND(I5="Cancelled",H5=""),"CHECK timestamps",IF(OR(AND(G5<>"",G5<F5),AND(H5<>"",H5<IF(G5<>"",G5,F5))),"CHECK order",IF(AND(OR(I5="Rejected",I5="Reversed"),J5=""),"CHECK reason","OK"))))))) -> OK | L5: =IF(OR(I5="Requested",I5="Under Review",I5="Processing"),1,0) -> 0 | M5: =IF(G5="","",(G5-F5)*24) -> 18.085751 | N5: =IF(AND(I5="Completed",G5<>"",H5<>""),(H5-G5)*24,"") -> 26.092326 | O5: =IF(AND(I5="Completed",H5<>""),(H5-F5)*24,"") -> 44.178077 | P5: =IF(O5="","",IF(O5<=Settings!$B$8,"Yes","No")) -> Yes | Q5: =IF(AND(I5="Rejected",H5<>""),(H5-F5)*24,"") | R5: =IF(L5=1,(Settings!$B$5-F5)*24,"") | S5: =IF(COUNTIF($B$5:B5,B5)=1,1,0) -> 1 | T5: =IF(I5="Completed",IF(COUNTIFS(Wallet_Transactions!$I$5:$I$3000,A5,Wallet_Transactions!$D$5:$D$3000,"Redemption",Wallet_Transactions!$G$5:$G$3000,"Posted")>=1,"OK","CHECK no debit"),IF(I5="Reversed",IF(AND(COUNTIFS(Wallet_Transactions!$I$5:$I$3000,A5,Wallet_Transactions!$D$5:$D$3000,"Redemption",Wallet_Transactions!$G$5:$G$3000,"Posted")>=1,COUNTIFS(Wallet_Transactions!$I$5:$I$3000,A5,Wallet_Transactions!$D$5:$D$3000,"Reversal",Wallet_Transactions!$G$5:$G$3000,"Posted")>=1),"OK","CHECK no reversal"),IF(COUNTIFS(Wallet_Transactions!$I$5:$I$3000,A5,Wallet_Transactions!$D$5:$D$3000,"Redemption",Wallet_Transactions!$G$5:$G$3000,"Posted")>0,"CHECK unexpected debit","OK"))) -> OK
A6: WD-0002 | B6: U006 | C6: 1100 | D6: Points | E6: Bank Transfer | F6: 46271.551 | G6: 46272.447 | H6: 46273.29 | I6: Completed | K6: =IF(ISNA(MATCH(I6,Withdrawal_Lifecycle!$A$5:$A$11,0)),"CHECK status",IF(AND(I6="Requested",OR(G6<>"",H6<>"")),"CHECK timestamps",IF(AND(OR(I6="Under Review",I6="Processing"),OR(G6="",H6<>"")),"CHECK timestamps",IF(AND(OR(I6="Completed",I6="Reversed",I6="Rejected"),OR(G6="",H6="")),"CHECK timestamps",IF(AND(I6="Cancelled",H6=""),"CHECK timestamps",IF(OR(AND(G6<>"",G6<F6),AND(H6<>"",H6<IF(G6<>"",G6,F6))),"CHECK order",IF(AND(OR(I6="Rejected",I6="Reversed"),J6=""),"CHECK reason","OK"))))))) -> OK | L6: =IF(OR(I6="Requested",I6="Under Review",I6="Processing"),1,0) -> 0 | M6: =IF(G6="","",(G6-F6)*24) -> 21.505025 | N6: =IF(AND(I6="Completed",G6<>"",H6<>""),(H6-G6)*24,"") -> 20.223598 | O6: =IF(AND(I6="Completed",H6<>""),(H6-F6)*24,"") -> 41.728623 | P6: =IF(O6="","",IF(O6<=Settings!$B$8,"Yes","No")) -> Yes | Q6: =IF(AND(I6="Rejected",H6<>""),(H6-F6)*24,"") | R6: =IF(L6=1,(Settings!$B$5-F6)*24,"") | S6: =IF(COUNTIF($B$5:B6,B6)=1,1,0) -> 1 | T6: =IF(I6="Completed",IF(COUNTIFS(Wallet_Transactions!$I$5:$I$3000,A6,Wallet_Transactions!$D$5:$D$3000,"Redemption",Wallet_Transactions!$G$5:$G$3000,"Posted")>=1,"OK","CHECK no debit"),IF(I6="Reversed",IF(AND(COUNTIFS(Wallet_Transactions!$I$5:$I$3000,A6,Wallet_Transactions!$D$5:$D$3000,"Redemption",Wallet_Transactions!$G$5:$G$3000,"Posted")>=1,COUNTIFS(Wallet_Transactions!$I$5:$I$3000,A6,Wallet_Transactions!$D$5:$D$3000,"Reversal",Wallet_Transactions!$G$5:$G$3000,"Posted")>=1),"OK","CHECK no reversal"),IF(COUNTIFS(Wallet_Transactions!$I$5:$I$3000,A6,Wallet_Transactions!$D$5:$D$3000,"Redemption",Wallet_Transactions!$G$5:$G$3000,"Posted")>0,"CHECK unexpected debit","OK"))) -> OK
A7: WD-0003 | B7: U003 | C7: 1950 | D7: Points | E7: E-Wallet | F7: 46273.069 | G7: 46273.324 | H7: 46274.984 | I7: Completed | K7: =IF(ISNA(MATCH(I7,Withdrawal_Lifecycle!$A$5:$A$11,0)),"CHECK status",IF(AND(I7="Requested",OR(G7<>"",H7<>"")),"CHECK timestamps",IF(AND(OR(I7="Under Review",I7="Processing"),OR(G7="",H7<>"")),"CHECK timestamps",IF(AND(OR(I7="Completed",I7="Reversed",I7="Rejected"),OR(G7="",H7="")),"CHECK timestamps",IF(AND(I7="Cancelled",H7=""),"CHECK timestamps",IF(OR(AND(G7<>"",G7<F7),AND(H7<>"",H7<IF(G7<>"",G7,F7))),"CHECK order",IF(AND(OR(I7="Rejected",I7="Reversed"),J7=""),"CHECK reason","OK"))))))) -> OK | L7: =IF(OR(I7="Requested",I7="Under Review",I7="Processing"),1,0) -> 0 | M7: =IF(G7="","",(G7-F7)*24) -> 6.1251639 | N7: =IF(AND(I7="Completed",G7<>"",H7<>""),(H7-G7)*24,"") -> 39.843158 | O7: =IF(AND(I7="Completed",H7<>""),(H7-F7)*24,"") -> 45.968322 | P7: =IF(O7="","",IF(O7<=Settings!$B$8,"Yes","No")) -> Yes | Q7: =IF(AND(I7="Rejected",H7<>""),(H7-F7)*24,"") | R7: =IF(L7=1,(Settings!$B$5-F7)*24,"") | S7: =IF(COUNTIF($B$5:B7,B7)=1,1,0) -> 1 | T7: =IF(I7="Completed",IF(COUNTIFS(Wallet_Transactions!$I$5:$I$3000,A7,Wallet_Transactions!$D$5:$D$3000,"Redemption",Wallet_Transactions!$G$5:$G$3000,"Posted")>=1,"OK","CHECK no debit"),IF(I7="Reversed",IF(AND(COUNTIFS(Wallet_Transactions!$I$5:$I$3000,A7,Wallet_Transactions!$D$5:$D$3000,"Redemption",Wallet_Transactions!$G$5:$G$3000,"Posted")>=1,COUNTIFS(Wallet_Transactions!$I$5:$I$3000,A7,Wallet_Transactions!$D$5:$D$3000,"Reversal",Wallet_Transactions!$G$5:$G$3000,"Posted")>=1),"OK","CHECK no reversal"),IF(COUNTIFS(Wallet_Transactions!$I$5:$I$3000,A7,Wallet_Transactions!$D$5:$D$3000,"Redemption",Wallet_Transactions!$G$5:$G$3000,"Posted")>0,"CHECK unexpected debit","OK"))) -> OK
A8: WD-0004 | B8: U015 | C8: 550 | D8: Points | E8: Other | F8: 46274.96 | G8: 46275.873 | H8: 46277.984 | I8: Completed | K8: =IF(ISNA(MATCH(I8,Withdrawal_Lifecycle!$A$5:$A$11,0)),"CHECK status",IF(AND(I8="Requested",OR(G8<>"",H8<>"")),"CHECK timestamps",IF(AND(OR(I8="Under Review",I8="Processing"),OR(G8="",H8<>"")),"CHECK timestamps",IF(AND(OR(I8="Completed",I8="Reversed",I8="Rejected"),OR(G8="",H8="")),"CHECK timestamps",IF(AND(I8="Cancelled",H8=""),"CHECK timestamps",IF(OR(AND(G8<>"",G8<F8),AND(H8<>"",H8<IF(G8<>"",G8,F8))),"CHECK order",IF(AND(OR(I8="Rejected",I8="Reversed"),J8=""),"CHECK reason","OK"))))))) -> OK | L8: =IF(OR(I8="Requested",I8="Under Review",I8="Processing"),1,0) -> 0 | M8: =IF(G8="","",(G8-F8)*24) -> 21.898631 | N8: =IF(AND(I8="Completed",G8<>"",H8<>""),(H8-G8)*24,"") -> 50.669366 | O8: =IF(AND(I8="Completed",H8<>""),(H8-F8)*24,"") -> 72.567997 | P8: =IF(O8="","",IF(O8<=Settings!$B$8,"Yes","No")) -> No | Q8: =IF(AND(I8="Rejected",H8<>""),(H8-F8)*24,"") | R8: =IF(L8=1,(Settings!$B$5-F8)*24,"") | S8: =IF(COUNTIF($B$5:B8,B8)=1,1,0) -> 1 | T8: =IF(I8="Completed",IF(COUNTIFS(Wallet_Transactions!$I$5:$I$3000,A8,Wallet_Transactions!$D$5:$D$3000,"Redemption",Wallet_Transactions!$G$5:$G$3000,"Posted")>=1,"OK","CHECK no debit"),IF(I8="Reversed",IF(AND(COUNTIFS(Wallet_Transactions!$I$5:$I$3000,A8,Wallet_Transactions!$D$5:$D$3000,"Redemption",Wallet_Transactions!$G$5:$G$3000,"Posted")>=1,COUNTIFS(Wallet_Transactions!$I$5:$I$3000,A8,Wallet_Transactions!$D$5:$D$3000,"Reversal",Wallet_Transactions!$G$5:$G$3000,"Posted")>=1),"OK","CHECK no reversal"),IF(COUNTIFS(Wallet_Transactions!$I$5:$I$3000,A8,Wallet_Transactions!$D$5:$D$3000,"Redemption",Wallet_Transactions!$G$5:$G$3000,"Posted")>0,"CHECK unexpected debit","OK"))) -> OK
A9: WD-0005 | B9: U015 | C9: 750 | D9: Points | E9: Bank Transfer | F9: 46278.524 | G9: 46278.641 | H9: 46278.92 | I9: Completed | K9: =IF(ISNA(MATCH(I9,Withdrawal_Lifecycle!$A$5:$A$11,0)),"CHECK status",IF(AND(I9="Requested",OR(G9<>"",H9<>"")),"CHECK timestamps",IF(AND(OR(I9="Under Review",I9="Processing"),OR(G9="",H9<>"")),"CHECK timestamps",IF(AND(OR(I9="Completed",I9="Reversed",I9="Rejected"),OR(G9="",H9="")),"CHECK timestamps",IF(AND(I9="Cancelled",H9=""),"CHECK timestamps",IF(OR(AND(G9<>"",G9<F9),AND(H9<>"",H9<IF(G9<>"",G9,F9))),"CHECK order",IF(AND(OR(I9="Rejected",I9="Reversed"),J9=""),"CHECK reason","OK"))))))) -> OK | L9: =IF(OR(I9="Requested",I9="Under Review",I9="Processing"),1,0) -> 0 | M9: =IF(G9="","",(G9-F9)*24) -> 2.8081394 | N9: =IF(AND(I9="Completed",G9<>"",H9<>""),(H9-G9)*24,"") -> 6.6842523 | O9: =IF(AND(I9="Completed",H9<>""),(H9-F9)*24,"") -> 9.4923917 | P9: =IF(O9="","",IF(O9<=Settings!$B$8,"Yes","No")) -> Yes | Q9: =IF(AND(I9="Rejected",H9<>""),(H9-F9)*24,"") | R9: =IF(L9=1,(Settings!$B$5-F9)*24,"") | S9: =IF(COUNTIF($B$5:B9,B9)=1,1,0) -> 0 | T9: =IF(I9="Completed",IF(COUNTIFS(Wallet_Transactions!$I$5:$I$3000,A9,Wallet_Transactions!$D$5:$D$3000,"Redemption",Wallet_Transactions!$G$5:$G$3000,"Posted")>=1,"OK","CHECK no debit"),IF(I9="Reversed",IF(AND(COUNTIFS(Wallet_Transactions!$I$5:$I$3000,A9,Wallet_Transactions!$D$5:$D$3000,"Redemption",Wallet_Transactions!$G$5:$G$3000,"Posted")>=1,COUNTIFS(Wallet_Transactions!$I$5:$I$3000,A9,Wallet_Transactions!$D$5:$D$3000,"Reversal",Wallet_Transactions!$G$5:$G$3000,"Posted")>=1),"OK","CHECK no reversal"),IF(COUNTIFS(Wallet_Transactions!$I$5:$I$3000,A9,Wallet_Transactions!$D$5:$D$3000,"Redemption",Wallet_Transactions!$G$5:$G$3000,"Posted")>0,"CHECK unexpected debit","OK"))) -> OK
A10: WD-0006 | B10: U004 | C10: 1350 | D10: Points | E10: Bank Transfer | F10: 46278.826 | H10: 46279.005 | I10: Cancelled | J10: User Request | K10: =IF(ISNA(MATCH(I10,Withdrawal_Lifecycle!$A$5:$A$11,0)),"CHECK status",IF(AND(I10="Requested",OR(G10<>"",H10<>"")),"CHECK timestamps",IF(AND(OR(I10="Under Review",I10="Processing"),OR(G10="",H10<>"")),"CHECK timestamps",IF(AND(OR(I10="Completed",I10="Reversed",I10="Rejected"),OR(G10="",H10="")),"CHECK timestamps",IF(AND(I10="Cancelled",H10=""),"CHECK timestamps",IF(OR(AND(G10<>"",G10<F10),AND(H10<>"",H10<IF(G10<>"",G10,F10))),"CHECK order",IF(AND(OR(I10="Rejected",I10="Reversed"),J10=""),"CHECK reason","OK"))))))) -> OK | L10: =IF(OR(I10="Requested",I10="Under Review",I10="Processing"),1,0) -> 0 | M10: =IF(G10="","",(G10-F10)*24) | N10: =IF(AND(I10="Completed",G10<>"",H10<>""),(H10-G10)*24,"") | O10: =IF(AND(I10="Completed",H10<>""),(H10-F10)*24,"") | P10: =IF(O10="","",IF(O10<=Settings!$B$8,"Yes","No")) | Q10: =IF(AND(I10="Rejected",H10<>""),(H10-F10)*24,"") | R10: =IF(L10=1,(Settings!$B$5-F10)*24,"") | S10: =IF(COUNTIF($B$5:B10,B10)=1,1,0) -> 1 | T10: =IF(I10="Completed",IF(COUNTIFS(Wallet_Transactions!$I$5:$I$3000,A10,Wallet_Transactions!$D$5:$D$3000,"Redemption",Wallet_Transactions!$G$5:$G$3000,"Posted")>=1,"OK","CHECK no debit"),IF(I10="Reversed",IF(AND(COUNTIFS(Wallet_Transactions!$I$5:$I$3000,A10,Wallet_Transactions!$D$5:$D$3000,"Redemption",Wallet_Transactions!$G$5:$G$3000,"Posted")>=1,COUNTIFS(Wallet_Transactions!$I$5:$I$3000,A10,Wallet_Transactions!$D$5:$D$3000,"Reversal",Wallet_Transactions!$G$5:$G$3000,"Posted")>=1),"OK","CHECK no reversal"),IF(COUNTIFS(Wallet_Transactions!$I$5:$I$3000,A10,Wallet_Transactions!$D$5:$D$3000,"Redemption",Wallet_Transactions!$G$5:$G$3000,"Posted")>0,"CHECK unexpected debit","OK"))) -> OK
A11: WD-0007 | B11: U010 | C11: 1800 | D11: Points | E11: E-Wallet | F11: 46279.015 | G11: 46279.143 | H11: 46280.331 | I11: Rejected | J11: Verification Failed | K11: =IF(ISNA(MATCH(I11,Withdrawal_Lifecycle!$A$5:$A$11,0)),"CHECK status",IF(AND(I11="Requested",OR(G11<>"",H11<>"")),"CHECK timestamps",IF(AND(OR(I11="Under Review",I11="Processing"),OR(G11="",H11<>"")),"CHECK timestamps",IF(AND(OR(I11="Completed",I11="Reversed",I11="Rejected"),OR(G11="",H11="")),"CHECK timestamps",IF(AND(I11="Cancelled",H11=""),"CHECK timestamps",IF(OR(AND(G11<>"",G11<F11),AND(H11<>"",H11<IF(G11<>"",G11,F11))),"CHECK order",IF(AND(OR(I11="Rejected",I11="Reversed"),J11=""),"CHECK reason","OK"))))))) -> OK | L11: =IF(OR(I11="Requested",I11="Under Review",I11="Processing"),1,0) -> 0 | M11: =IF(G11="","",(G11-F11)*24) -> 3.0889277 | N11: =IF(AND(I11="Completed",G11<>"",H11<>""),(H11-G11)*24,"") | O11: =IF(AND(I11="Completed",H11<>""),(H11-F11)*24,"") | P11: =IF(O11="","",IF(O11<=Settings!$B$8,"Yes","No")) | Q11: =IF(AND(I11="Rejected",H11<>""),(H11-F11)*24,"") -> 31.593931 | R11: =IF(L11=1,(Settings!$B$5-F11)*24,"") | S11: =IF(COUNTIF($B$5:B11,B11)=1,1,0) -> 1 | T11: =IF(I11="Completed",IF(COUNTIFS(Wallet_Transactions!$I$5:$I$3000,A11,Wallet_Transactions!$D$5:$D$3000,"Redemption",Wallet_Transactions!$G$5:$G$3000,"Posted")>=1,"OK","CHECK no debit"),IF(I11="Reversed",IF(AND(COUNTIFS(Wallet_Transactions!$I$5:$I$3000,A11,Wallet_Transactions!$D$5:$D$3000,"Redemption",Wallet_Transactions!$G$5:$G$3000,"Posted")>=1,COUNTIFS(Wallet_Transactions!$I$5:$I$3000,A11,Wallet_Transactions!$D$5:$D$3000,"Reversal",Wallet_Transactions!$G$5:$G$3000,"Posted")>=1),"OK","CHECK no reversal"),IF(COUNTIFS(Wallet_Transactions!$I$5:$I$3000,A11,Wallet_Transactions!$D$5:$D$3000,"Redemption",Wallet_Transactions!$G$5:$G$3000,"Posted")>0,"CHECK unexpected debit","OK"))) -> OK
A12: WD-0008 | B12: U015 | C12: 800 | D12: Points | E12: E-Wallet | F12: 46279.121 | G12: 46280.048 | H12: 46281.278 | I12: Completed | K12: =IF(ISNA(MATCH(I12,Withdrawal_Lifecycle!$A$5:$A$11,0)),"CHECK status",IF(AND(I12="Requested",OR(G12<>"",H12<>"")),"CHECK timestamps",IF(AND(OR(I12="Under Review",I12="Processing"),OR(G12="",H12<>"")),"CHECK timestamps",IF(AND(OR(I12="Completed",I12="Reversed",I12="Rejected"),OR(G12="",H12="")),"CHECK timestamps",IF(AND(I12="Cancelled",H12=""),"CHECK timestamps",IF(OR(AND(G12<>"",G12<F12),AND(H12<>"",H12<IF(G12<>"",G12,F12))),"CHECK order",IF(AND(OR(I12="Rejected",I12="Reversed"),J12=""),"CHECK reason","OK"))))))) -> OK | L12: =IF(OR(I12="Requested",I12="Under Review",I12="Processing"),1,0) -> 0 | M12: =IF(G12="","",(G12-F12)*24) -> 22.250934 | N12: =IF(AND(I12="Completed",G12<>"",H12<>""),(H12-G12)*24,"") -> 29.522992 | O12: =IF(AND(I12="Completed",H12<>""),(H12-F12)*24,"") -> 51.773926 | P12: =IF(O12="","",IF(O12<=Settings!$B$8,"Yes","No")) -> No | Q12: =IF(AND(I12="Rejected",H12<>""),(H12-F12)*24,"") | R12: =IF(L12=1,(Settings!$B$5-F12)*24,"") | S12: =IF(COUNTIF($B$5:B12,B12)=1,1,0) -> 0 | T12: =IF(I12="Completed",IF(COUNTIFS(Wallet_Transactions!$I$5:$I$3000,A12,Wallet_Transactions!$D$5:$D$3000,"Redemption",Wallet_Transactions!$G$5:$G$3000,"Posted")>=1,"OK","CHECK no debit"),IF(I12="Reversed",IF(AND(COUNTIFS(Wallet_Transactions!$I$5:$I$3000,A12,Wallet_Transactions!$D$5:$D$3000,"Redemption",Wallet_Transactions!$G$5:$G$3000,"Posted")>=1,COUNTIFS(Wallet_Transactions!$I$5:$I$3000,A12,Wallet_Transactions!$D$5:$D$3000,"Reversal",Wallet_Transactions!$G$5:$G$3000,"Posted")>=1),"OK","CHECK no reversal"),IF(COUNTIFS(Wallet_Transactions!$I$5:$I$3000,A12,Wallet_Transactions!$D$5:$D$3000,"Redemption",Wallet_Transactions!$G$5:$G$3000,"Posted")>0,"CHECK unexpected debit","OK"))) -> OK
A13: WD-0009 | B13: U008 | C13: 1750 | D13: Points | E13: E-Wallet | F13: 46279.34 | G13: 46279.858 | H13: 46280.849 | I13: Completed | K13: =IF(ISNA(MATCH(I13,Withdrawal_Lifecycle!$A$5:$A$11,0)),"CHECK status",IF(AND(I13="Requested",OR(G13<>"",H13<>"")),"CHECK timestamps",IF(AND(OR(I13="Under Review",I13="Processing"),OR(G13="",H13<>"")),"CHECK timestamps",IF(AND(OR(I13="Completed",I13="Reversed",I13="Rejected"),OR(G13="",H13="")),"CHECK timestamps",IF(AND(I13="Cancelled",H13=""),"CHECK timestamps",IF(OR(AND(G13<>"",G13<F13),AND(H13<>"",H13<IF(G13<>"",G13,F13))),"CHECK order",IF(AND(OR(I13="Rejected",I13="Reversed"),J13=""),"CHECK reason","OK"))))))) -> OK | L13: =IF(OR(I13="Requested",I13="Under Review",I13="Processing"),1,0) -> 0 | M13: =IF(G13="","",(G13-F13)*24) -> 12.440792 | N13: =IF(AND(I13="Completed",G13<>"",H13<>""),(H13-G13)*24,"") -> 23.782924 | O13: =IF(AND(I13="Completed",H13<>""),(H13-F13)*24,"") -> 36.223716 | P13: =IF(O13="","",IF(O13<=Settings!$B$8,"Yes","No")) -> Yes | Q13: =IF(AND(I13="Rejected",H13<>""),(H13-F13)*24,"") | R13: =IF(L13=1,(Settings!$B$5-F13)*24,"") | S13: =IF(COUNTIF($B$5:B13,B13)=1,1,0) -> 1 | T13: =IF(I13="Completed",IF(COUNTIFS(Wallet_Transactions!$I$5:$I$3000,A13,Wallet_Transactions!$D$5:$D$3000,"Redemption",Wallet_Transactions!$G$5:$G$3000,"Posted")>=1,"OK","CHECK no debit"),IF(I13="Reversed",IF(AND(COUNTIFS(Wallet_Transactions!$I$5:$I$3000,A13,Wallet_Transactions!$D$5:$D$3000,"Redemption",Wallet_Transactions!$G$5:$G$3000,"Posted")>=1,COUNTIFS(Wallet_Transactions!$I$5:$I$3000,A13,Wallet_Transactions!$D$5:$D$3000,"Reversal",Wallet_Transactions!$G$5:$G$3000,"Posted")>=1),"OK","CHECK no reversal"),IF(COUNTIFS(Wallet_Transactions!$I$5:$I$3000,A13,Wallet_Transactions!$D$5:$D$3000,"Redemption",Wallet_Transactions!$G$5:$G$3000,"Posted")>0,"CHECK unexpected debit","OK"))) -> OK
A14: WD-0010 | B14: U002 | C14: 900 | D14: Points | E14: Bank Transfer | F14: 46280.078 | G14: 46280.176 | H14: 46281.723 | I14: Completed | K14: =IF(ISNA(MATCH(I14,Withdrawal_Lifecycle!$A$5:$A$11,0)),"CHECK status",IF(AND(I14="Requested",OR(G14<>"",H14<>"")),"CHECK timestamps",IF(AND(OR(I14="Under Review",I14="Processing"),OR(G14="",H14<>"")),"CHECK timestamps",IF(AND(OR(I14="Completed",I14="Reversed",I14="Rejected"),OR(G14="",H14="")),"CHECK timestamps",IF(AND(I14="Cancelled",H14=""),"CHECK timestamps",IF(OR(AND(G14<>"",G14<F14),AND(H14<>"",H14<IF(G14<>"",G14,F14))),"CHECK order",IF(AND(OR(I14="Rejected",I14="Reversed"),J14=""),"CHECK reason","OK"))))))) -> OK | L14: =IF(OR(I14="Requested",I14="Under Review",I14="Processing"),1,0) -> 0 | M14: =IF(G14="","",(G14-F14)*24) -> 2.3541264 | N14: =IF(AND(I14="Completed",G14<>"",H14<>""),(H14-G14)*24,"") -> 37.125745 | O14: =IF(AND(I14="Completed",H14<>""),(H14-F14)*24,"") -> 39.479871 | P14: =IF(O14="","",IF(O14<=Settings!$B$8,"Yes","No")) -> Yes | Q14: =IF(AND(I14="Rejected",H14<>""),(H14-F14)*24,"") | R14: =IF(L14=1,(Settings!$B$5-F14)*24,"") | S14: =IF(COUNTIF($B$5:B14,B14)=1,1,0) -> 0 | T14: =IF(I14="Completed",IF(COUNTIFS(Wallet_Transactions!$I$5:$I$3000,A14,Wallet_Transactions!$D$5:$D$3000,"Redemption",Wallet_Transactions!$G$5:$G$3000,"Posted")>=1,"OK","CHECK no debit"),IF(I14="Reversed",IF(AND(COUNTIFS(Wallet_Transactions!$I$5:$I$3000,A14,Wallet_Transactions!$D$5:$D$3000,"Redemption",Wallet_Transactions!$G$5:$G$3000,"Posted")>=1,COUNTIFS(Wallet_Transactions!$I$5:$I$3000,A14,Wallet_Transactions!$D$5:$D$3000,"Reversal",Wallet_Transactions!$G$5:$G$3000,"Posted")>=1),"OK","CHECK no reversal"),IF(COUNTIFS(Wallet_Transactions!$I$5:$I$3000,A14,Wallet_Transactions!$D$5:$D$3000,"Redemption",Wallet_Transactions!$G$5:$G$3000,"Posted")>0,"CHECK unexpected debit","OK"))) -> OK
A15: WD-0011 | B15: U011 | C15: 2000 | D15: Points | E15: E-Wallet | F15: 46280.321 | H15: 46280.365 | I15: Cancelled | J15: User Request | K15: =IF(ISNA(MATCH(I15,Withdrawal_Lifecycle!$A$5:$A$11,0)),"CHECK status",IF(AND(I15="Requested",OR(G15<>"",H15<>"")),"CHECK timestamps",IF(AND(OR(I15="Under Review",I15="Processing"),OR(G15="",H15<>"")),"CHECK timestamps",IF(AND(OR(I15="Completed",I15="Reversed",I15="Rejected"),OR(G15="",H15="")),"CHECK timestamps",IF(AND(I15="Cancelled",H15=""),"CHECK timestamps",IF(OR(AND(G15<>"",G15<F15),AND(H15<>"",H15<IF(G15<>"",G15,F15))),"CHECK order",IF(AND(OR(I15="Rejected",I15="Reversed"),J15=""),"CHECK reason","OK"))))))) -> OK | L15: =IF(OR(I15="Requested",I15="Under Review",I15="Processing"),1,0) -> 0 | M15: =IF(G15="","",(G15-F15)*24) | N15: =IF(AND(I15="Completed",G15<>"",H15<>""),(H15-G15)*24,"") | O15: =IF(AND(I15="Completed",H15<>""),(H15-F15)*24,"") | P15: =IF(O15="","",IF(O15<=Settings!$B$8,"Yes","No")) | Q15: =IF(AND(I15="Rejected",H15<>""),(H15-F15)*24,"") | R15: =IF(L15=1,(Settings!$B$5-F15)*24,"") | S15: =IF(COUNTIF($B$5:B15,B15)=1,1,0) -> 1 | T15: =IF(I15="Completed",IF(COUNTIFS(Wallet_Transactions!$I$5:$I$3000,A15,Wallet_Transactions!$D$5:$D$3000,"Redemption",Wallet_Transactions!$G$5:$G$3000,"Posted")>=1,"OK","CHECK no debit"),IF(I15="Reversed",IF(AND(COUNTIFS(Wallet_Transactions!$I$5:$I$3000,A15,Wallet_Transactions!$D$5:$D$3000,"Redemption",Wallet_Transactions!$G$5:$G$3000,"Posted")>=1,COUNTIFS(Wallet_Transactions!$I$5:$I$3000,A15,Wallet_Transactions!$D$5:$D$3000,"Reversal",Wallet_Transactions!$G$5:$G$3000,"Posted")>=1),"OK","CHECK no reversal"),IF(COUNTIFS(Wallet_Transactions!$I$5:$I$3000,A15,Wallet_Transactions!$D$5:$D$3000,"Redemption",Wallet_Transactions!$G$5:$G$3000,"Posted")>0,"CHECK unexpected debit","OK"))) -> OK
A16: WD-0012 | B16: U011 | C16: 1950 | D16: Points | E16: Gift Card | F16: 46280.369 | G16: 46280.394 | H16: 46282.304 | I16: Completed | K16: =IF(ISNA(MATCH(I16,Withdrawal_Lifecycle!$A$5:$A$11,0)),"CHECK status",IF(AND(I16="Requested",OR(G16<>"",H16<>"")),"CHECK timestamps",IF(AND(OR(I16="Under Review",I16="Processing"),OR(G16="",H16<>"")),"CHECK timestamps",IF(AND(OR(I16="Completed",I16="Reversed",I16="Rejected"),OR(G16="",H16="")),"CHECK timestamps",IF(AND(I16="Cancelled",H16=""),"CHECK timestamps",IF(OR(AND(G16<>"",G16<F16),AND(H16<>"",H16<IF(G16<>"",G16,F16))),"CHECK order",IF(AND(OR(I16="Rejected",I16="Reversed"),J16=""),"CHECK reason","OK"))))))) -> OK | L16: =IF(OR(I16="Requested",I16="Under Review",I16="Processing"),1,0) -> 0 | M16: =IF(G16="","",(G16-F16)*24) -> 0.61126267 | N16: =IF(AND(I16="Completed",G16<>"",H16<>""),(H16-G16)*24,"") -> 45.827838 | O16: =IF(AND(I16="Completed",H16<>""),(H16-F16)*24,"") -> 46.4391 | P16: =IF(O16="","",IF(O16<=Settings!$B$8,"Yes","No")) -> Yes | Q16: =IF(AND(I16="Rejected",H16<>""),(H16-F16)*24,"") | R16: =IF(L16=1,(Settings!$B$5-F16)*24,"") | S16: =IF(COUNTIF($B$5:B16,B16)=1,1,0) -> 0 | T16: =IF(I16="Completed",IF(COUNTIFS(Wallet_Transactions!$I$5:$I$3000,A16,Wallet_Transactions!$D$5:$D$3000,"Redemption",Wallet_Transactions!$G$5:$G$3000,"Posted")>=1,"OK","CHECK no debit"),IF(I16="Reversed",IF(AND(COUNTIFS(Wallet_Transactions!$I$5:$I$3000,A16,Wallet_Transactions!$D$5:$D$3000,"Redemption",Wallet_Transactions!$G$5:$G$3000,"Posted")>=1,COUNTIFS(Wallet_Transactions!$I$5:$I$3000,A16,Wallet_Transactions!$D$5:$D$3000,"Reversal",Wallet_Transactions!$G$5:$G$3000,"Posted")>=1),"OK","CHECK no reversal"),IF(COUNTIFS(Wallet_Transactions!$I$5:$I$3000,A16,Wallet_Transactions!$D$5:$D$3000,"Redemption",Wallet_Transactions!$G$5:$G$3000,"Posted")>0,"CHECK unexpected debit","OK"))) -> OK
A17: WD-0013 | B17: U003 | C17: 500 | D17: Points | E17: Gift Card | F17: 46280.504 | G17: 46280.657 | H17: 46281.861 | I17: Rejected | J17: Suspected Fraud | K17: =IF(ISNA(MATCH(I17,Withdrawal_Lifecycle!$A$5:$A$11,0)),"CHECK status",IF(AND(I17="Requested",OR(G17<>"",H17<>"")),"CHECK timestamps",IF(AND(OR(I17="Under Review",I17="Processing"),OR(G17="",H17<>"")),"CHECK timestamps",IF(AND(OR(I17="Completed",I17="Reversed",I17="Rejected"),OR(G17="",H17="")),"CHECK timestamps",IF(AND(I17="Cancelled",H17=""),"CHECK timestamps",IF(OR(AND(G17<>"",G17<F17),AND(H17<>"",H17<IF(G17<>"",G17,F17))),"CHECK order",IF(AND(OR(I17="Rejected",I17="Reversed"),J17=""),"CHECK reason","OK"))))))) -> OK | L17: =IF(OR(I17="Requested",I17="Under Review",I17="Processing"),1,0) -> 0 | M17: =IF(G17="","",(G17-F17)*24) -> 3.6642104 | N17: =IF(AND(I17="Completed",G17<>"",H17<>""),(H17-G17)*24,"") | O17: =IF(AND(I17="Completed",H17<>""),(H17-F17)*24,"") | P17: =IF(O17="","",IF(O17<=Settings!$B$8,"Yes","No")) | Q17: =IF(AND(I17="Rejected",H17<>""),(H17-F17)*24,"") -> 32.571487 | R17: =IF(L17=1,(Settings!$B$5-F17)*24,"") | S17: =IF(COUNTIF($B$5:B17,B17)=1,1,0) -> 0 | T17: =IF(I17="Completed",IF(COUNTIFS(Wallet_Transactions!$I$5:$I$3000,A17,Wallet_Transactions!$D$5:$D$3000,"Redemption",Wallet_Transactions!$G$5:$G$3000,"Posted")>=1,"OK","CHECK no debit"),IF(I17="Reversed",IF(AND(COUNTIFS(Wallet_Transactions!$I$5:$I$3000,A17,Wallet_Transactions!$D$5:$D$3000,"Redemption",Wallet_Transactions!$G$5:$G$3000,"Posted")>=1,COUNTIFS(Wallet_Transactions!$I$5:$I$3000,A17,Wallet_Transactions!$D$5:$D$3000,"Reversal",Wallet_Transactions!$G$5:$G$3000,"Posted")>=1),"OK","CHECK no reversal"),IF(COUNTIFS(Wallet_Transactions!$I$5:$I$3000,A17,Wallet_Transactions!$D$5:$D$3000,"Redemption",Wallet_Transactions!$G$5:$G$3000,"Posted")>0,"CHECK unexpected debit","OK"))) -> OK
A18: WD-0014 | B18: U009 | C18: 1950 | D18: Points | E18: Bank Transfer | F18: 46281.708 | G18: 46282.335 | H18: 46284.661 | I18: Completed | K18: =IF(ISNA(MATCH(I18,Withdrawal_Lifecycle!$A$5:$A$11,0)),"CHECK status",IF(AND(I18="Requested",OR(G18<>"",H18<>"")),"CHECK timestamps",IF(AND(OR(I18="Under Review",I18="Processing"),OR(G18="",H18<>"")),"CHECK timestamps",IF(AND(OR(I18="Completed",I18="Reversed",I18="Rejected"),OR(G18="",H18="")),"CHECK timestamps",IF(AND(I18="Cancelled",H18=""),"CHECK timestamps",IF(OR(AND(G18<>"",G18<F18),AND(H18<>"",H18<IF(G18<>"",G18,F18))),"CHECK order",IF(AND(OR(I18="Rejected",I18="Reversed"),J18=""),"CHECK reason","OK"))))))) -> OK | L18: =IF(OR(I18="Requested",I18="Under Review",I18="Processing"),1,0) -> 0 | M18: =IF(G18="","",(G18-F18)*24) -> 15.057478 | N18: =IF(AND(I18="Completed",G18<>"",H18<>""),(H18-G18)*24,"") -> 55.829766 | O18: =IF(AND(I18="Completed",H18<>""),(H18-F18)*24,"") -> 70.887245 | P18: =IF(O18="","",IF(O18<=Settings!$B$8,"Yes","No")) -> No | Q18: =IF(AND(I18="Rejected",H18<>""),(H18-F18)*24,"") | R18: =IF(L18=1,(Settings!$B$5-F18)*24,"") | S18: =IF(COUNTIF($B$5:B18,B18)=1,1,0) -> 1 | T18: =IF(I18="Completed",IF(COUNTIFS(Wallet_Transactions!$I$5:$I$3000,A18,Wallet_Transactions!$D$5:$D$3000,"Redemption",Wallet_Transactions!$G$5:$G$3000,"Posted")>=1,"OK","CHECK no debit"),IF(I18="Reversed",IF(AND(COUNTIFS(Wallet_Transactions!$I$5:$I$3000,A18,Wallet_Transactions!$D$5:$D$3000,"Redemption",Wallet_Transactions!$G$5:$G$3000,"Posted")>=1,COUNTIFS(Wallet_Transactions!$I$5:$I$3000,A18,Wallet_Transactions!$D$5:$D$3000,"Reversal",Wallet_Transactions!$G$5:$G$3000,"Posted")>=1),"OK","CHECK no reversal"),IF(COUNTIFS(Wallet_Transactions!$I$5:$I$3000,A18,Wallet_Transactions!$D$5:$D$3000,"Redemption",Wallet_Transactions!$G$5:$G$3000,"Posted")>0,"CHECK unexpected debit","OK"))) -> OK
A19: WD-0015 | B19: U010 | C19: 1800 | D19: Points | E19: E-Wallet | F19: 46282.061 | G19: 46282.268 | H19: 46282.693 | I19: Rejected | J19: Duplicate Request | K19: =IF(ISNA(MATCH(I19,Withdrawal_Lifecycle!$A$5:$A$11,0)),"CHECK status",IF(AND(I19="Requested",OR(G19<>"",H19<>"")),"CHECK timestamps",IF(AND(OR(I19="Under Review",I19="Processing"),OR(G19="",H19<>"")),"CHECK timestamps",IF(AND(OR(I19="Completed",I19="Reversed",I19="Rejected"),OR(G19="",H19="")),"CHECK timestamps",IF(AND(I19="Cancelled",H19=""),"CHECK timestamps",IF(OR(AND(G19<>"",G19<F19),AND(H19<>"",H19<IF(G19<>"",G19,F19))),"CHECK order",IF(AND(OR(I19="Rejected",I19="Reversed"),J19=""),"CHECK reason","OK"))))))) -> OK | L19: =IF(OR(I19="Requested",I19="Under Review",I19="Processing"),1,0) -> 0 | M19: =IF(G19="","",(G19-F19)*24) -> 4.9637993 | N19: =IF(AND(I19="Completed",G19<>"",H19<>""),(H19-G19)*24,"") | O19: =IF(AND(I19="Completed",H19<>""),(H19-F19)*24,"") | P19: =IF(O19="","",IF(O19<=Settings!$B$8,"Yes","No")) | Q19: =IF(AND(I19="Rejected",H19<>""),(H19-F19)*24,"") -> 15.173357 | R19: =IF(L19=1,(Settings!$B$5-F19)*24,"") | S19: =IF(COUNTIF($B$5:B19,B19)=1,1,0) -> 0 | T19: =IF(I19="Completed",IF(COUNTIFS(Wallet_Transactions!$I$5:$I$3000,A19,Wallet_Transactions!$D$5:$D$3000,"Redemption",Wallet_Transactions!$G$5:$G$3000,"Posted")>=1,"OK","CHECK no debit"),IF(I19="Reversed",IF(AND(COUNTIFS(Wallet_Transactions!$I$5:$I$3000,A19,Wallet_Transactions!$D$5:$D$3000,"Redemption",Wallet_Transactions!$G$5:$G$3000,"Posted")>=1,COUNTIFS(Wallet_Transactions!$I$5:$I$3000,A19,Wallet_Transactions!$D$5:$D$3000,"Reversal",Wallet_Transactions!$G$5:$G$3000,"Posted")>=1),"OK","CHECK no reversal"),IF(COUNTIFS(Wallet_Transactions!$I$5:$I$3000,A19,Wallet_Transactions!$D$5:$D$3000,"Redemption",Wallet_Transactions!$G$5:$G$3000,"Posted")>0,"CHECK unexpected debit","OK"))) -> OK
A20: WD-0016 | B20: U020 | C20: 600 | D20: Points | E20: Bank Transfer | F20: 46283.294 | G20: 46283.796 | H20: 46284.266 | I20: Completed | K20: =IF(ISNA(MATCH(I20,Withdrawal_Lifecycle!$A$5:$A$11,0)),"CHECK status",IF(AND(I20="Requested",OR(G20<>"",H20<>"")),"CHECK timestamps",IF(AND(OR(I20="Under Review",I20="Processing"),OR(G20="",H20<>"")),"CHECK timestamps",IF(AND(OR(I20="Completed",I20="Reversed",I20="Rejected"),OR(G20="",H20="")),"CHECK timestamps",IF(AND(I20="Cancelled",H20=""),"CHECK timestamps",IF(OR(AND(G20<>"",G20<F20),AND(H20<>"",H20<IF(G20<>"",G20,F20))),"CHECK order",IF(AND(OR(I20="Rejected",I20="Reversed"),J20=""),"CHECK reason","OK"))))))) -> OK | L20: =IF(OR(I20="Requested",I20="Under Review",I20="Processing"),1,0) -> 0 | M20: =IF(G20="","",(G20-F20)*24) -> 12.05472 | N20: =IF(AND(I20="Completed",G20<>"",H20<>""),(H20-G20)*24,"") -> 11.276368 | O20: =IF(AND(I20="Completed",H20<>""),(H20-F20)*24,"") -> 23.331088 | P20: =IF(O20="","",IF(O20<=Settings!$B$8,"Yes","No")) -> Yes | Q20: =IF(AND(I20="Rejected",H20<>""),(H20-F20)*24,"") | R20: =IF(L20=1,(Settings!$B$5-F20)*24,"") | S20: =IF(COUNTIF($B$5:B20,B20)=1,1,0) -> 1 | T20: =IF(I20="Completed",IF(COUNTIFS(Wallet_Transactions!$I$5:$I$3000,A20,Wallet_Transactions!$D$5:$D$3000,"Redemption",Wallet_Transactions!$G$5:$G$3000,"Posted")>=1,"OK","CHECK no debit"),IF(I20="Reversed",IF(AND(COUNTIFS(Wallet_Transactions!$I$5:$I$3000,A20,Wallet_Transactions!$D$5:$D$3000,"Redemption",Wallet_Transactions!$G$5:$G$3000,"Posted")>=1,COUNTIFS(Wallet_Transactions!$I$5:$I$3000,A20,Wallet_Transactions!$D$5:$D$3000,"Reversal",Wallet_Transactions!$G$5:$G$3000,"Posted")>=1),"OK","CHECK no reversal"),IF(COUNTIFS(Wallet_Transactions!$I$5:$I$3000,A20,Wallet_Transactions!$D$5:$D$3000,"Redemption",Wallet_Transactions!$G$5:$G$3000,"Posted")>0,"CHECK unexpected debit","OK"))) -> OK
A21: WD-0017 | B21: U002 | C21: 1250 | D21: Points | E21: Gift Card | F21: 46283.422 | G21: 46283.843 | H21: 46286.296 | I21: Completed | K21: =IF(ISNA(MATCH(I21,Withdrawal_Lifecycle!$A$5:$A$11,0)),"CHECK status",IF(AND(I21="Requested",OR(G21<>"",H21<>"")),"CHECK timestamps",IF(AND(OR(I21="Under Review",I21="Processing"),OR(G21="",H21<>"")),"CHECK timestamps",IF(AND(OR(I21="Completed",I21="Reversed",I21="Rejected"),OR(G21="",H21="")),"CHECK timestamps",IF(AND(I21="Cancelled",H21=""),"CHECK timestamps",IF(OR(AND(G21<>"",G21<F21),AND(H21<>"",H21<IF(G21<>"",G21,F21))),"CHECK order",IF(AND(OR(I21="Rejected",I21="Reversed"),J21=""),"CHECK reason","OK"))))))) -> OK | L21: =IF(OR(I21="Requested",I21="Under Review",I21="Processing"),1,0) -> 0 | M21: =IF(G21="","",(G21-F21)*24) -> 10.109871 | N21: =IF(AND(I21="Completed",G21<>"",H21<>""),(H21-G21)*24,"") -> 58.854835 | O21: =IF(AND(I21="Completed",H21<>""),(H21-F21)*24,"") -> 68.964706 | P21: =IF(O21="","",IF(O21<=Settings!$B$8,"Yes","No")) -> No | Q21: =IF(AND(I21="Rejected",H21<>""),(H21-F21)*24,"") | R21: =IF(L21=1,(Settings!$B$5-F21)*24,"") | S21: =IF(COUNTIF($B$5:B21,B21)=1,1,0) -> 0 | T21: =IF(I21="Completed",IF(COUNTIFS(Wallet_Transactions!$I$5:$I$3000,A21,Wallet_Transactions!$D$5:$D$3000,"Redemption",Wallet_Transactions!$G$5:$G$3000,"Posted")>=1,"OK","CHECK no debit"),IF(I21="Reversed",IF(AND(COUNTIFS(Wallet_Transactions!$I$5:$I$3000,A21,Wallet_Transactions!$D$5:$D$3000,"Redemption",Wallet_Transactions!$G$5:$G$3000,"Posted")>=1,COUNTIFS(Wallet_Transactions!$I$5:$I$3000,A21,Wallet_Transactions!$D$5:$D$3000,"Reversal",Wallet_Transactions!$G$5:$G$3000,"Posted")>=1),"OK","CHECK no reversal"),IF(COUNTIFS(Wallet_Transactions!$I$5:$I$3000,A21,Wallet_Transactions!$D$5:$D$3000,"Redemption",Wallet_Transactions!$G$5:$G$3000,"Posted")>0,"CHECK unexpected debit","OK"))) -> OK
A22: WD-0018 | B22: U003 | C22: 900 | D22: Points | E22: Other | F22: 46284.186 | G22: 46284.463 | H22: 46285.564 | I22: Completed | K22: =IF(ISNA(MATCH(I22,Withdrawal_Lifecycle!$A$5:$A$11,0)),"CHECK status",IF(AND(I22="Requested",OR(G22<>"",H22<>"")),"CHECK timestamps",IF(AND(OR(I22="Under Review",I22="Processing"),OR(G22="",H22<>"")),"CHECK timestamps",IF(AND(OR(I22="Completed",I22="Reversed",I22="Rejected"),OR(G22="",H22="")),"CHECK timestamps",IF(AND(I22="Cancelled",H22=""),"CHECK timestamps",IF(OR(AND(G22<>"",G22<F22),AND(H22<>"",H22<IF(G22<>"",G22,F22))),"CHECK order",IF(AND(OR(I22="Rejected",I22="Reversed"),J22=""),"CHECK reason","OK"))))))) -> OK | L22: =IF(OR(I22="Requested",I22="Under Review",I22="Processing"),1,0) -> 0 | M22: =IF(G22="","",(G22-F22)*24) -> 6.6460607 | N22: =IF(AND(I22="Completed",G22<>"",H22<>""),(H22-G22)*24,"") -> 26.421496 | O22: =IF(AND(I22="Completed",H22<>""),(H22-F22)*24,"") -> 33.067557 | P22: =IF(O22="","",IF(O22<=Settings!$B$8,"Yes","No")) -> Yes | Q22: =IF(AND(I22="Rejected",H22<>""),(H22-F22)*24,"") | R22: =IF(L22=1,(Settings!$B$5-F22)*24,"") | S22: =IF(COUNTIF($B$5:B22,B22)=1,1,0) -> 0 | T22: =IF(I22="Completed",IF(COUNTIFS(Wallet_Transactions!$I$5:$I$3000,A22,Wallet_Transactions!$D$5:$D$3000,"Redemption",Wallet_Transactions!$G$5:$G$3000,"Posted")>=1,"OK","CHECK no debit"),IF(I22="Reversed",IF(AND(COUNTIFS(Wallet_Transactions!$I$5:$I$3000,A22,Wallet_Transactions!$D$5:$D$3000,"Redemption",Wallet_Transactions!$G$5:$G$3000,"Posted")>=1,COUNTIFS(Wallet_Transactions!$I$5:$I$3000,A22,Wallet_Transactions!$D$5:$D$3000,"Reversal",Wallet_Transactions!$G$5:$G$3000,"Posted")>=1),"OK","CHECK no reversal"),IF(COUNTIFS(Wallet_Transactions!$I$5:$I$3000,A22,Wallet_Transactions!$D$5:$D$3000,"Redemption",Wallet_Transactions!$G$5:$G$3000,"Posted")>0,"CHECK unexpected debit","OK"))) -> OK
A23: WD-0019 | B23: U015 | C23: 750 | D23: Points | E23: E-Wallet | F23: 46285.385 | G23: 46285.918 | H23: 46287.5 | I23: Completed | K23: =IF(ISNA(MATCH(I23,Withdrawal_Lifecycle!$A$5:$A$11,0)),"CHECK status",IF(AND(I23="Requested",OR(G23<>"",H23<>"")),"CHECK timestamps",IF(AND(OR(I23="Under Review",I23="Processing"),OR(G23="",H23<>"")),"CHECK timestamps",IF(AND(OR(I23="Completed",I23="Reversed",I23="Rejected"),OR(G23="",H23="")),"CHECK timestamps",IF(AND(I23="Cancelled",H23=""),"CHECK timestamps",IF(OR(AND(G23<>"",G23<F23),AND(H23<>"",H23<IF(G23<>"",G23,F23))),"CHECK order",IF(AND(OR(I23="Rejected",I23="Reversed"),J23=""),"CHECK reason","OK"))))))) -> OK | L23: =IF(OR(I23="Requested",I23="Under Review",I23="Processing"),1,0) -> 0 | M23: =IF(G23="","",(G23-F23)*24) -> 12.796799 | N23: =IF(AND(I23="Completed",G23<>"",H23<>""),(H23-G23)*24,"") -> 37.977843 | O23: =IF(AND(I23="Completed",H23<>""),(H23-F23)*24,"") -> 50.774642 | P23: =IF(O23="","",IF(O23<=Settings!$B$8,"Yes","No")) -> No | Q23: =IF(AND(I23="Rejected",H23<>""),(H23-F23)*24,"") | R23: =IF(L23=1,(Settings!$B$5-F23)*24,"") | S23: =IF(COUNTIF($B$5:B23,B23)=1,1,0) -> 0 | T23: =IF(I23="Completed",IF(COUNTIFS(Wallet_Transactions!$I$5:$I$3000,A23,Wallet_Transactions!$D$5:$D$3000,"Redemption",Wallet_Transactions!$G$5:$G$3000,"Posted")>=1,"OK","CHECK no debit"),IF(I23="Reversed",IF(AND(COUNTIFS(Wallet_Transactions!$I$5:$I$3000,A23,Wallet_Transactions!$D$5:$D$3000,"Redemption",Wallet_Transactions!$G$5:$G$3000,"Posted")>=1,COUNTIFS(Wallet_Transactions!$I$5:$I$3000,A23,Wallet_Transactions!$D$5:$D$3000,"Reversal",Wallet_Transactions!$G$5:$G$3000,"Posted")>=1),"OK","CHECK no reversal"),IF(COUNTIFS(Wallet_Transactions!$I$5:$I$3000,A23,Wallet_Transactions!$D$5:$D$3000,"Redemption",Wallet_Transactions!$G$5:$G$3000,"Posted")>0,"CHECK unexpected debit","OK"))) -> OK
A24: WD-0020 | B24: U018 | C24: 1850 | D24: Points | E24: Bank Transfer | F24: 46286.489 | G24: 46287.443 | H24: 46288.752 | I24: Rejected | J24: Verification Failed | K24: =IF(ISNA(MATCH(I24,Withdrawal_Lifecycle!$A$5:$A$11,0)),"CHECK status",IF(AND(I24="Requested",OR(G24<>"",H24<>"")),"CHECK timestamps",IF(AND(OR(I24="Under Review",I24="Processing"),OR(G24="",H24<>"")),"CHECK timestamps",IF(AND(OR(I24="Completed",I24="Reversed",I24="Rejected"),OR(G24="",H24="")),"CHECK timestamps",IF(AND(I24="Cancelled",H24=""),"CHECK timestamps",IF(OR(AND(G24<>"",G24<F24),AND(H24<>"",H24<IF(G24<>"",G24,F24))),"CHECK order",IF(AND(OR(I24="Rejected",I24="Reversed"),J24=""),"CHECK reason","OK"))))))) -> OK | L24: =IF(OR(I24="Requested",I24="Under Review",I24="Processing"),1,0) -> 0 | M24: =IF(G24="","",(G24-F24)*24) -> 22.907216 | N24: =IF(AND(I24="Completed",G24<>"",H24<>""),(H24-G24)*24,"") | O24: =IF(AND(I24="Completed",H24<>""),(H24-F24)*24,"") | P24: =IF(O24="","",IF(O24<=Settings!$B$8,"Yes","No")) | Q24: =IF(AND(I24="Rejected",H24<>""),(H24-F24)*24,"") -> 54.317489 | R24: =IF(L24=1,(Settings!$B$5-F24)*24,"") | S24: =IF(COUNTIF($B$5:B24,B24)=1,1,0) -> 1 | T24: =IF(I24="Completed",IF(COUNTIFS(Wallet_Transactions!$I$5:$I$3000,A24,Wallet_Transactions!$D$5:$D$3000,"Redemption",Wallet_Transactions!$G$5:$G$3000,"Posted")>=1,"OK","CHECK no debit"),IF(I24="Reversed",IF(AND(COUNTIFS(Wallet_Transactions!$I$5:$I$3000,A24,Wallet_Transactions!$D$5:$D$3000,"Redemption",Wallet_Transactions!$G$5:$G$3000,"Posted")>=1,COUNTIFS(Wallet_Transactions!$I$5:$I$3000,A24,Wallet_Transactions!$D$5:$D$3000,"Reversal",Wallet_Transactions!$G$5:$G$3000,"Posted")>=1),"OK","CHECK no reversal"),IF(COUNTIFS(Wallet_Transactions!$I$5:$I$3000,A24,Wallet_Transactions!$D$5:$D$3000,"Redemption",Wallet_Transactions!$G$5:$G$3000,"Posted")>0,"CHECK unexpected debit","OK"))) -> OK
A25: WD-0021 | B25: U009 | C25: 750 | D25: Points | E25: Bank Transfer | F25: 46286.849 | G25: 46287.189 | H25: 46288.335 | I25: Completed | K25: =IF(ISNA(MATCH(I25,Withdrawal_Lifecycle!$A$5:$A$11,0)),"CHECK status",IF(AND(I25="Requested",OR(G25<>"",H25<>"")),"CHECK timestamps",IF(AND(OR(I25="Under Review",I25="Processing"),OR(G25="",H25<>"")),"CHECK timestamps",IF(AND(OR(I25="Completed",I25="Reversed",I25="Rejected"),OR(G25="",H25="")),"CHECK timestamps",IF(AND(I25="Cancelled",H25=""),"CHECK timestamps",IF(OR(AND(G25<>"",G25<F25),AND(H25<>"",H25<IF(G25<>"",G25,F25))),"CHECK order",IF(AND(OR(I25="Rejected",I25="Reversed"),J25=""),"CHECK reason","OK"))))))) -> OK | L25: =IF(OR(I25="Requested",I25="Under Review",I25="Processing"),1,0) -> 0 | M25: =IF(G25="","",(G25-F25)*24) -> 8.179884 | N25: =IF(AND(I25="Completed",G25<>"",H25<>""),(H25-G25)*24,"") -> 27.48507 | O25: =IF(AND(I25="Completed",H25<>""),(H25-F25)*24,"") -> 35.664954 | P25: =IF(O25="","",IF(O25<=Settings!$B$8,"Yes","No")) -> Yes | Q25: =IF(AND(I25="Rejected",H25<>""),(H25-F25)*24,"") | R25: =IF(L25=1,(Settings!$B$5-F25)*24,"") | S25: =IF(COUNTIF($B$5:B25,B25)=1,1,0) -> 0 | T25: =IF(I25="Completed",IF(COUNTIFS(Wallet_Transactions!$I$5:$I$3000,A25,Wallet_Transactions!$D$5:$D$3000,"Redemption",Wallet_Transactions!$G$5:$G$3000,"Posted")>=1,"OK","CHECK no debit"),IF(I25="Reversed",IF(AND(COUNTIFS(Wallet_Transactions!$I$5:$I$3000,A25,Wallet_Transactions!$D$5:$D$3000,"Redemption",Wallet_Transactions!$G$5:$G$3000,"Posted")>=1,COUNTIFS(Wallet_Transactions!$I$5:$I$3000,A25,Wallet_Transactions!$D$5:$D$3000,"Reversal",Wallet_Transactions!$G$5:$G$3000,"Posted")>=1),"OK","CHECK no reversal"),IF(COUNTIFS(Wallet_Transactions!$I$5:$I$3000,A25,Wallet_Transactions!$D$5:$D$3000,"Redemption",Wallet_Transactions!$G$5:$G$3000,"Posted")>0,"CHECK unexpected debit","OK"))) -> OK
A26: WD-0022 | B26: U008 | C26: 700 | D26: Points | E26: Bank Transfer | F26: 46288.038 | G26: 46289.175 | H26: 46289.713 | I26: Completed | K26: =IF(ISNA(MATCH(I26,Withdrawal_Lifecycle!$A$5:$A$11,0)),"CHECK status",IF(AND(I26="Requested",OR(G26<>"",H26<>"")),"CHECK timestamps",IF(AND(OR(I26="Under Review",I26="Processing"),OR(G26="",H26<>"")),"CHECK timestamps",IF(AND(OR(I26="Completed",I26="Reversed",I26="Rejected"),OR(G26="",H26="")),"CHECK timestamps",IF(AND(I26="Cancelled",H26=""),"CHECK timestamps",IF(OR(AND(G26<>"",G26<F26),AND(H26<>"",H26<IF(G26<>"",G26,F26))),"CHECK order",IF(AND(OR(I26="Rejected",I26="Reversed"),J26=""),"CHECK reason","OK"))))))) -> OK | L26: =IF(OR(I26="Requested",I26="Under Review",I26="Processing"),1,0) -> 0 | M26: =IF(G26="","",(G26-F26)*24) -> 27.273263 | N26: =IF(AND(I26="Completed",G26<>"",H26<>""),(H26-G26)*24,"") -> 12.918508 | O26: =IF(AND(I26="Completed",H26<>""),(H26-F26)*24,"") -> 40.191771 | P26: =IF(O26="","",IF(O26<=Settings!$B$8,"Yes","No")) -> Yes | Q26: =IF(AND(I26="Rejected",H26<>""),(H26-F26)*24,"") | R26: =IF(L26=1,(Settings!$B$5-F26)*24,"") | S26: =IF(COUNTIF($B$5:B26,B26)=1,1,0) -> 0 | T26: =IF(I26="Completed",IF(COUNTIFS(Wallet_Transactions!$I$5:$I$3000,A26,Wallet_Transactions!$D$5:$D$3000,"Redemption",Wallet_Transactions!$G$5:$G$3000,"Posted")>=1,"OK","CHECK no debit"),IF(I26="Reversed",IF(AND(COUNTIFS(Wallet_Transactions!$I$5:$I$3000,A26,Wallet_Transactions!$D$5:$D$3000,"Redemption",Wallet_Transactions!$G$5:$G$3000,"Posted")>=1,COUNTIFS(Wallet_Transactions!$I$5:$I$3000,A26,Wallet_Transactions!$D$5:$D$3000,"Reversal",Wallet_Transactions!$G$5:$G$3000,"Posted")>=1),"OK","CHECK no reversal"),IF(COUNTIFS(Wallet_Transactions!$I$5:$I$3000,A26,Wallet_Transactions!$D$5:$D$3000,"Redemption",Wallet_Transactions!$G$5:$G$3000,"Posted")>0,"CHECK unexpected debit","OK"))) -> OK
A27: WD-0023 | B27: U010 | C27: 850 | D27: Points | E27: E-Wallet | F27: 46289.14 | G27: 46289.445 | H27: 46291.482 | I27: Completed | K27: =IF(ISNA(MATCH(I27,Withdrawal_Lifecycle!$A$5:$A$11,0)),"CHECK status",IF(AND(I27="Requested",OR(G27<>"",H27<>"")),"CHECK timestamps",IF(AND(OR(I27="Under Review",I27="Processing"),OR(G27="",H27<>"")),"CHECK timestamps",IF(AND(OR(I27="Completed",I27="Reversed",I27="Rejected"),OR(G27="",H27="")),"CHECK timestamps",IF(AND(I27="Cancelled",H27=""),"CHECK timestamps",IF(OR(AND(G27<>"",G27<F27),AND(H27<>"",H27<IF(G27<>"",G27,F27))),"CHECK order",IF(AND(OR(I27="Rejected",I27="Reversed"),J27=""),"CHECK reason","OK"))))))) -> OK | L27: =IF(OR(I27="Requested",I27="Under Review",I27="Processing"),1,0) -> 0 | M27: =IF(G27="","",(G27-F27)*24) -> 7.3257379 | N27: =IF(AND(I27="Completed",G27<>"",H27<>""),(H27-G27)*24,"") -> 48.889688 | O27: =IF(AND(I27="Completed",H27<>""),(H27-F27)*24,"") -> 56.215426 | P27: =IF(O27="","",IF(O27<=Settings!$B$8,"Yes","No")) -> No | Q27: =IF(AND(I27="Rejected",H27<>""),(H27-F27)*24,"") | R27: =IF(L27=1,(Settings!$B$5-F27)*24,"") | S27: =IF(COUNTIF($B$5:B27,B27)=1,1,0) -> 0 | T27: =IF(I27="Completed",IF(COUNTIFS(Wallet_Transactions!$I$5:$I$3000,A27,Wallet_Transactions!$D$5:$D$3000,"Redemption",Wallet_Transactions!$G$5:$G$3000,"Posted")>=1,"OK","CHECK no debit"),IF(I27="Reversed",IF(AND(COUNTIFS(Wallet_Transactions!$I$5:$I$3000,A27,Wallet_Transactions!$D$5:$D$3000,"Redemption",Wallet_Transactions!$G$5:$G$3000,"Posted")>=1,COUNTIFS(Wallet_Transactions!$I$5:$I$3000,A27,Wallet_Transactions!$D$5:$D$3000,"Reversal",Wallet_Transactions!$G$5:$G$3000,"Posted")>=1),"OK","CHECK no reversal"),IF(COUNTIFS(Wallet_Transactions!$I$5:$I$3000,A27,Wallet_Transactions!$D$5:$D$3000,"Redemption",Wallet_Transactions!$G$5:$G$3000,"Posted")>0,"CHECK unexpected debit","OK"))) -> OK
A28: WD-0024 | B28: U002 | C28: 550 | D28: Points | E28: Bank Transfer | F28: 46289.311 | G28: 46290.417 | H28: 46291.059 | I28: Completed | K28: =IF(ISNA(MATCH(I28,Withdrawal_Lifecycle!$A$5:$A$11,0)),"CHECK status",IF(AND(I28="Requested",OR(G28<>"",H28<>"")),"CHECK timestamps",IF(AND(OR(I28="Under Review",I28="Processing"),OR(G28="",H28<>"")),"CHECK timestamps",IF(AND(OR(I28="Completed",I28="Reversed",I28="Rejected"),OR(G28="",H28="")),"CHECK timestamps",IF(AND(I28="Cancelled",H28=""),"CHECK timestamps",IF(OR(AND(G28<>"",G28<F28),AND(H28<>"",H28<IF(G28<>"",G28,F28))),"CHECK order",IF(AND(OR(I28="Rejected",I28="Reversed"),J28=""),"CHECK reason","OK"))))))) -> OK | L28: =IF(OR(I28="Requested",I28="Under Review",I28="Processing"),1,0) -> 0 | M28: =IF(G28="","",(G28-F28)*24) -> 26.543338 | N28: =IF(AND(I28="Completed",G28<>"",H28<>""),(H28-G28)*24,"") -> 15.404586 | O28: =IF(AND(I28="Completed",H28<>""),(H28-F28)*24,"") -> 41.947925 | P28: =IF(O28="","",IF(O28<=Settings!$B$8,"Yes","No")) -> Yes | Q28: =IF(AND(I28="Rejected",H28<>""),(H28-F28)*24,"") | R28: =IF(L28=1,(Settings!$B$5-F28)*24,"") | S28: =IF(COUNTIF($B$5:B28,B28)=1,1,0) -> 0 | T28: =IF(I28="Completed",IF(COUNTIFS(Wallet_Transactions!$I$5:$I$3000,A28,Wallet_Transactions!$D$5:$D$3000,"Redemption",Wallet_Transactions!$G$5:$G$3000,"Posted")>=1,"OK","CHECK no debit"),IF(I28="Reversed",IF(AND(COUNTIFS(Wallet_Transactions!$I$5:$I$3000,A28,Wallet_Transactions!$D$5:$D$3000,"Redemption",Wallet_Transactions!$G$5:$G$3000,"Posted")>=1,COUNTIFS(Wallet_Transactions!$I$5:$I$3000,A28,Wallet_Transactions!$D$5:$D$3000,"Reversal",Wallet_Transactions!$G$5:$G$3000,"Posted")>=1),"OK","CHECK no reversal"),IF(COUNTIFS(Wallet_Transactions!$I$5:$I$3000,A28,Wallet_Transactions!$D$5:$D$3000,"Redemption",Wallet_Transactions!$G$5:$G$3000,"Posted")>0,"CHECK unexpected debit","OK"))) -> OK
A29: WD-0025 | B29: U014 | C29: 550 | D29: Points | E29: Bank Transfer | F29: 46291.167 | G29: 46291.474 | H29: 46295.079 | I29: Reversed | J29: Duplicate Request | K29: =IF(ISNA(MATCH(I29,Withdrawal_Lifecycle!$A$5:$A$11,0)),"CHECK status",IF(AND(I29="Requested",OR(G29<>"",H29<>"")),"CHECK timestamps",IF(AND(OR(I29="Under Review",I29="Processing"),OR(G29="",H29<>"")),"CHECK timestamps",IF(AND(OR(I29="Completed",I29="Reversed",I29="Rejected"),OR(G29="",H29="")),"CHECK timestamps",IF(AND(I29="Cancelled",H29=""),"CHECK timestamps",IF(OR(AND(G29<>"",G29<F29),AND(H29<>"",H29<IF(G29<>"",G29,F29))),"CHECK order",IF(AND(OR(I29="Rejected",I29="Reversed"),J29=""),"CHECK reason","OK"))))))) -> OK | L29: =IF(OR(I29="Requested",I29="Under Review",I29="Processing"),1,0) -> 0 | M29: =IF(G29="","",(G29-F29)*24) -> 7.370334 | N29: =IF(AND(I29="Completed",G29<>"",H29<>""),(H29-G29)*24,"") | O29: =IF(AND(I29="Completed",H29<>""),(H29-F29)*24,"") | P29: =IF(O29="","",IF(O29<=Settings!$B$8,"Yes","No")) | Q29: =IF(AND(I29="Rejected",H29<>""),(H29-F29)*24,"") | R29: =IF(L29=1,(Settings!$B$5-F29)*24,"") | S29: =IF(COUNTIF($B$5:B29,B29)=1,1,0) -> 1 | T29: =IF(I29="Completed",IF(COUNTIFS(Wallet_Transactions!$I$5:$I$3000,A29,Wallet_Transactions!$D$5:$D$3000,"Redemption",Wallet_Transactions!$G$5:$G$3000,"Posted")>=1,"OK","CHECK no debit"),IF(I29="Reversed",IF(AND(COUNTIFS(Wallet_Transactions!$I$5:$I$3000,A29,Wallet_Transactions!$D$5:$D$3000,"Redemption",Wallet_Transactions!$G$5:$G$3000,"Posted")>=1,COUNTIFS(Wallet_Transactions!$I$5:$I$3000,A29,Wallet_Transactions!$D$5:$D$3000,"Reversal",Wallet_Transactions!$G$5:$G$3000,"Posted")>=1),"OK","CHECK no reversal"),IF(COUNTIFS(Wallet_Transactions!$I$5:$I$3000,A29,Wallet_Transactions!$D$5:$D$3000,"Redemption",Wallet_Transactions!$G$5:$G$3000,"Posted")>0,"CHECK unexpected debit","OK"))) -> OK
A30: WD-0026 | B30: U004 | C30: 1050 | D30: Points | E30: Gift Card | F30: 46292.434 | G30: 46292.673 | H30: 46294.214 | I30: Completed | K30: =IF(ISNA(MATCH(I30,Withdrawal_Lifecycle!$A$5:$A$11,0)),"CHECK status",IF(AND(I30="Requested",OR(G30<>"",H30<>"")),"CHECK timestamps",IF(AND(OR(I30="Under Review",I30="Processing"),OR(G30="",H30<>"")),"CHECK timestamps",IF(AND(OR(I30="Completed",I30="Reversed",I30="Rejected"),OR(G30="",H30="")),"CHECK timestamps",IF(AND(I30="Cancelled",H30=""),"CHECK timestamps",IF(OR(AND(G30<>"",G30<F30),AND(H30<>"",H30<IF(G30<>"",G30,F30))),"CHECK order",IF(AND(OR(I30="Rejected",I30="Reversed"),J30=""),"CHECK reason","OK"))))))) -> OK | L30: =IF(OR(I30="Requested",I30="Under Review",I30="Processing"),1,0) -> 0 | M30: =IF(G30="","",(G30-F30)*24) -> 5.7438906 | N30: =IF(AND(I30="Completed",G30<>"",H30<>""),(H30-G30)*24,"") -> 36.976447 | O30: =IF(AND(I30="Completed",H30<>""),(H30-F30)*24,"") -> 42.720337 | P30: =IF(O30="","",IF(O30<=Settings!$B$8,"Yes","No")) -> Yes | Q30: =IF(AND(I30="Rejected",H30<>""),(H30-F30)*24,"") | R30: =IF(L30=1,(Settings!$B$5-F30)*24,"") | S30: =IF(COUNTIF($B$5:B30,B30)=1,1,0) -> 0 | T30: =IF(I30="Completed",IF(COUNTIFS(Wallet_Transactions!$I$5:$I$3000,A30,Wallet_Transactions!$D$5:$D$3000,"Redemption",Wallet_Transactions!$G$5:$G$3000,"Posted")>=1,"OK","CHECK no debit"),IF(I30="Reversed",IF(AND(COUNTIFS(Wallet_Transactions!$I$5:$I$3000,A30,Wallet_Transactions!$D$5:$D$3000,"Redemption",Wallet_Transactions!$G$5:$G$3000,"Posted")>=1,COUNTIFS(Wallet_Transactions!$I$5:$I$3000,A30,Wallet_Transactions!$D$5:$D$3000,"Reversal",Wallet_Transactions!$G$5:$G$3000,"Posted")>=1),"OK","CHECK no reversal"),IF(COUNTIFS(Wallet_Transactions!$I$5:$I$3000,A30,Wallet_Transactions!$D$5:$D$3000,"Redemption",Wallet_Transactions!$G$5:$G$3000,"Posted")>0,"CHECK unexpected debit","OK"))) -> OK
A31: WD-0027 | B31: U001 | C31: 650 | D31: Points | E31: Bank Transfer | F31: 46292.559 | G31: 46293.452 | H31: 46294.381 | I31: Completed | K31: =IF(ISNA(MATCH(I31,Withdrawal_Lifecycle!$A$5:$A$11,0)),"CHECK status",IF(AND(I31="Requested",OR(G31<>"",H31<>"")),"CHECK timestamps",IF(AND(OR(I31="Under Review",I31="Processing"),OR(G31="",H31<>"")),"CHECK timestamps",IF(AND(OR(I31="Completed",I31="Reversed",I31="Rejected"),OR(G31="",H31="")),"CHECK timestamps",IF(AND(I31="Cancelled",H31=""),"CHECK timestamps",IF(OR(AND(G31<>"",G31<F31),AND(H31<>"",H31<IF(G31<>"",G31,F31))),"CHECK order",IF(AND(OR(I31="Rejected",I31="Reversed"),J31=""),"CHECK reason","OK"))))))) -> OK | L31: =IF(OR(I31="Requested",I31="Under Review",I31="Processing"),1,0) -> 0 | M31: =IF(G31="","",(G31-F31)*24) -> 21.43633 | N31: =IF(AND(I31="Completed",G31<>"",H31<>""),(H31-G31)*24,"") -> 22.282578 | O31: =IF(AND(I31="Completed",H31<>""),(H31-F31)*24,"") -> 43.718908 | P31: =IF(O31="","",IF(O31<=Settings!$B$8,"Yes","No")) -> Yes | Q31: =IF(AND(I31="Rejected",H31<>""),(H31-F31)*24,"") | R31: =IF(L31=1,(Settings!$B$5-F31)*24,"") | S31: =IF(COUNTIF($B$5:B31,B31)=1,1,0) -> 1 | T31: =IF(I31="Completed",IF(COUNTIFS(Wallet_Transactions!$I$5:$I$3000,A31,Wallet_Transactions!$D$5:$D$3000,"Redemption",Wallet_Transactions!$G$5:$G$3000,"Posted")>=1,"OK","CHECK no debit"),IF(I31="Reversed",IF(AND(COUNTIFS(Wallet_Transactions!$I$5:$I$3000,A31,Wallet_Transactions!$D$5:$D$3000,"Redemption",Wallet_Transactions!$G$5:$G$3000,"Posted")>=1,COUNTIFS(Wallet_Transactions!$I$5:$I$3000,A31,Wallet_Transactions!$D$5:$D$3000,"Reversal",Wallet_Transactions!$G$5:$G$3000,"Posted")>=1),"OK","CHECK no reversal"),IF(COUNTIFS(Wallet_Transactions!$I$5:$I$3000,A31,Wallet_Transactions!$D$5:$D$3000,"Redemption",Wallet_Transactions!$G$5:$G$3000,"Posted")>0,"CHECK unexpected debit","OK"))) -> OK
